Workbook

Sheet 00_운영가이드
A1: 베이시스소프트 HR 통합관리 시스템_운영 가이드
A2: 매년 1월에 차년도 파일을 복제·생성하여 사용하세요.
A4: ■ 색상 범례 (모든 시트 공통)
A5: 노란색 셀 | C5: HR 담당자가 직접 입력하는 셀입니다. 이 셀만 수정하세요.
A6: 연두색 셀 | C6: 자동 계산 셀 (수식). 수동으로 입력하지 마세요. 다른 시트의 값을 참조합니다.
A7: 흰색·회색 셀 | C7: 참고용 라벨·헤더. 일반적으로 수정하지 않습니다.
A8: S/A 등급 | C8: 탁월·우수 — 평가 결과가 S/A인 셀에 자동 색상 적용
A9: C 등급 | C9: 미흡 — 보완 필요
A10: D 등급 / 이탈 | C10: 부족 / 페이밴드 이탈 — 즉시 조치 필요
A12: ■ 시트 구성 (왼쪽→오른쪽 순서대로 사용)
A13: 구분 | B13: 시트명 | C13: 역할 | I13: 시기 | K13: 대상
A14: 기본 | B14: 01_인적정보 | C14: 임직원 명부 마스터. 사번·이름·직무·역할등급을 관리 | I14: 신규입사·퇴사·승진 시 | K14: HR 담당자
A15: 기본 | B15: 02_의사결정·종합결과 | C15: 가중치(3축+공통역량11개)·등급별 인상률·페이밴드 설정 + 종합 KPI 대시보드 | I15: 연초 정책 설정 시 | K15: HR 담당자·경영진
A16: 평가 | B16: 03_전사업적평가 | C16: 전사 KPI 달성도 평가 (별도 운영, 성과급 재원 가산용) | I16: 상·하반기 결산 후 | K16: 재무·경영전략
A17: 평가 | B17: 04_역할평가 | C17: 역할등급별 일반 수행도 5개 항목 평가 | I17: 상·하반기 평가 시 | K17: 평가자(상사·동료)
A18: 평가 | B18: 05_공통역량평가 | C18: 전사 공통 11개 역량 평가 | I18: 상·하반기 평가 시 | K18: 평가자
A19: 평가 | B19: 06_직무역량평가 | C19: 직무별 책무·과업 기반 전문역량 평가 | I19: 상·하반기 평가 시 | K19: 평가자
A20: 취합 | B20: 07_결과취합 | C20: 부서별 평가지 회수 후 등급 통합 입력 | I20: 평가 종료 후 | K20: HR 담당자
A21: 산출 | B21: 08_종합평가 | C21: 3축(역할·공통·직무) 가중 통합 + 최종 등급 자동 산출 | I21: 취합 완료 후 자동 | K21: 확인만
A22: 산출 | B22: 09_보상연계 | C22: 최종 등급 → 인상률 → 차년도 기본연봉 자동 산출 | I22: 12월 평가 후 | K22: HR 담당자·경영진
A23: 산출 | B23: 10_성과급관리 | C23: 등급별 성과급 자동 산출 + 부서별 통계 | I23: 성과급 지급 시 | K23: HR 담당자·재무
A24: 산출 | B24: 11_페이밴드검증 | C24: 인상 후 연봉의 페이밴드 적합도 검증·이탈자 관리 | I24: 보상 확정 전 | K24: HR 담당자
... A28: DB | B28: 15_역량개발플랜 | C28: 직무별 육성 전략 + 개인별 IDP | I28: 평가 면담 시 | K28: HR 담당자·관리자
A30: ■ 연간 운영 워크플로우 (4단계)
A31: 단계 | B31: 시기 | C31: 주요 활동 | D31: 상세 절차
A32: STEP 1 | B32: 연초 (1월~2월) | C32: 정책 설정 | D32: [01_인적정보] 명부 최신화 → [02_의사결정] 가중치·인상률·페이밴드·전사 KPI 목표 설정
A33: STEP 2 | B33: 상반기 평가 (6월) | C33: 1차 평가 회수·취합 | D33: 부서별 평가시트 회수 → [07_결과취합]에 등급 입력 → [04][05][06]에 자동 반영 → [08_종합평가] 자동 산출
A34: STEP 3 | B34: 하반기 평가 (12월) | C34: 2차 평가 + 연간 확정 | D34: STEP 2 동일 + [03_전사업적평가] 실적 입력 → 연간 최종 등급 확정
A35: STEP 4 | B35: 12월~1월 | C35: 보상·성과급 시뮬레이션·확정 | D35: [09_보상연계] → [11_페이밴드검증] 이탈자 조정 → [10_성과급관리] → [12_시뮬레이션] 경영진 보고
A38: ■ 평가 구조 — 3축 (역할 + 공통역량 + 직무역량 = 100%)
A39: 축 ① | B39: 역할평가 | C39: 역할등급(G1~G6)에 따른 일반 수행도 — 5개 평가 항목 (책임범위·의사결정·성과기여·코칭·산출물)
A40: 축 ② | B40: 공통역량평가 | C40: 전사 공통 11개 역량 (업무·조직·인성·미래) — 가중치 적용 (직무전문성 15%, 분석력 10% 등)
A41: 축 ③ | B41: 직무역량평가 | C41: 직무별 책무·과업에 대한 평가 — 직무 프로파일의 5~19개 책무 (예: BIM컨설팅 14개, 경영전략 19개)
A44: ■ 직급별 3축 가중치 (02_의사결정에서 수정 가능)
A45: 역할등급 | B45: 역할평가 | C45: 공통역량 | D45: 직무역량 | E45: 합계
A46: G6 | B46: 0.4 | C46: 0.25 | D46: 0.35 | E46: 1
A47: G5 | B47: 0.35 | C47: 0.3 | D47: 0.35 | E47: 1
A48: G4 | B48: 0.3 | C48: 0.3 | D48: 0.4 | E48: 1
A49: G3 | B49: 0.25 | C49: 0.3 | D49: 0.45 | E49: 1
A50: G2 | B50: 0.2 | C50: 0.35 | D50: 0.45 | E50: 1
...

Sheet 01_인적정보
A1: 임직원 명부 마스터 (Master)
A2: 사번을 키로 모든 시트를 연결. 노란색 셀만 직접 수정. 인적사항은 이 시트에서만 관리하세요.
A3: ▶ 신규입사·퇴사·승진 시 이 시트만 업데이트하면 모든 시트에 자동 반영됩니다.
A4: No. | B4: 사번 | C4: 성명 | D4: 직군 | E4: 직무 | F4: 부서 | G4: 기존직급 | H4: 역할등급 | I4: 입사일 | J4: 근속연수 | K4: 1차 평가자 | L4: 2차 평가자 | M4: 조회키 (직무+역할등급) | N4: 비고
A5: 1 | B5: BSS-001 | C5: 이화형 | D5: 영업 | E5: 프로젝트영업 | F5: 스마트사업부 | G5: 전무 | H5: G6 | I5: 41647 | J5: =IFERROR(DATEDIF(I5,TODAY(),"Y"),0) -> 12 | M5: =E5&IF(LEFT(H5,2)="G5","G5",H5) -> 프로젝트영업G6
A6: 2 | B6: BSS-002 | C6: 강전용 | D6: 연구&개발 | E6: 연구개발(R&D) | F6: R&D 본부 | G6: 상무 | H6: G6 | I6: 41685 | J6: =IFERROR(DATEDIF(I6,TODAY(),"Y"),0) -> 12 | M6: =E6&IF(LEFT(H6,2)="G5","G5",H6) -> 연구개발(R&D)G6
A7: 3 | B7: BSS-003 | C7: 김현민 | D7: 설계 | E7: BIM컨설팅 | F7: 컨설팅본부 | G7: 상무 | H7: G6 | I7: 41720 | J7: =IFERROR(DATEDIF(I7,TODAY(),"Y"),0) -> 12 | M7: =E7&IF(LEFT(H7,2)="G5","G5",H7) -> BIM컨설팅G6
A8: 4 | B8: BSS-004 | C8: 이일곤 | D8: 경영관리 | E8: 경영전략기획 | F8: 경영전략실 | G8: 이사 | H8: G6 | I8: 41730 | J8: =IFERROR(DATEDIF(I8,TODAY(),"Y"),0) -> 12 | M8: =E8&IF(LEFT(H8,2)="G5","G5",H8) -> 경영전략기획G6
A9: 5 | B9: BSS-005 | C9: 송헌영 | D9: 경영관리 | E9: 경영전략기획 | F9: 경영전략실 | G9: 이사 | H9: G6 | I9: 42132 | J9: =IFERROR(DATEDIF(I9,TODAY(),"Y"),0) -> 11 | M9: =E9&IF(LEFT(H9,2)="G5","G5",H9) -> 경영전략기획G6
A10: 6 | B10: BSS-006 | C10: 이재용 | D10: 경영관리 | E10: 경영전략기획 | F10: 경영전략실 | G10: 이사 | H10: G6 | I10: 42170 | J10: =IFERROR(DATEDIF(I10,TODAY(),"Y"),0) -> 10 | M10: =E10&IF(LEFT(H10,2)="G5","G5",H10) -> 경영전략기획G6
A11: 7 | B11: BSS-007 | C11: 이진행 | D11: 교육 및 기술지원 | E11: 교육·기술지원 | F11: 솔루션본부 | G11: 부장 | H11: G5 | I11: 42207 | J11: =IFERROR(DATEDIF(I11,TODAY(),"Y"),0) -> 10 | M11: =E11&IF(LEFT(H11,2)="G5","G5",H11) -> 교육·기술지원G5
A12: 8 | B12: BSS-008 | C12: 김민수 | D12: 교육 및 기술지원 | E12: 교육·기술지원 | F12: 솔루션본부 | G12: 부장 | H12: G5 | I12: 42217 | J12: =IFERROR(DATEDIF(I12,TODAY(),"Y"),0) -> 10 | M12: =E12&IF(LEFT(H12,2)="G5","G5",H12) -> 교육·기술지원G5
A13: 9 | B13: BSS-009 | C13: 박남식 | D13: 설계 | E13: BIM컨설팅 | F13: 컨설팅본부 | G13: 부장 | H13: G5 | I13: 42621 | J13: =IFERROR(DATEDIF(I13,TODAY(),"Y"),0) -> 9 | M13: =E13&IF(LEFT(H13,2)="G5","G5",H13) -> BIM컨설팅G5
A14: 10 | B14: BSS-010 | C14: 신재민 | D14: 설계 | E14: BIM컨설팅 | F14: 컨설팅본부 | G14: 부장 | H14: G5 | I14: 42658 | J14: =IFERROR(DATEDIF(I14,TODAY(),"Y"),0) -> 9 | M14: =E14&IF(LEFT(H14,2)="G5","G5",H14) -> BIM컨설팅G5
A15: 11 | B15: BSS-011 | C15: 마장엽 | D15: 설계 | E15: BIM컨설팅 | F15: 컨설팅본부 | G15: 부장 | H15: G5 | I15: 42696 | J15: =IFERROR(DATEDIF(I15,TODAY(),"Y"),0) -> 9 | M15: =E15&IF(LEFT(H15,2)="G5","G5",H15) -> BIM컨설팅G5
A16: 12 | B16: BSS-012 | C16: 하은주 | D16: 경영관리 | E16: 경영전략기획 | F16: 마케팅팀 | G16: 부장 | H16: G5 | I16: 42705 | J16: =IFERROR(DATEDIF(I16,TODAY(),"Y"),0) -> 9 | M16: =E16&IF(LEFT(H16,2)="G5","G5",H16) -> 경영전략기획G5
... A38: 34 | B38: BSS-034 | C38: 엄보근 | D38: 설계 | E38: BIM컨설팅 | F38: 컨설팅본부 | G38: 사원 | H38: G1 | I38: 44849 | J38: =IFERROR(DATEDIF(I38,TODAY(),"Y"),0) -> 3 | M38: =E38&IF(LEFT(H38,2)="G5","G5",H38) -> BIM컨설팅G1
A41: ■ 통계 요약
A42: 역할등급별 | B42: 인원 | D42: 직군별 | E42: 인원 | G42: 부서별 | H42: 인원
A43: G6 | B43: =COUNTIF(H5:H38,"G6") -> 6 | D43: 경영관리 | E43: =COUNTIF(D5:D38,"경영관리") -> 5 | G43: 스마트사업부 | H43: =COUNTIF(F5:F38,"스마트사업부") -> 1
A44: G5 | B44: =COUNTIF(H5:H38,"G5-M")+COUNTIF(H5:H38,"G5-S")+COUNTIF(H5:H38,"G5") -> 10 | D44: 교육 및 기술지원 | E44: =COUNTIF(D5:D38,"교육 및 기술지원") -> 5 | G44: R&D 본부 | H44: =COUNTIF(F5:F38,"R&D 본부") -> 1
A45: G4 | B45: =COUNTIF(H5:H38,"G4") -> 2 | D45: 설계 | E45: =COUNTIF(D5:D38,"설계") -> 21 | G45: 컨설팅본부 | H45: =COUNTIF(F5:F38,"컨설팅본부") -> 22
A46: G3 | B46: =COUNTIF(H5:H38,"G3") -> 1 | D46: 연구&개발 | E46: =COUNTIF(D5:D38,"연구&개발") -> 2 | G46: 경영전략실 | H46: =COUNTIF(F5:F38,"경영전략실") -> 3
A47: G2 | B47: =COUNTIF(H5:H38,"G2") -> 7 | D47: 영업 | E47: =COUNTIF(D5:D38,"영업") -> 1 | G47: 솔루션본부 | H47: =COUNTIF(F5:F38,"솔루션본부") -> 5
A48: G1 | B48: =COUNTIF(H5:H38,"G1") -> 8 | G48: 마케팅팀 | H48: =COUNTIF(F5:F38,"마케팅팀") -> 2

Sheet 02_의사결정·종합결과
A1: HR 의사결정 컨피그 + 종합 결과 대시보드
A2: HR 담당자가 가중치·인상률·평가방식을 결정하는 컨피그 영역 + 모든 시트의 결과가 자동 집계되는 대시보드
A4: ■ ① 평가 방식·반기 가중치 | K4: ■ 종합 결과 대시보드 (모든 시트 자동 집계)
A5: 평가 척도 | B5: 5점 | C5: 5점 또는 100점 (전 시트 일괄 적용) | K5: 총 인원 | M5: 연봉 총액 (현재) | O5: 연봉 총액 (인상 후)
A6: 평가 방식 | B6: 절대평가 | C6: 절대평가: 점수→등급 환산 / 상대평가: 분포 강제 | K6: =COUNTA('01_인적정보'!C5:C38) -> 34 | M6: =SUM('09_보상연계'!F11:F44) -> 3035970000 | O6: =SUM('09_보상연계'!N11:N44) -> 3096670000
A7: 상반기 가중치 | B7: 0.5
A8: 하반기 가중치 | B8: =1-B7 -> 0.5 | K8: 총 인상액 | M8: 평균 인상률 | O8: 성과급 총액
K9: =SUM('09_보상연계'!O11:O44) -> 3096670000 | M9: =IFERROR(AVERAGE('09_보상연계'!M11:M44),0) -> 58413793 | O9: =SUM('10_성과급관리'!J11:J44) -> 0
A10: 강제분포 비중 | B10: S | C10: A | D10: B | E10: C | F10: D
B11: 0.1 | C11: 0.15 | D11: 0.5 | E11: 0.15 | F11: 0.1 | K11: S등급 | M11: A등급 | O11: B등급
K12: =COUNTIF('08_종합평가'!T15:T48,"S") -> 0 | M12: =COUNTIF('08_종합평가'!T15:T48,"A") -> 0 | O12: =COUNTIF('08_종합평가'!T15:T48,"B") -> 0
A13: ■ ② 직급별 3축 평가 가중치 (역할 + 공통역량 + 직무역량 = 100%)
A14: 역할등급 | B14: 역할평가 W | C14: 공통역량 W | D14: 직무역량 W | E14: 합계 | F14: 검증 | G14: 설계 의도 | K14: C·D등급 | M14: 페이밴드 적합률 | O14: 전사 KPI 연간 등급
A15: G6 | B15: 0.4 | C15: 0.25 | D15: 0.35 | E15: =B15+C15+D15 -> 1 | F15: =IF(E15=1,"✓ OK","✗ ≠100%") -> ✓ OK | G15: 경영성과 책임·전사 의사결정 중심 | K15: =COUNTIF('08_종합평가'!T15:T48,"C")+COUNTIF('08_종합평가'!T15:T48,"D") -> 25 | M15: =IFERROR(COUNTIF('11_페이밴드검증'!N15:N48,"적합")/COUNTA('11_페이밴드검증'!C15:C48),0) -> 0 | O15: ='03_전사업적평가'!#REF! -> #REF!
A16: G5 | B16: 0.35 | C16: 0.3 | D16: 0.35 | E16: =B16+C16+D16 -> 1 | F16: =IF(E16=1,"✓ OK","✗ ≠100%") -> ✓ OK | G16: 조직 관리·실무 전문성 균형
A17: G4 | B17: 0.3 | C17: 0.3 | D17: 0.4 | E17: =B17+C17+D17 -> 1 | F17: =IF(E17=1,"✓ OK","✗ ≠100%") -> ✓ OK | G17: 실무 책임자, 직무역량 강조
A18: G3 | B18: 0.25 | C18: 0.3 | D18: 0.45 | E18: =B18+C18+D18 -> 1 | F18: =IF(E18=1,"✓ OK","✗ ≠100%") -> ✓ OK | G18: 핵심 실무자, 직무 깊이 가중 | K18: 등급 | L18: 인원 | M18: 비율
A19: G2 | B19: 0.2 | C19: 0.35 | D19: 0.45 | E19: =B19+C19+D19 -> 1 | F19: =IF(E19=1,"✓ OK","✗ ≠100%") -> ✓ OK | G19: 실무자, 역량 개발 집중 | K19: S | L19: =COUNTIF('08_종합평가'!T15:T48,"S") -> 0 | M19: =IFERROR(L19/SUM($L$19:$L$23),0) -> 0
A20: G1 | B20: 0.15 | C20: 0.35 | D20: 0.5 | E20: =B20+C20+D20 -> 1 | F20: =IF(E20=1,"✓ OK","✗ ≠100%") -> ✓ OK | G20: 신입·실무 보조, 기본기 학습 | K20: A | L20: =COUNTIF('08_종합평가'!T15:T48,"A") -> 0 | M20: =IFERROR(L20/SUM($L$19:$L$23),0) -> 0
K21: B | L21: =COUNTIF('08_종합평가'!T15:T48,"B") -> 0 | M21: =IFERROR(L21/SUM($L$19:$L$23),0) -> 0
A22: ■ ③ 평가 등급별 인상률 & 성과급률 | K22: C | L22: =COUNTIF('08_종합평가'!T15:T48,"C") -> 0 | M22: =IFERROR(L22/SUM($L$19:$L$23),0) -> 0
A23: 등급 | B23: S | C23: A | D23: B | E23: C | F23: D | G23: 비고 | K23: D | L23: =COUNTIF('08_종합평가'!T15:T48,"D") -> 25 | M23: =IFERROR(L23/SUM($L$19:$L$23),0) -> 1
A24: 기본연봉 인상률 | B24: 0.06 | C24: 0.05 | D24: 0.04 | E24: 0.03 | F24: 0.02 | G24: 09_보상연계 시트에 자동 반영
A25: 성과급 지급률 | B25: 0.2 | C25: 0.15 | D25: 0.1 | E25: 0.05 | F25: 0 | G25: 10_성과급관리 시트에 자동 반영
A26: 승진 가산률 | B26: 0.01 | C26: 승진(역할등급 상승) 시 기본연봉 인상률에 가산 | G26: Y/N 선택 시 자동 적용
A28: ■ ④ 페이밴드 (역할등급별 기본연봉 범위)
A29: 역할등급 | B29: 최소(Min) | C29: 중위(Mid) | D29: 최대(Max) | E29: Range Spread
A30: G1 | B30: 33000000 | C30: 38500000 | D30: 44000000 | E30: =(D30-B30)/B30 -> 0.33333333
A31: G2 | B31: 36000000 | C31: 42500000 | D31: 49000000 | E31: =(D31-B31)/B31 -> 0.36111111
A32: G3 | B32: 42000000 | C32: 49500000 | D32: 57000000 | E32: =(D32-B32)/B32 -> 0.35714286
A33: G4 | B33: 49000000 | C33: 57500000 | D33: 66000000 | E33: =(D33-B33)/B33 -> 0.34693878
A34: G5 | B34: 53000000 | C34: 63000000 | D34: 73000000 | E34: =(D34-B34)/B34 -> 0.37735849
A35: G6 | B35: 58000000 | C35: 69000000 | D35: 80000000 | E35: =(D35-B35)/B35 -> 0.37931034
A37: ■ ⑤ 전사 KPI 목표 (성과급 재원 가산용)
A38: KPI | B38: 측정방법 | C38: 가중치 | D38: 목표 | E38: S기준 | F38: A기준 | G38: B기준 | H38: C기준 | I38: D기준
A39: 영업이익률 | B39: 영업이익 ÷ 매출액 × 100 | C39: 0.4 | D39: 0.12 | E39: 0.15 | F39: 0.12 | G39: 0.1 | H39: 0.08 | I39: 0.06
A40: 매출 성장률 | B40: (금년도매출-전년도매출) ÷ 전년도매출 × 100 | C40: 0.35 | D40: 0.07 | E40: 0.08 | F40: 0.07 | G40: 0.06 | H40: 0.05 | I40: 0.04
A41: 프로젝트 납기·품질 준수율 | B41: 납기·품질 충족 프로젝트 ÷ 총 프로젝트 × 100 | C41: 0.25 | D41: 0.92 | E41: 0.93 | F41: 0.92 | G41: 0.91 | H41: 0.9 | I41: 0.89
A51: ■ ⑥ 공통역량별 가중치 (11개 역량) — HR 담당자가 직접 조정 가능
A52: No. | B52: 역량군 | C52: 핵심 역량 | E52: 가중치 | F52: 역량 설명
...

Sheet 03_전사업적평가
A1: 전사 업적평가 — KPI 달성도 (성과급 재원 가산용)
A2: 전사 KPI 실적을 입력 → 자동 등급 산정. 별도 운영으로 전사 등급은 성과급 재원 조정에 사용됩니다
A4: ■ 상반기 (1월~6월)
A5: No. | B5: KPI | C5: 측정방법 | D5: 가중치 | E5: 목표 | F5: 실적 | G5: S기준 | H5: A기준 | I5: B기준 | J5: C기준 | K5: D기준 | L5: 달성등급
A6: 1 | B6: ='02_의사결정·종합결과'!A39 -> 영업이익률 | C6: ='02_의사결정·종합결과'!B39 -> 영업이익 ÷ 매출액 × 100 | D6: ='02_의사결정·종합결과'!C39 -> 0.4 | E6: ='02_의사결정·종합결과'!D39 -> 0.12 | G6: ='02_의사결정·종합결과'!E39 -> 0.15 | H6: ='02_의사결정·종합결과'!F39 -> 0.12 | I6: ='02_의사결정·종합결과'!G39 -> 0.1 | J6: ='02_의사결정·종합결과'!H39 -> 0.08 | K6: ='02_의사결정·종합결과'!I39 -> 0.06 | L6: =IF(F6="","",IF(F6>=G6,"S",IF(F6>=H6,"A",IF(F6>=I6,"B",IF(F6>=J6,"C","D")))))
A7: 2 | B7: ='02_의사결정·종합결과'!A40 -> 매출 성장률 | C7: ='02_의사결정·종합결과'!B40 -> (금년도매출-전년도매출) ÷ 전년도매출 × 100 | D7: ='02_의사결정·종합결과'!C40 -> 0.35 | E7: ='02_의사결정·종합결과'!D40 -> 0.07 | G7: ='02_의사결정·종합결과'!E40 -> 0.08 | H7: ='02_의사결정·종합결과'!F40 -> 0.07 | I7: ='02_의사결정·종합결과'!G40 -> 0.06 | J7: ='02_의사결정·종합결과'!H40 -> 0.05 | K7: ='02_의사결정·종합결과'!I40 -> 0.04 | L7: =IF(F7="","",IF(F7>=G7,"S",IF(F7>=H7,"A",IF(F7>=I7,"B",IF(F7>=J7,"C","D")))))
A8: 3 | B8: ='02_의사결정·종합결과'!A41 -> 프로젝트 납기·품질 준수율 | C8: ='02_의사결정·종합결과'!B41 -> 납기·품질 충족 프로젝트 ÷ 총 프로젝트 × 100 | D8: ='02_의사결정·종합결과'!C41 -> 0.25 | E8: ='02_의사결정·종합결과'!D41 -> 0.92 | G8: ='02_의사결정·종합결과'!E41 -> 0.93 | H8: ='02_의사결정·종합결과'!F41 -> 0.92 | I8: ='02_의사결정·종합결과'!G41 -> 0.91 | J8: ='02_의사결정·종합결과'!H41 -> 0.9 | K8: ='02_의사결정·종합결과'!I41 -> 0.89 | L8: =IF(F8="","",IF(F8>=G8,"S",IF(F8>=H8,"A",IF(F8>=I8,"B",IF(F8>=J8,"C","D")))))
A9: 상반기 종합 | F9: 가중평균: | G9: =IF(COUNTBLANK(L6:L8)>0,"",D6*(IF(L6="S",5,IF(L6="A",4,IF(L6="B",3,IF(L6="C",2,IF(L6="D",1,0))))))+D7*(IF(L7="S",5,IF(L7="A",4,IF(L7="B",3,IF(L7="C",2,IF(L7="D",1,0))))))+D8*(IF(L8="S",5,IF(L8="A",4,IF(L8="B",3,IF(L8="C",2,IF(L8="D",1,0))))))) | H9: 등급: | I9: =IF(G9="","",IF(G9>=4.5,"S",IF(G9>=3.5,"A",IF(G9>=2.5,"B",IF(G9>=1.5,"C","D")))))
A11: ■ 하반기 (7월~12월)
A12: No. | B12: KPI | C12: 측정방법 | D12: 가중치 | E12: 목표 | F12: 실적 | G12: S기준 | H12: A기준 | I12: B기준 | J12: C기준 | K12: D기준 | L12: 달성등급
A13: 1 | B13: ='02_의사결정·종합결과'!A39 -> 영업이익률 | C13: ='02_의사결정·종합결과'!B39 -> 영업이익 ÷ 매출액 × 100 | D13: ='02_의사결정·종합결과'!C39 -> 0.4 | E13: ='02_의사결정·종합결과'!D39 -> 0.12 | G13: ='02_의사결정·종합결과'!E39 -> 0.15 | H13: ='02_의사결정·종합결과'!F39 -> 0.12 | I13: ='02_의사결정·종합결과'!G39 -> 0.1 | J13: ='02_의사결정·종합결과'!H39 -> 0.08 | K13: ='02_의사결정·종합결과'!I39 -> 0.06 | L13: =IF(F13="","",IF(F13>=G13,"S",IF(F13>=H13,"A",IF(F13>=I13,"B",IF(F13>=J13,"C","D")))))
A14: 2 | B14: ='02_의사결정·종합결과'!A40 -> 매출 성장률 | C14: ='02_의사결정·종합결과'!B40 -> (금년도매출-전년도매출) ÷ 전년도매출 × 100 | D14: ='02_의사결정·종합결과'!C40 -> 0.35 | E14: ='02_의사결정·종합결과'!D40 -> 0.07 | G14: ='02_의사결정·종합결과'!E40 -> 0.08 | H14: ='02_의사결정·종합결과'!F40 -> 0.07 | I14: ='02_의사결정·종합결과'!G40 -> 0.06 | J14: ='02_의사결정·종합결과'!H40 -> 0.05 | K14: ='02_의사결정·종합결과'!I40 -> 0.04 | L14: =IF(F14="","",IF(F14>=G14,"S",IF(F14>=H14,"A",IF(F14>=I14,"B",IF(F14>=J14,"C","D")))))
A15: 3 | B15: ='02_의사결정·종합결과'!A41 -> 프로젝트 납기·품질 준수율 | C15: ='02_의사결정·종합결과'!B41 -> 납기·품질 충족 프로젝트 ÷ 총 프로젝트 × 100 | D15: ='02_의사결정·종합결과'!C41 -> 0.25 | E15: ='02_의사결정·종합결과'!D41 -> 0.92 | G15: ='02_의사결정·종합결과'!E41 -> 0.93 | H15: ='02_의사결정·종합결과'!F41 -> 0.92 | I15: ='02_의사결정·종합결과'!G41 -> 0.91 | J15: ='02_의사결정·종합결과'!H41 -> 0.9 | K15: ='02_의사결정·종합결과'!I41 -> 0.89 | L15: =IF(F15="","",IF(F15>=G15,"S",IF(F15>=H15,"A",IF(F15>=I15,"B",IF(F15>=J15,"C","D")))))
A16: 하반기 종합 | F16: 가중평균: | G16: =IF(COUNTBLANK(L13:L15)>0,"",D13*(IF(L13="S",5,IF(L13="A",4,IF(L13="B",3,IF(L13="C",2,IF(L13="D",1,0))))))+D14*(IF(L14="S",5,IF(L14="A",4,IF(L14="B",3,IF(L14="C",2,IF(L14="D",1,0))))))+D15*(IF(L15="S",5,IF(L15="A",4,IF(L15="B",3,IF(L15="C",2,IF(L15="D",1,0))))))) | H16: 등급: | I16: =IF(G16="","",IF(G16>=4.5,"S",IF(G16>=3.5,"A",IF(G16>=2.5,"B",IF(G16>=1.5,"C","D")))))
A18: ■ 연간 종합 업적평가
B19: 상반기 가중치 | C19: 0.5 | D19: 하반기 가중치 | E19: =1-C19 -> 0.5 | F19: 연간 가중평균: | G19: =IF(OR(G9="",G16=""),"",G9*C19+G16*E19) | H19: 연간 등급: | I19: =IF(G19="","",IF(G19>=4.5,"S",IF(G19>=3.5,"A",IF(G19>=2.5,"B",IF(G19>=1.5,"C","D")))))

Sheet 04_역할평가
A1: 역할평가 — 역할등급별 일반 수행도 5개 항목
A2: 역할정의(13_직무역할DB 자동 참조) + 5개 평가 항목 등급 입력 → 자동 종합
A4: ■ 등급 부여 기준 (BARS 행동기준)
A5: S (탁월) | B5: 역할정의를 현저히 초과 달성. 조직 전체에 긍정적 파급효과 창출.
A6: A (우수) | B6: 역할정의를 충실히 수행하며 기대 수준을 상회. 자기주도적 성과.
A7: B (양호) | B7: 역할정의에 부합하는 수준으로 안정적 수행. 기대 책임을 기한 내 완수.
A8: C (미흡) | B8: 역할정의 대비 부분적 미흡. 추가 지도·지원 필요.
A9: D (부족) | B9: 역할정의 대비 전반적 미흡. 구체적 개선 계획 필요.
A11: ■ 상반기 역할평가
A12: No. | B12: 사번 | C12: 성명 | D12: 직무 | E12: 역할등급 | F12: 역할명 | G12: 역할정의 | H12: 책임범위 이행 | I12: 의사결정 적절성 | J12: 성과 기여도 | K12: 조직·코칭 | L12: 산출물 완성도 | M12: 1차 평가 (종합) | N12: 2차 평가 (종합) | O12: 확정등급 | P12: 평가점수 | Q12: 강점·개선 소견
A13: ='01_인적정보'!A5 -> 1 | B13: ='01_인적정보'!B5 -> BSS-001 | C13: ='01_인적정보'!C5 -> 이화형 | D13: ='01_인적정보'!E5 -> 프로젝트영업 | E13: ='01_인적정보'!H5 -> G6 | F13: =IFERROR(VLOOKUP('01_인적정보'!M5,'13_직무역할DB'!$A$5:$L$70,4,FALSE),"") -> 사업·조직 관리 | G13: =IFERROR(VLOOKUP('01_인적정보'!M5,'13_직무역할DB'!$A$5:$L$70,5,FALSE),"") -> 회사의 영업전략 수립과 목표 달성을 총괄하며, 주요 고객·파트너십 관리 및 사업 기회를 확대하는 역할. | H13: ='07_결과취합'!G6 -> 0 | I13: ='07_결과취합'!H6 -> 0 | J13: ='07_결과취합'!I6 -> 0 | K13: ='07_결과취합'!J6 -> 0 | L13: ='07_결과취합'!K6 -> 0 | M13: ='07_결과취합'!L6 -> 0 | N13: ='07_결과취합'!M6 -> 0 | O13: =IF(N13<>"",N13,M13) -> 0 | P13: =IF(O13="","",IF(O13="S",5,IF(O13="A",4,IF(O13="B",3,IF(O13="C",2,IF(O13="D",1,0)))))) -> 0
A14: ='01_인적정보'!A6 -> 2 | B14: ='01_인적정보'!B6 -> BSS-002 | C14: ='01_인적정보'!C6 -> 강전용 | D14: ='01_인적정보'!E6 -> 연구개발(R&D) | E14: ='01_인적정보'!H6 -> G6 | F14: =IFERROR(VLOOKUP('01_인적정보'!M6,'13_직무역할DB'!$A$5:$L$70,4,FALSE),"") -> 사업·조직 관리 | G14: =IFERROR(VLOOKUP('01_인적정보'!M6,'13_직무역할DB'!$A$5:$L$70,5,FALSE),"") -> 전사 기술 로드맵과 제품 포트폴리오 전략을 총괄하며 핵심 기술 투자·외부 협력·IP 전략을 통해 사업 경쟁력을 창출하는 역할. | H14: ='07_결과취합'!G7 -> 0 | I14: ='07_결과취합'!H7 -> 0 | J14: ='07_결과취합'!I7 -> 0 | K14: ='07_결과취합'!J7 -> 0 | L14: ='07_결과취합'!K7 -> 0 | M14: ='07_결과취합'!L7 -> 0 | N14: ='07_결과취합'!M7 -> 0 | O14: =IF(N14<>"",N14,M14) -> 0 | P14: =IF(O14="","",IF(O14="S",5,IF(O14="A",4,IF(O14="B",3,IF(O14="C",2,IF(O14="D",1,0)))))) -> 0
A15: ='01_인적정보'!A7 -> 3 | B15: ='01_인적정보'!B7 -> BSS-003 | C15: ='01_인적정보'!C7 -> 김현민 | D15: ='01_인적정보'!E7 -> BIM컨설팅 | E15: ='01_인적정보'!H7 -> G6 | F15: =IFERROR(VLOOKUP('01_인적정보'!M7,'13_직무역할DB'!$A$5:$L$70,4,FALSE),"") -> 사업·조직 관리 | G15: =IFERROR(VLOOKUP('01_인적정보'!M7,'13_직무역할DB'!$A$5:$L$70,5,FALSE),"") -> BIM 컨설팅 전략과 서비스 체계를 총괄하며 대외 협력과 사업 확장을 책임지는 역할. | H15: ='07_결과취합'!G8 -> 0 | I15: ='07_결과취합'!H8 -> 0 | J15: ='07_결과취합'!I8 -> 0 | K15: ='07_결과취합'!J8 -> 0 | L15: ='07_결과취합'!K8 -> 0 | M15: ='07_결과취합'!L8 -> 0 | N15: ='07_결과취합'!M8 -> 0 | O15: =IF(N15<>"",N15,M15) -> 0 | P15: =IF(O15="","",IF(O15="S",5,IF(O15="A",4,IF(O15="B",3,IF(O15="C",2,IF(O15="D",1,0)))))) -> 0
A16: ='01_인적정보'!A8 -> 4 | B16: ='01_인적정보'!B8 -> BSS-004 | C16: ='01_인적정보'!C8 -> 이일곤 | D16: ='01_인적정보'!E8 -> 경영전략기획 | E16: ='01_인적정보'!H8 -> G6 | F16: =IFERROR(VLOOKUP('01_인적정보'!M8,'13_직무역할DB'!$A$5:$L$70,4,FALSE),"") -> 사업·조직 관리 | G16: =IFERROR(VLOOKUP('01_인적정보'!M8,'13_직무역할DB'!$A$5:$L$70,5,FALSE),"") -> 회사의 비전과 중장기 전략을 총괄하며, 경영·인사·재무·마케팅 등 핵심 기능을 통합 관리하고, 전사 의사결정·대외 협력·리스크 관리를 주도함. | H16: ='07_결과취합'!G9 -> 0 | I16: ='07_결과취합'!H9 -> 0 | J16: ='07_결과취합'!I9 -> 0 | K16: ='07_결과취합'!J9 -> 0 | L16: ='07_결과취합'!K9 -> 0 | M16: ='07_결과취합'!L9 -> 0 | N16: ='07_결과취합'!M9 -> 0 | O16: =IF(N16<>"",N16,M16) -> 0 | P16: =IF(O16="","",IF(O16="S",5,IF(O16="A",4,IF(O16="B",3,IF(O16="C",2,IF(O16="D",1,0)))))) -> 0
A17: ='01_인적정보'!A9 -> 5 | B17: ='01_인적정보'!B9 -> BSS-005 | C17: ='01_인적정보'!C9 -> 송헌영 | D17: ='01_인적정보'!E9 -> 경영전략기획 | E17: ='01_인적정보'!H9 -> G6 | F17: =IFERROR(VLOOKUP('01_인적정보'!M9,'13_직무역할DB'!$A$5:$L$70,4,FALSE),"") -> 사업·조직 관리 | G17: =IFERROR(VLOOKUP('01_인적정보'!M9,'13_직무역할DB'!$A$5:$L$70,5,FALSE),"") -> 회사의 비전과 중장기 전략을 총괄하며, 경영·인사·재무·마케팅 등 핵심 기능을 통합 관리하고, 전사 의사결정·대외 협력·리스크 관리를 주도함. | H17: ='07_결과취합'!G10 -> 0 | I17: ='07_결과취합'!H10 -> 0 | J17: ='07_결과취합'!I10 -> 0 | K17: ='07_결과취합'!J10 -> 0 | L17: ='07_결과취합'!K10 -> 0 | M17: ='07_결과취합'!L10 -> 0 | N17: ='07_결과취합'!M10 -> 0 | O17: =IF(N17<>"",N17,M17) -> 0 | P17: =IF(O17="","",IF(O17="S",5,IF(O17="A",4,IF(O17="B",3,IF(O17="C",2,IF(O17="D",1,0)))))) -> 0
A18: ='01_인적정보'!A10 -> 6 | B18: ='01_인적정보'!B10 -> BSS-006 | C18: ='01_인적정보'!C10 -> 이재용 | D18: ='01_인적정보'!E10 -> 경영전략기획 | E18: ='01_인적정보'!H10 -> G6 | F18: =IFERROR(VLOOKUP('01_인적정보'!M10,'13_직무역할DB'!$A$5:$L$70,4,FALSE),"") -> 사업·조직 관리 | G18: =IFERROR(VLOOKUP('01_인적정보'!M10,'13_직무역할DB'!$A$5:$L$70,5,FALSE),"") -> 회사의 비전과 중장기 전략을 총괄하며, 경영·인사·재무·마케팅 등 핵심 기능을 통합 관리하고, 전사 의사결정·대외 협력·리스크 관리를 주도함. | H18: ='07_결과취합'!G11 -> 0 | I18: ='07_결과취합'!H11 -> 0 | J18: ='07_결과취합'!I11 -> 0 | K18: ='07_결과취합'!J11 -> 0 | L18: ='07_결과취합'!K11 -> 0 | M18: ='07_결과취합'!L11 -> 0 | N18: ='07_결과취합'!M11 -> 0 | O18: =IF(N18<>"",N18,M18) -> 0 | P18: =IF(O18="","",IF(O18="S",5,IF(O18="A",4,IF(O18="B",3,IF(O18="C",2,IF(O18="D",1,0)))))) -> 0
A19: ='01_인적정보'!A11 -> 7 | B19: ='01_인적정보'!B11 -> BSS-007 | C19: ='01_인적정보'!C11 -> 이진행 | D19: ='01_인적정보'!E11 -> 교육·기술지원 | E19: ='01_인적정보'!H11 -> G5 | F19: =IFERROR(VLOOKUP('01_인적정보'!M11,'13_직무역할DB'!$A$5:$L$70,4,FALSE),"") -> 직무 관리(부서장) | G19: =IFERROR(VLOOKUP('01_인적정보'!M11,'13_직무역할DB'!$A$5:$L$70,5,FALSE),"") -> 교육 조직의 목표·예산·인력을 관리하고 과정 기획·운영 품질을 총괄하며 대외 인증·평가 대응을 주도하는 역할. | H19: ='07_결과취합'!G12 -> 0 | I19: ='07_결과취합'!H12 -> 0 | J19: ='07_결과취합'!I12 -> 0 | K19: ='07_결과취합'!J12 -> 0 | L19: ='07_결과취합'!K12 -> 0 | M19: ='07_결과취합'!L12 -> 0 | N19: ='07_결과취합'!M12 -> 0 | O19: =IF(N19<>"",N19,M19) -> 0 | P19: =IF(O19="","",IF(O19="S",5,IF(O19="A",4,IF(O19="B",3,IF(O19="C",2,IF(O19="D",1,0)))))) -> 0
A20: ='01_인적정보'!A12 -> 8 | B20: ='01_인적정보'!B12 -> BSS-008 | C20: ='01_인적정보'!C12 -> 김민수 | D20: ='01_인적정보'!E12 -> 교육·기술지원 | E20: ='01_인적정보'!H12 -> G5 | F20: =IFERROR(VLOOKUP('01_인적정보'!M12,'13_직무역할DB'!$A$5:$L$70,4,FALSE),"") -> 직무 관리(부서장) | G20: =IFERROR(VLOOKUP('01_인적정보'!M12,'13_직무역할DB'!$A$5:$L$70,5,FALSE),"") -> 교육 조직의 목표·예산·인력을 관리하고 과정 기획·운영 품질을 총괄하며 대외 인증·평가 대응을 주도하는 역할. | H20: ='07_결과취합'!G13 -> 0 | I20: ='07_결과취합'!H13 -> 0 | J20: ='07_결과취합'!I13 -> 0 | K20: ='07_결과취합'!J13 -> 0 | L20: ='07_결과취합'!K13 -> 0 | M20: ='07_결과취합'!L13 -> 0 | N20: ='07_결과취합'!M13 -> 0 | O20: =IF(N20<>"",N20,M20) -> 0 | P20: =IF(O20="","",IF(O20="S",5,IF(O20="A",4,IF(O20="B",3,IF(O20="C",2,IF(O20="D",1,0)))))) -> 0
A21: ='01_인적정보'!A13 -> 9 | B21: ='01_인적정보'!B13 -> BSS-009 | C21: ='01_인적정보'!C13 -> 박남식 | D21: ='01_인적정보'!E13 -> BIM컨설팅 | E21: ='01_인적정보'!H13 -> G5 | F21: =IFERROR(VLOOKUP('01_인적정보'!M13,'13_직무역할DB'!$A$5:$L$70,4,FALSE),"") -> 직무 관리(부서장) | G21: =IFERROR(VLOOKUP('01_인적정보'!M13,'13_직무역할DB'!$A$5:$L$70,5,FALSE),"") -> BIM 컨설팅 조직의 목표와 방향을 설정·관리하고 프로젝트 포트폴리오 운영 및 성과 달성을 총괄하는 역할. | H21: ='07_결과취합'!G14 -> 0 | I21: ='07_결과취합'!H14 -> 0 | J21: ='07_결과취합'!I14 -> 0 | K21: ='07_결과취합'!J14 -> 0 | L21: ='07_결과취합'!K14 -> 0 | M21: ='07_결과취합'!L14 -> 0 | N21: ='07_결과취합'!M14 -> 0 | O21: =IF(N21<>"",N21,M21) -> 0 | P21: =IF(O21="","",IF(O21="S",5,IF(O21="A",4,IF(O21="B",3,IF(O21="C",2,IF(O21="D",1,0)))))) -> 0
A22: ='01_인적정보'!A14 -> 10 | B22: ='01_인적정보'!B14 -> BSS-010 | C22: ='01_인적정보'!C14 -> 신재민 | D22: ='01_인적정보'!E14 -> BIM컨설팅 | E22: ='01_인적정보'!H14 -> G5 | F22: =IFERROR(VLOOKUP('01_인적정보'!M14,'13_직무역할DB'!$A$5:$L$70,4,FALSE),"") -> 직무 관리(부서장) | G22: =IFERROR(VLOOKUP('01_인적정보'!M14,'13_직무역할DB'!$A$5:$L$70,5,FALSE),"") -> BIM 컨설팅 조직의 목표와 방향을 설정·관리하고 프로젝트 포트폴리오 운영 및 성과 달성을 총괄하는 역할. | H22: ='07_결과취합'!G15 -> 0 | I22: ='07_결과취합'!H15 -> 0 | J22: ='07_결과취합'!I15 -> 0 | K22: ='07_결과취합'!J15 -> 0 | L22: ='07_결과취합'!K15 -> 0 | M22: ='07_결과취합'!L15 -> 0 | N22: ='07_결과취합'!M15 -> 0 | O22: =IF(N22<>"",N22,M22) -> 0 | P22: =IF(O22="","",IF(O22="S",5,IF(O22="A",4,IF(O22="B",3,IF(O22="C",2,IF(O22="D",1,0)))))) -> 0
A23: ='01_인적정보'!A15 -> 11 | B23: ='01_인적정보'!B15 -> BSS-011 | C23: ='01_인적정보'!C15 -> 마장엽 | D23: ='01_인적정보'!E15 -> BIM컨설팅 | E23: ='01_인적정보'!H15 -> G5 | F23: =IFERROR(VLOOKUP('01_인적정보'!M15,'13_직무역할DB'!$A$5:$L$70,4,FALSE),"") -> 직무 관리(부서장) | G23: =IFERROR(VLOOKUP('01_인적정보'!M15,'13_직무역할DB'!$A$5:$L$70,5,FALSE),"") -> BIM 컨설팅 조직의 목표와 방향을 설정·관리하고 프로젝트 포트폴리오 운영 및 성과 달성을 총괄하는 역할. | H23: ='07_결과취합'!G16 -> 0 | I23: ='07_결과취합'!H16 -> 0 | J23: ='07_결과취합'!I16 -> 0 | K23: ='07_결과취합'!J16 -> 0 | L23: ='07_결과취합'!K16 -> 0 | M23: ='07_결과취합'!L16 -> 0 | N23: ='07_결과취합'!M16 -> 0 | O23: =IF(N23<>"",N23,M23) -> 0 | P23: =IF(O23="","",IF(O23="S",5,IF(O23="A",4,IF(O23="B",3,IF(O23="C",2,IF(O23="D",1,0)))))) -> 0
A24: ='01_인적정보'!A16 -> 12 | B24: ='01_인적정보'!B16 -> BSS-012 | C24: ='01_인적정보'!C16 -> 하은주 | D24: ='01_인적정보'!E16 -> 경영전략기획 | E24: ='01_인적정보'!H16 -> G5 | F24: =IFERROR(VLOOKUP('01_인적정보'!M16,'13_직무역할DB'!$A$5:$L$70,4,FALSE),"") -> 직무 관리(부서장) | G24: =IFERROR(VLOOKUP('01_인적정보'!M16,'13_직무역할DB'!$A$5:$L$70,5,FALSE),"") -> 부서 전략 및 목표를 수립하고, 자원 배분·예산 관리·성과 관리를 통해 조직 성과 달성을 책임지고, 부서 내 의사결정을 주도함. | H24: ='07_결과취합'!G17 -> 0 | I24: ='07_결과취합'!H17 -> 0 | J24: ='07_결과취합'!I17 -> 0 | K24: ='07_결과취합'!J17 -> 0 | L24: ='07_결과취합'!K17 -> 0 | M24: ='07_결과취합'!L17 -> 0 | N24: ='07_결과취합'!M17 -> 0 | O24: =IF(N24<>"",N24,M24) -> 0 | P24: =IF(O24="","",IF(O24="S",5,IF(O24="A",4,IF(O24="B",3,IF(O24="C",2,IF(O24="D",1,0)))))) -> 0
... A46: ='01_인적정보'!A38 -> 34 | B46: ='01_인적정보'!B38 -> BSS-034 | C46: ='01_인적정보'!C38 -> 엄보근 | D46: ='01_인적정보'!E38 -> BIM컨설팅 | E46: ='01_인적정보'!H38 -> G1 | F46: =IFERROR(VLOOKUP('01_인적정보'!M38,'13_직무역할DB'!$A$5:$L$70,4,FALSE),"") -> 실무 보조 | G46: =IFERROR(VLOOKUP('01_인적정보'!M38,'13_직무역할DB'!$A$5:$L$70,5,FALSE),"") -> BIM 모델링 기초 작업과 자료 정리를 담당하며 실무 진행을 보조하는 역할. | H46: ='07_결과취합'!G39 -> 0 | I46: ='07_결과취합'!H39 -> 0 | J46: ='07_결과취합'!I39 -> 0 | K46: ='07_결과취합'!J39 -> 0 | L46: ='07_결과취합'!K39 -> 0 | M46: ='07_결과취합'!L39 -> 0 | N46: ='07_결과취합'!M39 -> 0 | O46: =IF(N46<>"",N46,M46) -> 0 | P46: =IF(O46="","",IF(O46="S",5,IF(O46="A",4,IF(O46="B",3,IF(O46="C",2,IF(O46="D",1,0)))))) -> 0
A49: ■ 하반기 역할평가
A50: No. | B50: 사번 | C50: 성명 | D50: 직무 | E50: 역할등급 | F50: 역할명 | G50: 역할정의 | H50: 책임범위 이행 | I50: 의사결정 적절성 | J50: 성과 기여도 | K50: 조직·코칭 | L50: 산출물 완성도 | M50: 1차 평가 (종합) | N50: 2차 평가 (종합) | O50: 확정등급 | P50: 평가점수 | Q50: 강점·개선 소견
A51: ='01_인적정보'!A5 -> 1 | B51: ='01_인적정보'!B5 -> BSS-001 | C51: ='01_인적정보'!C5 -> 이화형 | D51: ='01_인적정보'!E5 -> 프로젝트영업 | E51: ='01_인적정보'!H5 -> G6 | F51: =IFERROR(VLOOKUP('01_인적정보'!M5,'13_직무역할DB'!$A$5:$L$70,4,FALSE),"") -> 사업·조직 관리 | G51: =IFERROR(VLOOKUP('01_인적정보'!M5,'13_직무역할DB'!$A$5:$L$70,5,FALSE),"") -> 회사의 영업전략 수립과 목표 달성을 총괄하며, 주요 고객·파트너십 관리 및 사업 기회를 확대하는 역할. | H51: ='07_결과취합'!G44 -> 0 | I51: ='07_결과취합'!H44 -> 0 | J51: ='07_결과취합'!I44 -> 0 | K51: ='07_결과취합'!J44 -> 0 | L51: ='07_결과취합'!K44 -> 0 | M51: ='07_결과취합'!L44 -> 0 | N51: ='07_결과취합'!M44 -> 0 | O51: =IF(N51<>"",N51,M51) -> 0 | P51: =IF(O51="","",IF(O51="S",5,IF(O51="A",4,IF(O51="B",3,IF(O51="C",2,IF(O51="D",1,0)))))) -> 0
A52: ='01_인적정보'!A6 -> 2 | B52: ='01_인적정보'!B6 -> BSS-002 | C52: ='01_인적정보'!C6 -> 강전용 | D52: ='01_인적정보'!E6 -> 연구개발(R&D) | E52: ='01_인적정보'!H6 -> G6 | F52: =IFERROR(VLOOKUP('01_인적정보'!M6,'13_직무역할DB'!$A$5:$L$70,4,FALSE),"") -> 사업·조직 관리 | G52: =IFERROR(VLOOKUP('01_인적정보'!M6,'13_직무역할DB'!$A$5:$L$70,5,FALSE),"") -> 전사 기술 로드맵과 제품 포트폴리오 전략을 총괄하며 핵심 기술 투자·외부 협력·IP 전략을 통해 사업 경쟁력을 창출하는 역할. | H52: ='07_결과취합'!G45 -> 0 | I52: ='07_결과취합'!H45 -> 0 | J52: ='07_결과취합'!I45 -> 0 | K52: ='07_결과취합'!J45 -> 0 | L52: ='07_결과취합'!K45 -> 0 | M52: ='07_결과취합'!L45 -> 0 | N52: ='07_결과취합'!M45 -> 0 | O52: =IF(N52<>"",N52,M52) -> 0 | P52: =IF(O52="","",IF(O52="S",5,IF(O52="A",4,IF(O52="B",3,IF(O52="C",2,IF(O52="D",1,0)))))) -> 0
A53: ='01_인적정보'!A7 -> 3 | B53: ='01_인적정보'!B7 -> BSS-003 | C53: ='01_인적정보'!C7 -> 김현민 | D53: ='01_인적정보'!E7 -> BIM컨설팅 | E53: ='01_인적정보'!H7 -> G6 | F53: =IFERROR(VLOOKUP('01_인적정보'!M7,'13_직무역할DB'!$A$5:$L$70,4,FALSE),"") -> 사업·조직 관리 | G53: =IFERROR(VLOOKUP('01_인적정보'!M7,'13_직무역할DB'!$A$5:$L$70,5,FALSE),"") -> BIM 컨설팅 전략과 서비스 체계를 총괄하며 대외 협력과 사업 확장을 책임지는 역할. | H53: ='07_결과취합'!G46 -> 0 | I53: ='07_결과취합'!H46 -> 0 | J53: ='07_결과취합'!I46 -> 0 | K53: ='07_결과취합'!J46 -> 0 | L53: ='07_결과취합'!K46 -> 0 | M53: ='07_결과취합'!L46 -> 0 | N53: ='07_결과취합'!M46 -> 0 | O53: =IF(N53<>"",N53,M53) -> 0 | P53: =IF(O53="","",IF(O53="S",5,IF(O53="A",4,IF(O53="B",3,IF(O53="C",2,IF(O53="D",1,0)))))) -> 0
A54: ='01_인적정보'!A8 -> 4 | B54: ='01_인적정보'!B8 -> BSS-004 | C54: ='01_인적정보'!C8 -> 이일곤 | D54: ='01_인적정보'!E8 -> 경영전략기획 | E54: ='01_인적정보'!H8 -> G6 | F54: =IFERROR(VLOOKUP('01_인적정보'!M8,'13_직무역할DB'!$A$5:$L$70,4,FALSE),"") -> 사업·조직 관리 | G54: =IFERROR(VLOOKUP('01_인적정보'!M8,'13_직무역할DB'!$A$5:$L$70,5,FALSE),"") -> 회사의 비전과 중장기 전략을 총괄하며, 경영·인사·재무·마케팅 등 핵심 기능을 통합 관리하고, 전사 의사결정·대외 협력·리스크 관리를 주도함. | H54: ='07_결과취합'!G47 -> 0 | I54: ='07_결과취합'!H47 -> 0 | J54: ='07_결과취합'!I47 -> 0 | K54: ='07_결과취합'!J47 -> 0 | L54: ='07_결과취합'!K47 -> 0 | M54: ='07_결과취합'!L47 -> 0 | N54: ='07_결과취합'!M47 -> 0 | O54: =IF(N54<>"",N54,M54) -> 0 | P54: =IF(O54="","",IF(O54="S",5,IF(O54="A",4,IF(O54="B",3,IF(O54="C",2,IF(O54="D",1,0)))))) -> 0
A55: ='01_인적정보'!A9 -> 5 | B55: ='01_인적정보'!B9 -> BSS-005 | C55: ='01_인적정보'!C9 -> 송헌영 | D55: ='01_인적정보'!E9 -> 경영전략기획 | E55: ='01_인적정보'!H9 -> G6 | F55: =IFERROR(VLOOKUP('01_인적정보'!M9,'13_직무역할DB'!$A$5:$L$70,4,FALSE),"") -> 사업·조직 관리 | G55: =IFERROR(VLOOKUP('01_인적정보'!M9,'13_직무역할DB'!$A$5:$L$70,5,FALSE),"") -> 회사의 비전과 중장기 전략을 총괄하며, 경영·인사·재무·마케팅 등 핵심 기능을 통합 관리하고, 전사 의사결정·대외 협력·리스크 관리를 주도함. | H55: ='07_결과취합'!G48 -> 0 | I55: ='07_결과취합'!H48 -> 0 | J55: ='07_결과취합'!I48 -> 0 | K55: ='07_결과취합'!J48 -> 0 | L55: ='07_결과취합'!K48 -> 0 | M55: ='07_결과취합'!L48 -> 0 | N55: ='07_결과취합'!M48 -> 0 | O55: =IF(N55<>"",N55,M55) -> 0 | P55: =IF(O55="","",IF(O55="S",5,IF(O55="A",4,IF(O55="B",3,IF(O55="C",2,IF(O55="D",1,0)))))) -> 0
A56: ='01_인적정보'!A10 -> 6 | B56: ='01_인적정보'!B10 -> BSS-006 | C56: ='01_인적정보'!C10 -> 이재용 | D56: ='01_인적정보'!E10 -> 경영전략기획 | E56: ='01_인적정보'!H10 -> G6 | F56: =IFERROR(VLOOKUP('01_인적정보'!M10,'13_직무역할DB'!$A$5:$L$70,4,FALSE),"") -> 사업·조직 관리 | G56: =IFERROR(VLOOKUP('01_인적정보'!M10,'13_직무역할DB'!$A$5:$L$70,5,FALSE),"") -> 회사의 비전과 중장기 전략을 총괄하며, 경영·인사·재무·마케팅 등 핵심 기능을 통합 관리하고, 전사 의사결정·대외 협력·리스크 관리를 주도함. | H56: ='07_결과취합'!G49 -> 0 | I56: ='07_결과취합'!H49 -> 0 | J56: ='07_결과취합'!I49 -> 0 | K56: ='07_결과취합'!J49 -> 0 | L56: ='07_결과취합'!K49 -> 0 | M56: ='07_결과취합'!L49 -> 0 | N56: ='07_결과취합'!M49 -> 0 | O56: =IF(N56<>"",N56,M56) -> 0 | P56: =IF(O56="","",IF(O56="S",5,IF(O56="A",4,IF(O56="B",3,IF(O56="C",2,IF(O56="D",1,0)))))) -> 0
A57: ='01_인적정보'!A11 -> 7 | B57: ='01_인적정보'!B11 -> BSS-007 | C57: ='01_인적정보'!C11 -> 이진행 | D57: ='01_인적정보'!E11 -> 교육·기술지원 | E57: ='01_인적정보'!H11 -> G5 | F57: =IFERROR(VLOOKUP('01_인적정보'!M11,'13_직무역할DB'!$A$5:$L$70,4,FALSE),"") -> 직무 관리(부서장) | G57: =IFERROR(VLOOKUP('01_인적정보'!M11,'13_직무역할DB'!$A$5:$L$70,5,FALSE),"") -> 교육 조직의 목표·예산·인력을 관리하고 과정 기획·운영 품질을 총괄하며 대외 인증·평가 대응을 주도하는 역할. | H57: ='07_결과취합'!G50 -> 0 | I57: ='07_결과취합'!H50 -> 0 | J57: ='07_결과취합'!I50 -> 0 | K57: ='07_결과취합'!J50 -> 0 | L57: ='07_결과취합'!K50 -> 0 | M57: ='07_결과취합'!L50 -> 0 | N57: ='07_결과취합'!M50 -> 0 | O57: =IF(N57<>"",N57,M57) -> 0 | P57: =IF(O57="","",IF(O57="S",5,IF(O57="A",4,IF(O57="B",3,IF(O57="C",2,IF(O57="D",1,0)))))) -> 0
A58: ='01_인적정보'!A12 -> 8 | B58: ='01_인적정보'!B12 -> BSS-008 | C58: ='01_인적정보'!C12 -> 김민수 | D58: ='01_인적정보'!E12 -> 교육·기술지원 | E58: ='01_인적정보'!H12 -> G5 | F58: =IFERROR(VLOOKUP('01_인적정보'!M12,'13_직무역할DB'!$A$5:$L$70,4,FALSE),"") -> 직무 관리(부서장) | G58: =IFERROR(VLOOKUP('01_인적정보'!M12,'13_직무역할DB'!$A$5:$L$70,5,FALSE),"") -> 교육 조직의 목표·예산·인력을 관리하고 과정 기획·운영 품질을 총괄하며 대외 인증·평가 대응을 주도하는 역할. | H58: ='07_결과취합'!G51 -> 0 | I58: ='07_결과취합'!H51 -> 0 | J58: ='07_결과취합'!I51 -> 0 | K58: ='07_결과취합'!J51 -> 0 | L58: ='07_결과취합'!K51 -> 0 | M58: ='07_결과취합'!L51 -> 0 | N58: ='07_결과취합'!M51 -> 0 | O58: =IF(N58<>"",N58,M58) -> 0 | P58: =IF(O58="","",IF(O58="S",5,IF(O58="A",4,IF(O58="B",3,IF(O58="C",2,IF(O58="D",1,0)))))) -> 0
A59: ='01_인적정보'!A13 -> 9 | B59: ='01_인적정보'!B13 -> BSS-009 | C59: ='01_인적정보'!C13 -> 박남식 | D59: ='01_인적정보'!E13 -> BIM컨설팅 | E59: ='01_인적정보'!H13 -> G5 | F59: =IFERROR(VLOOKUP('01_인적정보'!M13,'13_직무역할DB'!$A$5:$L$70,4,FALSE),"") -> 직무 관리(부서장) | G59: =IFERROR(VLOOKUP('01_인적정보'!M13,'13_직무역할DB'!$A$5:$L$70,5,FALSE),"") -> BIM 컨설팅 조직의 목표와 방향을 설정·관리하고 프로젝트 포트폴리오 운영 및 성과 달성을 총괄하는 역할. | H59: ='07_결과취합'!G52 -> 0 | I59: ='07_결과취합'!H52 -> 0 | J59: ='07_결과취합'!I52 -> 0 | K59: ='07_결과취합'!J52 -> 0 | L59: ='07_결과취합'!K52 -> 0 | M59: ='07_결과취합'!L52 -> 0 | N59: ='07_결과취합'!M52 -> 0 | O59: =IF(N59<>"",N59,M59) -> 0 | P59: =IF(O59="","",IF(O59="S",5,IF(O59="A",4,IF(O59="B",3,IF(O59="C",2,IF(O59="D",1,0)))))) -> 0
A60: ='01_인적정보'!A14 -> 10 | B60: ='01_인적정보'!B14 -> BSS-010 | C60: ='01_인적정보'!C14 -> 신재민 | D60: ='01_인적정보'!E14 -> BIM컨설팅 | E60: ='01_인적정보'!H14 -> G5 | F60: =IFERROR(VLOOKUP('01_인적정보'!M14,'13_직무역할DB'!$A$5:$L$70,4,FALSE),"") -> 직무 관리(부서장) | G60: =IFERROR(VLOOKUP('01_인적정보'!M14,'13_직무역할DB'!$A$5:$L$70,5,FALSE),"") -> BIM 컨설팅 조직의 목표와 방향을 설정·관리하고 프로젝트 포트폴리오 운영 및 성과 달성을 총괄하는 역할. | H60: ='07_결과취합'!G53 -> 0 | I60: ='07_결과취합'!H53 -> 0 | J60: ='07_결과취합'!I53 -> 0 | K60: ='07_결과취합'!J53 -> 0 | L60: ='07_결과취합'!K53 -> 0 | M60: ='07_결과취합'!L53 -> 0 | N60: ='07_결과취합'!M53 -> 0 | O60: =IF(N60<>"",N60,M60) -> 0 | P60: =IF(O60="","",IF(O60="S",5,IF(O60="A",4,IF(O60="B",3,IF(O60="C",2,IF(O60="D",1,0)))))) -> 0
A61: ='01_인적정보'!A15 -> 11 | B61: ='01_인적정보'!B15 -> BSS-011 | C61: ='01_인적정보'!C15 -> 마장엽 | D61: ='01_인적정보'!E15 -> BIM컨설팅 | E61: ='01_인적정보'!H15 -> G5 | F61: =IFERROR(VLOOKUP('01_인적정보'!M15,'13_직무역할DB'!$A$5:$L$70,4,FALSE),"") -> 직무 관리(부서장) | G61: =IFERROR(VLOOKUP('01_인적정보'!M15,'13_직무역할DB'!$A$5:$L$70,5,FALSE),"") -> BIM 컨설팅 조직의 목표와 방향을 설정·관리하고 프로젝트 포트폴리오 운영 및 성과 달성을 총괄하는 역할. | H61: ='07_결과취합'!G54 -> 0 | I61: ='07_결과취합'!H54 -> 0 | J61: ='07_결과취합'!I54 -> 0 | K61: ='07_결과취합'!J54 -> 0 | L61: ='07_결과취합'!K54 -> 0 | M61: ='07_결과취합'!L54 -> 0 | N61: ='07_결과취합'!M54 -> 0 | O61: =IF(N61<>"",N61,M61) -> 0 | P61: =IF(O61="","",IF(O61="S",5,IF(O61="A",4,IF(O61="B",3,IF(O61="C",2,IF(O61="D",1,0)))))) -> 0
A62: ='01_인적정보'!A16 -> 12 | B62: ='01_인적정보'!B16 -> BSS-012 | C62: ='01_인적정보'!C16 -> 하은주 | D62: ='01_인적정보'!E16 -> 경영전략기획 | E62: ='01_인적정보'!H16 -> G5 | F62: =IFERROR(VLOOKUP('01_인적정보'!M16,'13_직무역할DB'!$A$5:$L$70,4,FALSE),"") -> 직무 관리(부서장) | G62: =IFERROR(VLOOKUP('01_인적정보'!M16,'13_직무역할DB'!$A$5:$L$70,5,FALSE),"") -> 부서 전략 및 목표를 수립하고, 자원 배분·예산 관리·성과 관리를 통해 조직 성과 달성을 책임지고, 부서 내 의사결정을 주도함. | H62: ='07_결과취합'!G55 -> 0 | I62: ='07_결과취합'!H55 -> 0 | J62: ='07_결과취합'!I55 -> 0 | K62: ='07_결과취합'!J55 -> 0 | L62: ='07_결과취합'!K55 -> 0 | M62: ='07_결과취합'!L55 -> 0 | N62: ='07_결과취합'!M55 -> 0 | O62: =IF(N62<>"",N62,M62) -> 0 | P62: =IF(O62="","",IF(O62="S",5,IF(O62="A",4,IF(O62="B",3,IF(O62="C",2,IF(O62="D",1,0)))))) -> 0
... A84: ='01_인적정보'!A38 -> 34 | B84: ='01_인적정보'!B38 -> BSS-034 | C84: ='01_인적정보'!C38 -> 엄보근 | D84: ='01_인적정보'!E38 -> BIM컨설팅 | E84: ='01_인적정보'!H38 -> G1 | F84: =IFERROR(VLOOKUP('01_인적정보'!M38,'13_직무역할DB'!$A$5:$L$70,4,FALSE),"") -> 실무 보조 | G84: =IFERROR(VLOOKUP('01_인적정보'!M38,'13_직무역할DB'!$A$5:$L$70,5,FALSE),"") -> BIM 모델링 기초 작업과 자료 정리를 담당하며 실무 진행을 보조하는 역할. | H84: ='07_결과취합'!G77 -> 0 | I84: ='07_결과취합'!H77 -> 0 | J84: ='07_결과취합'!I77 -> 0 | K84: ='07_결과취합'!J77 -> 0 | L84: ='07_결과취합'!K77 -> 0 | M84: ='07_결과취합'!L77 -> 0 | N84: ='07_결과취합'!M77 -> 0 | O84: =IF(N84<>"",N84,M84) -> 0 | P84: =IF(O84="","",IF(O84="S",5,IF(O84="A",4,IF(O84="B",3,IF(O84="C",2,IF(O84="D",1,0)))))) -> 0

Sheet 05_공통역량평가
A1: 공통역량평가 — 전사 공통 11개 역량
A2: 직무 전문성 15% / 분석력 10% / ... / 지속가능 기여 5% (가중합산 100%)
A4: ■ 상반기 공통역량평가
A5: No. | B5: 사번 | C5: 성명 | D5: 역할등급 | E5: 직무 전문성 (역량 #1) | F5: 분석력 (역량 #2) | G5: 기획/실행력 (역량 #3) | H5: 자원·시간 관리 (역량 #4) | I5: 협업 능력 (역량 #5) | J5: 소통 능력 (역량 #6) | K5: 윤리/책임감 (역량 #7) | L5: 업무 태도 (역량 #8) | M5: 혁신 역량 (역량 #9) | N5: 프로세스 개선 (역량 #10) | O5: 지속가능 기여 (역량 #11) | P5: 가중합산 | Q5: 등급 | R5: 소견
A6: ='01_인적정보'!A5 -> 1 | B6: ='01_인적정보'!B5 -> BSS-001 | C6: ='01_인적정보'!C5 -> 이화형 | D6: ='01_인적정보'!H5 -> G6 | E6: ='07_결과취합'!N6 -> 0 | F6: ='07_결과취합'!O6 -> 0 | G6: ='07_결과취합'!P6 -> 0 | H6: ='07_결과취합'!Q6 -> 0 | I6: ='07_결과취합'!R6 -> 0 | J6: ='07_결과취합'!S6 -> 0 | K6: ='07_결과취합'!T6 -> 0 | L6: ='07_결과취합'!U6 -> 0 | ... O6: ='07_결과취합'!X6 -> 0 | P6: =IF(COUNTBLANK(E6:O6)>0,"",'02_의사결정·종합결과'!$E$53*(IF(E6="S",5,IF(E6="A",4,IF(E6="B",3,IF(E6="C",2,IF(E6="D",1,0))))))+'02_의사결정·종합결과'!$E$54*(IF(F6="S",5,IF(F6="A",4,IF(F6="B",3,IF(F6="C",2,IF(F6="D",1,0))))))+'02_의사결정·종합결과'!$E$55*(IF(G6="S",5,IF(G6="A",4,IF(G6="B",3,IF(G6="C",2,IF(G6="D",1,0))))))+'02_의사결정·종합결과'!$E$56*(IF(H6="S",5,IF(H6="A",4,IF(H6="B",3,IF(H6="C",2,IF(H6="D",1,0))))))+'02_의사결정·종합결과'!$E$57*(IF(I6="S",5,IF(I6="A",4,IF(I6="B",3,IF(I6="C",2,IF(I6="D",1,0))))))+'02_의사결정·종합결과'!$E$58*(IF(J6="S",5,IF(J6="A",4,IF(J6="B",3,IF(J6="C",2,IF(J6="D",1,0))))))+'02_의사결정·종합결과'!$E$59*(IF(K6="S",5,IF(K6="A",4,IF(K6="B",3,IF(K6="C",2,IF(K6="D",1,0))))))+'02_의사결정·종합결과'!$E$60*(IF(L6="S",5,IF(L6="A",4,IF(L6="B",3,IF(L6="C",2,IF(L6="D",1,0))))))+'02_의사결정·종합결과'!$E$61*(IF(M6="S",5,IF(M6="A",4,IF(M6="B",3,IF(M6="C",2,IF(M6="D",1,0))))))+'02_의사결정·종합결과'!$E$62*(IF(N6="S",5,IF(N6="A",4,IF(N6="B",3,IF(N6="C",2,IF(N6="D",1,0))))))+'02_의사결정·종합결과'!$E$63*(IF(O6="S",5,IF(O6="A",4,IF(O6="B",3,IF(O6="C",2,IF(O6="D",1,0))))))) -> 0 | Q6: =IF(P6="","",IF(P6>=4.5,"S",IF(P6>=3.5,"A",IF(P6>=2.5,"B",IF(P6>=1.5,"C","D"))))) -> D
A7: ='01_인적정보'!A6 -> 2 | B7: ='01_인적정보'!B6 -> BSS-002 | C7: ='01_인적정보'!C6 -> 강전용 | D7: ='01_인적정보'!H6 -> G6 | E7: ='07_결과취합'!N7 -> 0 | F7: ='07_결과취합'!O7 -> 0 | G7: ='07_결과취합'!P7 -> 0 | H7: ='07_결과취합'!Q7 -> 0 | I7: ='07_결과취합'!R7 -> 0 | J7: ='07_결과취합'!S7 -> 0 | K7: ='07_결과취합'!T7 -> 0 | L7: ='07_결과취합'!U7 -> 0 | ... O7: ='07_결과취합'!X7 -> 0 | P7: =IF(COUNTBLANK(E7:O7)>0,"",'02_의사결정·종합결과'!$E$53*(IF(E7="S",5,IF(E7="A",4,IF(E7="B",3,IF(E7="C",2,IF(E7="D",1,0))))))+'02_의사결정·종합결과'!$E$54*(IF(F7="S",5,IF(F7="A",4,IF(F7="B",3,IF(F7="C",2,IF(F7="D",1,0))))))+'02_의사결정·종합결과'!$E$55*(IF(G7="S",5,IF(G7="A",4,IF(G7="B",3,IF(G7="C",2,IF(G7="D",1,0))))))+'02_의사결정·종합결과'!$E$56*(IF(H7="S",5,IF(H7="A",4,IF(H7="B",3,IF(H7="C",2,IF(H7="D",1,0))))))+'02_의사결정·종합결과'!$E$57*(IF(I7="S",5,IF(I7="A",4,IF(I7="B",3,IF(I7="C",2,IF(I7="D",1,0))))))+'02_의사결정·종합결과'!$E$58*(IF(J7="S",5,IF(J7="A",4,IF(J7="B",3,IF(J7="C",2,IF(J7="D",1,0))))))+'02_의사결정·종합결과'!$E$59*(IF(K7="S",5,IF(K7="A",4,IF(K7="B",3,IF(K7="C",2,IF(K7="D",1,0))))))+'02_의사결정·종합결과'!$E$60*(IF(L7="S",5,IF(L7="A",4,IF(L7="B",3,IF(L7="C",2,IF(L7="D",1,0))))))+'02_의사결정·종합결과'!$E$61*(IF(M7="S",5,IF(M7="A",4,IF(M7="B",3,IF(M7="C",2,IF(M7="D",1,0))))))+'02_의사결정·종합결과'!$E$62*(IF(N7="S",5,IF(N7="A",4,IF(N7="B",3,IF(N7="C",2,IF(N7="D",1,0))))))+'02_의사결정·종합결과'!$E$63*(IF(O7="S",5,IF(O7="A",4,IF(O7="B",3,IF(O7="C",2,IF(O7="D",1,0))))))) -> 0 | Q7: =IF(P7="","",IF(P7>=4.5,"S",IF(P7>=3.5,"A",IF(P7>=2.5,"B",IF(P7>=1.5,"C","D"))))) -> D
A8: ='01_인적정보'!A7 -> 3 | B8: ='01_인적정보'!B7 -> BSS-003 | C8: ='01_인적정보'!C7 -> 김현민 | D8: ='01_인적정보'!H7 -> G6 | E8: ='07_결과취합'!N8 -> 0 | F8: ='07_결과취합'!O8 -> 0 | G8: ='07_결과취합'!P8 -> 0 | H8: ='07_결과취합'!Q8 -> 0 | I8: ='07_결과취합'!R8 -> 0 | J8: ='07_결과취합'!S8 -> 0 | K8: ='07_결과취합'!T8 -> 0 | L8: ='07_결과취합'!U8 -> 0 | ... O8: ='07_결과취합'!X8 -> 0 | P8: =IF(COUNTBLANK(E8:O8)>0,"",'02_의사결정·종합결과'!$E$53*(IF(E8="S",5,IF(E8="A",4,IF(E8="B",3,IF(E8="C",2,IF(E8="D",1,0))))))+'02_의사결정·종합결과'!$E$54*(IF(F8="S",5,IF(F8="A",4,IF(F8="B",3,IF(F8="C",2,IF(F8="D",1,0))))))+'02_의사결정·종합결과'!$E$55*(IF(G8="S",5,IF(G8="A",4,IF(G8="B",3,IF(G8="C",2,IF(G8="D",1,0))))))+'02_의사결정·종합결과'!$E$56*(IF(H8="S",5,IF(H8="A",4,IF(H8="B",3,IF(H8="C",2,IF(H8="D",1,0))))))+'02_의사결정·종합결과'!$E$57*(IF(I8="S",5,IF(I8="A",4,IF(I8="B",3,IF(I8="C",2,IF(I8="D",1,0))))))+'02_의사결정·종합결과'!$E$58*(IF(J8="S",5,IF(J8="A",4,IF(J8="B",3,IF(J8="C",2,IF(J8="D",1,0))))))+'02_의사결정·종합결과'!$E$59*(IF(K8="S",5,IF(K8="A",4,IF(K8="B",3,IF(K8="C",2,IF(K8="D",1,0))))))+'02_의사결정·종합결과'!$E$60*(IF(L8="S",5,IF(L8="A",4,IF(L8="B",3,IF(L8="C",2,IF(L8="D",1,0))))))+'02_의사결정·종합결과'!$E$61*(IF(M8="S",5,IF(M8="A",4,IF(M8="B",3,IF(M8="C",2,IF(M8="D",1,0))))))+'02_의사결정·종합결과'!$E$62*(IF(N8="S",5,IF(N8="A",4,IF(N8="B",3,IF(N8="C",2,IF(N8="D",1,0))))))+'02_의사결정·종합결과'!$E$63*(IF(O8="S",5,IF(O8="A",4,IF(O8="B",3,IF(O8="C",2,IF(O8="D",1,0))))))) -> 0 | Q8: =IF(P8="","",IF(P8>=4.5,"S",IF(P8>=3.5,"A",IF(P8>=2.5,"B",IF(P8>=1.5,"C","D"))))) -> D
A9: ='01_인적정보'!A8 -> 4 | B9: ='01_인적정보'!B8 -> BSS-004 | C9: ='01_인적정보'!C8 -> 이일곤 | D9: ='01_인적정보'!H8 -> G6 | E9: ='07_결과취합'!N9 -> 0 | F9: ='07_결과취합'!O9 -> 0 | G9: ='07_결과취합'!P9 -> 0 | H9: ='07_결과취합'!Q9 -> 0 | I9: ='07_결과취합'!R9 -> 0 | J9: ='07_결과취합'!S9 -> 0 | K9: ='07_결과취합'!T9 -> 0 | L9: ='07_결과취합'!U9 -> 0 | ... O9: ='07_결과취합'!X9 -> 0 | P9: =IF(COUNTBLANK(E9:O9)>0,"",'02_의사결정·종합결과'!$E$53*(IF(E9="S",5,IF(E9="A",4,IF(E9="B",3,IF(E9="C",2,IF(E9="D",1,0))))))+'02_의사결정·종합결과'!$E$54*(IF(F9="S",5,IF(F9="A",4,IF(F9="B",3,IF(F9="C",2,IF(F9="D",1,0))))))+'02_의사결정·종합결과'!$E$55*(IF(G9="S",5,IF(G9="A",4,IF(G9="B",3,IF(G9="C",2,IF(G9="D",1,0))))))+'02_의사결정·종합결과'!$E$56*(IF(H9="S",5,IF(H9="A",4,IF(H9="B",3,IF(H9="C",2,IF(H9="D",1,0))))))+'02_의사결정·종합결과'!$E$57*(IF(I9="S",5,IF(I9="A",4,IF(I9="B",3,IF(I9="C",2,IF(I9="D",1,0))))))+'02_의사결정·종합결과'!$E$58*(IF(J9="S",5,IF(J9="A",4,IF(J9="B",3,IF(J9="C",2,IF(J9="D",1,0))))))+'02_의사결정·종합결과'!$E$59*(IF(K9="S",5,IF(K9="A",4,IF(K9="B",3,IF(K9="C",2,IF(K9="D",1,0))))))+'02_의사결정·종합결과'!$E$60*(IF(L9="S",5,IF(L9="A",4,IF(L9="B",3,IF(L9="C",2,IF(L9="D",1,0))))))+'02_의사결정·종합결과'!$E$61*(IF(M9="S",5,IF(M9="A",4,IF(M9="B",3,IF(M9="C",2,IF(M9="D",1,0))))))+'02_의사결정·종합결과'!$E$62*(IF(N9="S",5,IF(N9="A",4,IF(N9="B",3,IF(N9="C",2,IF(N9="D",1,0))))))+'02_의사결정·종합결과'!$E$63*(IF(O9="S",5,IF(O9="A",4,IF(O9="B",3,IF(O9="C",2,IF(O9="D",1,0))))))) -> 0 | Q9: =IF(P9="","",IF(P9>=4.5,"S",IF(P9>=3.5,"A",IF(P9>=2.5,"B",IF(P9>=1.5,"C","D"))))) -> D
A10: ='01_인적정보'!A9 -> 5 | B10: ='01_인적정보'!B9 -> BSS-005 | C10: ='01_인적정보'!C9 -> 송헌영 | D10: ='01_인적정보'!H9 -> G6 | E10: ='07_결과취합'!N10 -> 0 | F10: ='07_결과취합'!O10 -> 0 | G10: ='07_결과취합'!P10 -> 0 | H10: ='07_결과취합'!Q10 -> 0 | I10: ='07_결과취합'!R10 -> 0 | J10: ='07_결과취합'!S10 -> 0 | K10: ='07_결과취합'!T10 -> 0 | L10: ='07_결과취합'!U10 -> 0 | ... O10: ='07_결과취합'!X10 -> 0 | P10: =IF(COUNTBLANK(E10:O10)>0,"",'02_의사결정·종합결과'!$E$53*(IF(E10="S",5,IF(E10="A",4,IF(E10="B",3,IF(E10="C",2,IF(E10="D",1,0))))))+'02_의사결정·종합결과'!$E$54*(IF(F10="S",5,IF(F10="A",4,IF(F10="B",3,IF(F10="C",2,IF(F10="D",1,0))))))+'02_의사결정·종합결과'!$E$55*(IF(G10="S",5,IF(G10="A",4,IF(G10="B",3,IF(G10="C",2,IF(G10="D",1,0))))))+'02_의사결정·종합결과'!$E$56*(IF(H10="S",5,IF(H10="A",4,IF(H10="B",3,IF(H10="C",2,IF(H10="D",1,0))))))+'02_의사결정·종합결과'!$E$57*(IF(I10="S",5,IF(I10="A",4,IF(I10="B",3,IF(I10="C",2,IF(I10="D",1,0))))))+'02_의사결정·종합결과'!$E$58*(IF(J10="S",5,IF(J10="A",4,IF(J10="B",3,IF(J10="C",2,IF(J10="D",1,0))))))+'02_의사결정·종합결과'!$E$59*(IF(K10="S",5,IF(K10="A",4,IF(K10="B",3,IF(K10="C",2,IF(K10="D",1,0))))))+'02_의사결정·종합결과'!$E$60*(IF(L10="S",5,IF(L10="A",4,IF(L10="B",3,IF(L10="C",2,IF(L10="D",1,0))))))+'02_의사결정·종합결과'!$E$61*(IF(M10="S",5,IF(M10="A",4,IF(M10="B",3,IF(M10="C",2,IF(M10="D",1,0))))))+'02_의사결정·종합결과'!$E$62*(IF(N10="S",5,IF(N10="A",4,IF(N10="B",3,IF(N10="C",2,IF(N10="D",1,0))))))+'02_의사결정·종합결과'!$E$63*(IF(O10="S",5,IF(O10="A",4,IF(O10="B",3,IF(O10="C",2,IF(O10="D",1,0))))))) -> 0 | Q10: =IF(P10="","",IF(P10>=4.5,"S",IF(P10>=3.5,"A",IF(P10>=2.5,"B",IF(P10>=1.5,"C","D"))))) -> D
A11: ='01_인적정보'!A10 -> 6 | B11: ='01_인적정보'!B10 -> BSS-006 | C11: ='01_인적정보'!C10 -> 이재용 | D11: ='01_인적정보'!H10 -> G6 | E11: ='07_결과취합'!N11 -> 0 | F11: ='07_결과취합'!O11 -> 0 | G11: ='07_결과취합'!P11 -> 0 | H11: ='07_결과취합'!Q11 -> 0 | I11: ='07_결과취합'!R11 -> 0 | J11: ='07_결과취합'!S11 -> 0 | K11: ='07_결과취합'!T11 -> 0 | L11: ='07_결과취합'!U11 -> 0 | ... O11: ='07_결과취합'!X11 -> 0 | P11: =IF(COUNTBLANK(E11:O11)>0,"",'02_의사결정·종합결과'!$E$53*(IF(E11="S",5,IF(E11="A",4,IF(E11="B",3,IF(E11="C",2,IF(E11="D",1,0))))))+'02_의사결정·종합결과'!$E$54*(IF(F11="S",5,IF(F11="A",4,IF(F11="B",3,IF(F11="C",2,IF(F11="D",1,0))))))+'02_의사결정·종합결과'!$E$55*(IF(G11="S",5,IF(G11="A",4,IF(G11="B",3,IF(G11="C",2,IF(G11="D",1,0))))))+'02_의사결정·종합결과'!$E$56*(IF(H11="S",5,IF(H11="A",4,IF(H11="B",3,IF(H11="C",2,IF(H11="D",1,0))))))+'02_의사결정·종합결과'!$E$57*(IF(I11="S",5,IF(I11="A",4,IF(I11="B",3,IF(I11="C",2,IF(I11="D",1,0))))))+'02_의사결정·종합결과'!$E$58*(IF(J11="S",5,IF(J11="A",4,IF(J11="B",3,IF(J11="C",2,IF(J11="D",1,0))))))+'02_의사결정·종합결과'!$E$59*(IF(K11="S",5,IF(K11="A",4,IF(K11="B",3,IF(K11="C",2,IF(K11="D",1,0))))))+'02_의사결정·종합결과'!$E$60*(IF(L11="S",5,IF(L11="A",4,IF(L11="B",3,IF(L11="C",2,IF(L11="D",1,0))))))+'02_의사결정·종합결과'!$E$61*(IF(M11="S",5,IF(M11="A",4,IF(M11="B",3,IF(M11="C",2,IF(M11="D",1,0))))))+'02_의사결정·종합결과'!$E$62*(IF(N11="S",5,IF(N11="A",4,IF(N11="B",3,IF(N11="C",2,IF(N11="D",1,0))))))+'02_의사결정·종합결과'!$E$63*(IF(O11="S",5,IF(O11="A",4,IF(O11="B",3,IF(O11="C",2,IF(O11="D",1,0))))))) -> 0 | Q11: =IF(P11="","",IF(P11>=4.5,"S",IF(P11>=3.5,"A",IF(P11>=2.5,"B",IF(P11>=1.5,"C","D"))))) -> D
A12: ='01_인적정보'!A11 -> 7 | B12: ='01_인적정보'!B11 -> BSS-007 | C12: ='01_인적정보'!C11 -> 이진행 | D12: ='01_인적정보'!H11 -> G5 | E12: ='07_결과취합'!N12 -> 0 | F12: ='07_결과취합'!O12 -> 0 | G12: ='07_결과취합'!P12 -> 0 | H12: ='07_결과취합'!Q12 -> 0 | I12: ='07_결과취합'!R12 -> 0 | J12: ='07_결과취합'!S12 -> 0 | K12: ='07_결과취합'!T12 -> 0 | L12: ='07_결과취합'!U12 -> 0 | ... O12: ='07_결과취합'!X12 -> 0 | P12: =IF(COUNTBLANK(E12:O12)>0,"",'02_의사결정·종합결과'!$E$53*(IF(E12="S",5,IF(E12="A",4,IF(E12="B",3,IF(E12="C",2,IF(E12="D",1,0))))))+'02_의사결정·종합결과'!$E$54*(IF(F12="S",5,IF(F12="A",4,IF(F12="B",3,IF(F12="C",2,IF(F12="D",1,0))))))+'02_의사결정·종합결과'!$E$55*(IF(G12="S",5,IF(G12="A",4,IF(G12="B",3,IF(G12="C",2,IF(G12="D",1,0))))))+'02_의사결정·종합결과'!$E$56*(IF(H12="S",5,IF(H12="A",4,IF(H12="B",3,IF(H12="C",2,IF(H12="D",1,0))))))+'02_의사결정·종합결과'!$E$57*(IF(I12="S",5,IF(I12="A",4,IF(I12="B",3,IF(I12="C",2,IF(I12="D",1,0))))))+'02_의사결정·종합결과'!$E$58*(IF(J12="S",5,IF(J12="A",4,IF(J12="B",3,IF(J12="C",2,IF(J12="D",1,0))))))+'02_의사결정·종합결과'!$E$59*(IF(K12="S",5,IF(K12="A",4,IF(K12="B",3,IF(K12="C",2,IF(K12="D",1,0))))))+'02_의사결정·종합결과'!$E$60*(IF(L12="S",5,IF(L12="A",4,IF(L12="B",3,IF(L12="C",2,IF(L12="D",1,0))))))+'02_의사결정·종합결과'!$E$61*(IF(M12="S",5,IF(M12="A",4,IF(M12="B",3,IF(M12="C",2,IF(M12="D",1,0))))))+'02_의사결정·종합결과'!$E$62*(IF(N12="S",5,IF(N12="A",4,IF(N12="B",3,IF(N12="C",2,IF(N12="D",1,0))))))+'02_의사결정·종합결과'!$E$63*(IF(O12="S",5,IF(O12="A",4,IF(O12="B",3,IF(O12="C",2,IF(O12="D",1,0))))))) -> 0 | Q12: =IF(P12="","",IF(P12>=4.5,"S",IF(P12>=3.5,"A",IF(P12>=2.5,"B",IF(P12>=1.5,"C","D"))))) -> D
A13: ='01_인적정보'!A12 -> 8 | B13: ='01_인적정보'!B12 -> BSS-008 | C13: ='01_인적정보'!C12 -> 김민수 | D13: ='01_인적정보'!H12 -> G5 | E13: ='07_결과취합'!N13 -> 0 | F13: ='07_결과취합'!O13 -> 0 | G13: ='07_결과취합'!P13 -> 0 | H13: ='07_결과취합'!Q13 -> 0 | I13: ='07_결과취합'!R13 -> 0 | J13: ='07_결과취합'!S13 -> 0 | K13: ='07_결과취합'!T13 -> 0 | L13: ='07_결과취합'!U13 -> 0 | ... O13: ='07_결과취합'!X13 -> 0 | P13: =IF(COUNTBLANK(E13:O13)>0,"",'02_의사결정·종합결과'!$E$53*(IF(E13="S",5,IF(E13="A",4,IF(E13="B",3,IF(E13="C",2,IF(E13="D",1,0))))))+'02_의사결정·종합결과'!$E$54*(IF(F13="S",5,IF(F13="A",4,IF(F13="B",3,IF(F13="C",2,IF(F13="D",1,0))))))+'02_의사결정·종합결과'!$E$55*(IF(G13="S",5,IF(G13="A",4,IF(G13="B",3,IF(G13="C",2,IF(G13="D",1,0))))))+'02_의사결정·종합결과'!$E$56*(IF(H13="S",5,IF(H13="A",4,IF(H13="B",3,IF(H13="C",2,IF(H13="D",1,0))))))+'02_의사결정·종합결과'!$E$57*(IF(I13="S",5,IF(I13="A",4,IF(I13="B",3,IF(I13="C",2,IF(I13="D",1,0))))))+'02_의사결정·종합결과'!$E$58*(IF(J13="S",5,IF(J13="A",4,IF(J13="B",3,IF(J13="C",2,IF(J13="D",1,0))))))+'02_의사결정·종합결과'!$E$59*(IF(K13="S",5,IF(K13="A",4,IF(K13="B",3,IF(K13="C",2,IF(K13="D",1,0))))))+'02_의사결정·종합결과'!$E$60*(IF(L13="S",5,IF(L13="A",4,IF(L13="B",3,IF(L13="C",2,IF(L13="D",1,0))))))+'02_의사결정·종합결과'!$E$61*(IF(M13="S",5,IF(M13="A",4,IF(M13="B",3,IF(M13="C",2,IF(M13="D",1,0))))))+'02_의사결정·종합결과'!$E$62*(IF(N13="S",5,IF(N13="A",4,IF(N13="B",3,IF(N13="C",2,IF(N13="D",1,0))))))+'02_의사결정·종합결과'!$E$63*(IF(O13="S",5,IF(O13="A",4,IF(O13="B",3,IF(O13="C",2,IF(O13="D",1,0))))))) -> 0 | Q13: =IF(P13="","",IF(P13>=4.5,"S",IF(P13>=3.5,"A",IF(P13>=2.5,"B",IF(P13>=1.5,"C","D"))))) -> D
A14: ='01_인적정보'!A13 -> 9 | B14: ='01_인적정보'!B13 -> BSS-009 | C14: ='01_인적정보'!C13 -> 박남식 | D14: ='01_인적정보'!H13 -> G5 | E14: ='07_결과취합'!N14 -> 0 | F14: ='07_결과취합'!O14 -> 0 | G14: ='07_결과취합'!P14 -> 0 | H14: ='07_결과취합'!Q14 -> 0 | I14: ='07_결과취합'!R14 -> 0 | J14: ='07_결과취합'!S14 -> 0 | K14: ='07_결과취합'!T14 -> 0 | L14: ='07_결과취합'!U14 -> 0 | ... O14: ='07_결과취합'!X14 -> 0 | P14: =IF(COUNTBLANK(E14:O14)>0,"",'02_의사결정·종합결과'!$E$53*(IF(E14="S",5,IF(E14="A",4,IF(E14="B",3,IF(E14="C",2,IF(E14="D",1,0))))))+'02_의사결정·종합결과'!$E$54*(IF(F14="S",5,IF(F14="A",4,IF(F14="B",3,IF(F14="C",2,IF(F14="D",1,0))))))+'02_의사결정·종합결과'!$E$55*(IF(G14="S",5,IF(G14="A",4,IF(G14="B",3,IF(G14="C",2,IF(G14="D",1,0))))))+'02_의사결정·종합결과'!$E$56*(IF(H14="S",5,IF(H14="A",4,IF(H14="B",3,IF(H14="C",2,IF(H14="D",1,0))))))+'02_의사결정·종합결과'!$E$57*(IF(I14="S",5,IF(I14="A",4,IF(I14="B",3,IF(I14="C",2,IF(I14="D",1,0))))))+'02_의사결정·종합결과'!$E$58*(IF(J14="S",5,IF(J14="A",4,IF(J14="B",3,IF(J14="C",2,IF(J14="D",1,0))))))+'02_의사결정·종합결과'!$E$59*(IF(K14="S",5,IF(K14="A",4,IF(K14="B",3,IF(K14="C",2,IF(K14="D",1,0))))))+'02_의사결정·종합결과'!$E$60*(IF(L14="S",5,IF(L14="A",4,IF(L14="B",3,IF(L14="C",2,IF(L14="D",1,0))))))+'02_의사결정·종합결과'!$E$61*(IF(M14="S",5,IF(M14="A",4,IF(M14="B",3,IF(M14="C",2,IF(M14="D",1,0))))))+'02_의사결정·종합결과'!$E$62*(IF(N14="S",5,IF(N14="A",4,IF(N14="B",3,IF(N14="C",2,IF(N14="D",1,0))))))+'02_의사결정·종합결과'!$E$63*(IF(O14="S",5,IF(O14="A",4,IF(O14="B",3,IF(O14="C",2,IF(O14="D",1,0))))))) -> 0 | Q14: =IF(P14="","",IF(P14>=4.5,"S",IF(P14>=3.5,"A",IF(P14>=2.5,"B",IF(P14>=1.5,"C","D"))))) -> D
A15: ='01_인적정보'!A14 -> 10 | B15: ='01_인적정보'!B14 -> BSS-010 | C15: ='01_인적정보'!C14 -> 신재민 | D15: ='01_인적정보'!H14 -> G5 | E15: ='07_결과취합'!N15 -> 0 | F15: ='07_결과취합'!O15 -> 0 | G15: ='07_결과취합'!P15 -> 0 | H15: ='07_결과취합'!Q15 -> 0 | I15: ='07_결과취합'!R15 -> 0 | J15: ='07_결과취합'!S15 -> 0 | K15: ='07_결과취합'!T15 -> 0 | L15: ='07_결과취합'!U15 -> 0 | ... O15: ='07_결과취합'!X15 -> 0 | P15: =IF(COUNTBLANK(E15:O15)>0,"",'02_의사결정·종합결과'!$E$53*(IF(E15="S",5,IF(E15="A",4,IF(E15="B",3,IF(E15="C",2,IF(E15="D",1,0))))))+'02_의사결정·종합결과'!$E$54*(IF(F15="S",5,IF(F15="A",4,IF(F15="B",3,IF(F15="C",2,IF(F15="D",1,0))))))+'02_의사결정·종합결과'!$E$55*(IF(G15="S",5,IF(G15="A",4,IF(G15="B",3,IF(G15="C",2,IF(G15="D",1,0))))))+'02_의사결정·종합결과'!$E$56*(IF(H15="S",5,IF(H15="A",4,IF(H15="B",3,IF(H15="C",2,IF(H15="D",1,0))))))+'02_의사결정·종합결과'!$E$57*(IF(I15="S",5,IF(I15="A",4,IF(I15="B",3,IF(I15="C",2,IF(I15="D",1,0))))))+'02_의사결정·종합결과'!$E$58*(IF(J15="S",5,IF(J15="A",4,IF(J15="B",3,IF(J15="C",2,IF(J15="D",1,0))))))+'02_의사결정·종합결과'!$E$59*(IF(K15="S",5,IF(K15="A",4,IF(K15="B",3,IF(K15="C",2,IF(K15="D",1,0))))))+'02_의사결정·종합결과'!$E$60*(IF(L15="S",5,IF(L15="A",4,IF(L15="B",3,IF(L15="C",2,IF(L15="D",1,0))))))+'02_의사결정·종합결과'!$E$61*(IF(M15="S",5,IF(M15="A",4,IF(M15="B",3,IF(M15="C",2,IF(M15="D",1,0))))))+'02_의사결정·종합결과'!$E$62*(IF(N15="S",5,IF(N15="A",4,IF(N15="B",3,IF(N15="C",2,IF(N15="D",1,0))))))+'02_의사결정·종합결과'!$E$63*(IF(O15="S",5,IF(O15="A",4,IF(O15="B",3,IF(O15="C",2,IF(O15="D",1,0))))))) -> 0 | Q15: =IF(P15="","",IF(P15>=4.5,"S",IF(P15>=3.5,"A",IF(P15>=2.5,"B",IF(P15>=1.5,"C","D"))))) -> D
A16: ='01_인적정보'!A15 -> 11 | B16: ='01_인적정보'!B15 -> BSS-011 | C16: ='01_인적정보'!C15 -> 마장엽 | D16: ='01_인적정보'!H15 -> G5 | E16: ='07_결과취합'!N16 -> 0 | F16: ='07_결과취합'!O16 -> 0 | G16: ='07_결과취합'!P16 -> 0 | H16: ='07_결과취합'!Q16 -> 0 | I16: ='07_결과취합'!R16 -> 0 | J16: ='07_결과취합'!S16 -> 0 | K16: ='07_결과취합'!T16 -> 0 | L16: ='07_결과취합'!U16 -> 0 | ... O16: ='07_결과취합'!X16 -> 0 | P16: =IF(COUNTBLANK(E16:O16)>0,"",'02_의사결정·종합결과'!$E$53*(IF(E16="S",5,IF(E16="A",4,IF(E16="B",3,IF(E16="C",2,IF(E16="D",1,0))))))+'02_의사결정·종합결과'!$E$54*(IF(F16="S",5,IF(F16="A",4,IF(F16="B",3,IF(F16="C",2,IF(F16="D",1,0))))))+'02_의사결정·종합결과'!$E$55*(IF(G16="S",5,IF(G16="A",4,IF(G16="B",3,IF(G16="C",2,IF(G16="D",1,0))))))+'02_의사결정·종합결과'!$E$56*(IF(H16="S",5,IF(H16="A",4,IF(H16="B",3,IF(H16="C",2,IF(H16="D",1,0))))))+'02_의사결정·종합결과'!$E$57*(IF(I16="S",5,IF(I16="A",4,IF(I16="B",3,IF(I16="C",2,IF(I16="D",1,0))))))+'02_의사결정·종합결과'!$E$58*(IF(J16="S",5,IF(J16="A",4,IF(J16="B",3,IF(J16="C",2,IF(J16="D",1,0))))))+'02_의사결정·종합결과'!$E$59*(IF(K16="S",5,IF(K16="A",4,IF(K16="B",3,IF(K16="C",2,IF(K16="D",1,0))))))+'02_의사결정·종합결과'!$E$60*(IF(L16="S",5,IF(L16="A",4,IF(L16="B",3,IF(L16="C",2,IF(L16="D",1,0))))))+'02_의사결정·종합결과'!$E$61*(IF(M16="S",5,IF(M16="A",4,IF(M16="B",3,IF(M16="C",2,IF(M16="D",1,0))))))+'02_의사결정·종합결과'!$E$62*(IF(N16="S",5,IF(N16="A",4,IF(N16="B",3,IF(N16="C",2,IF(N16="D",1,0))))))+'02_의사결정·종합결과'!$E$63*(IF(O16="S",5,IF(O16="A",4,IF(O16="B",3,IF(O16="C",2,IF(O16="D",1,0))))))) -> 0 | Q16: =IF(P16="","",IF(P16>=4.5,"S",IF(P16>=3.5,"A",IF(P16>=2.5,"B",IF(P16>=1.5,"C","D"))))) -> D
A17: ='01_인적정보'!A16 -> 12 | B17: ='01_인적정보'!B16 -> BSS-012 | C17: ='01_인적정보'!C16 -> 하은주 | D17: ='01_인적정보'!H16 -> G5 | E17: ='07_결과취합'!N17 -> 0 | F17: ='07_결과취합'!O17 -> 0 | G17: ='07_결과취합'!P17 -> 0 | H17: ='07_결과취합'!Q17 -> 0 | I17: ='07_결과취합'!R17 -> 0 | J17: ='07_결과취합'!S17 -> 0 | K17: ='07_결과취합'!T17 -> 0 | L17: ='07_결과취합'!U17 -> 0 | ... O17: ='07_결과취합'!X17 -> 0 | P17: =IF(COUNTBLANK(E17:O17)>0,"",'02_의사결정·종합결과'!$E$53*(IF(E17="S",5,IF(E17="A",4,IF(E17="B",3,IF(E17="C",2,IF(E17="D",1,0))))))+'02_의사결정·종합결과'!$E$54*(IF(F17="S",5,IF(F17="A",4,IF(F17="B",3,IF(F17="C",2,IF(F17="D",1,0))))))+'02_의사결정·종합결과'!$E$55*(IF(G17="S",5,IF(G17="A",4,IF(G17="B",3,IF(G17="C",2,IF(G17="D",1,0))))))+'02_의사결정·종합결과'!$E$56*(IF(H17="S",5,IF(H17="A",4,IF(H17="B",3,IF(H17="C",2,IF(H17="D",1,0))))))+'02_의사결정·종합결과'!$E$57*(IF(I17="S",5,IF(I17="A",4,IF(I17="B",3,IF(I17="C",2,IF(I17="D",1,0))))))+'02_의사결정·종합결과'!$E$58*(IF(J17="S",5,IF(J17="A",4,IF(J17="B",3,IF(J17="C",2,IF(J17="D",1,0))))))+'02_의사결정·종합결과'!$E$59*(IF(K17="S",5,IF(K17="A",4,IF(K17="B",3,IF(K17="C",2,IF(K17="D",1,0))))))+'02_의사결정·종합결과'!$E$60*(IF(L17="S",5,IF(L17="A",4,IF(L17="B",3,IF(L17="C",2,IF(L17="D",1,0))))))+'02_의사결정·종합결과'!$E$61*(IF(M17="S",5,IF(M17="A",4,IF(M17="B",3,IF(M17="C",2,IF(M17="D",1,0))))))+'02_의사결정·종합결과'!$E$62*(IF(N17="S",5,IF(N17="A",4,IF(N17="B",3,IF(N17="C",2,IF(N17="D",1,0))))))+'02_의사결정·종합결과'!$E$63*(IF(O17="S",5,IF(O17="A",4,IF(O17="B",3,IF(O17="C",2,IF(O17="D",1,0))))))) -> 0 | Q17: =IF(P17="","",IF(P17>=4.5,"S",IF(P17>=3.5,"A",IF(P17>=2.5,"B",IF(P17>=1.5,"C","D"))))) -> D
... A39: ='01_인적정보'!A38 -> 34 | B39: ='01_인적정보'!B38 -> BSS-034 | C39: ='01_인적정보'!C38 -> 엄보근 | D39: ='01_인적정보'!H38 -> G1 | E39: ='07_결과취합'!N39 -> 0 | F39: ='07_결과취합'!O39 -> 0 | G39: ='07_결과취합'!P39 -> 0 | H39: ='07_결과취합'!Q39 -> 0 | I39: ='07_결과취합'!R39 -> 0 | J39: ='07_결과취합'!S39 -> 0 | K39: ='07_결과취합'!T39 -> 0 | L39: ='07_결과취합'!U39 -> 0 | ... O39: ='07_결과취합'!X39 -> 0 | P39: =IF(COUNTBLANK(E39:O39)>0,"",'02_의사결정·종합결과'!$E$53*(IF(E39="S",5,IF(E39="A",4,IF(E39="B",3,IF(E39="C",2,IF(E39="D",1,0))))))+'02_의사결정·종합결과'!$E$54*(IF(F39="S",5,IF(F39="A",4,IF(F39="B",3,IF(F39="C",2,IF(F39="D",1,0))))))+'02_의사결정·종합결과'!$E$55*(IF(G39="S",5,IF(G39="A",4,IF(G39="B",3,IF(G39="C",2,IF(G39="D",1,0))))))+'02_의사결정·종합결과'!$E$56*(IF(H39="S",5,IF(H39="A",4,IF(H39="B",3,IF(H39="C",2,IF(H39="D",1,0))))))+'02_의사결정·종합결과'!$E$57*(IF(I39="S",5,IF(I39="A",4,IF(I39="B",3,IF(I39="C",2,IF(I39="D",1,0))))))+'02_의사결정·종합결과'!$E$58*(IF(J39="S",5,IF(J39="A",4,IF(J39="B",3,IF(J39="C",2,IF(J39="D",1,0))))))+'02_의사결정·종합결과'!$E$59*(IF(K39="S",5,IF(K39="A",4,IF(K39="B",3,IF(K39="C",2,IF(K39="D",1,0))))))+'02_의사결정·종합결과'!$E$60*(IF(L39="S",5,IF(L39="A",4,IF(L39="B",3,IF(L39="C",2,IF(L39="D",1,0))))))+'02_의사결정·종합결과'!$E$61*(IF(M39="S",5,IF(M39="A",4,IF(M39="B",3,IF(M39="C",2,IF(M39="D",1,0))))))+'02_의사결정·종합결과'!$E$62*(IF(N39="S",5,IF(N39="A",4,IF(N39="B",3,IF(N39="C",2,IF(N39="D",1,0))))))+'02_의사결정·종합결과'!$E$63*(IF(O39="S",5,IF(O39="A",4,IF(O39="B",3,IF(O39="C",2,IF(O39="D",1,0))))))) -> 0 | Q39: =IF(P39="","",IF(P39>=4.5,"S",IF(P39>=3.5,"A",IF(P39>=2.5,"B",IF(P39>=1.5,"C","D"))))) -> D
A42: ■ 하반기 공통역량평가
A43: No. | B43: 사번 | C43: 성명 | D43: 역할등급 | E43: 직무 전문성 (역량 #1) | F43: 분석력 (역량 #2) | G43: 기획/실행력 (역량 #3) | H43: 자원·시간 관리 (역량 #4) | I43: 협업 능력 (역량 #5) | J43: 소통 능력 (역량 #6) | K43: 윤리/책임감 (역량 #7) | L43: 업무 태도 (역량 #8) | M43: 혁신 역량 (역량 #9) | N43: 프로세스 개선 (역량 #10) | O43: 지속가능 기여 (역량 #11) | P43: 가중합산 | Q43: 등급 | R43: 소견
A44: ='01_인적정보'!A5 -> 1 | B44: ='01_인적정보'!B5 -> BSS-001 | C44: ='01_인적정보'!C5 -> 이화형 | D44: ='01_인적정보'!H5 -> G6 | E44: ='07_결과취합'!N44 -> 0 | F44: ='07_결과취합'!O44 -> 0 | G44: ='07_결과취합'!P44 -> 0 | H44: ='07_결과취합'!Q44 -> 0 | I44: ='07_결과취합'!R44 -> 0 | J44: ='07_결과취합'!S44 -> 0 | K44: ='07_결과취합'!T44 -> 0 | L44: ='07_결과취합'!U44 -> 0 | ... O44: ='07_결과취합'!X44 -> 0 | P44: =IF(COUNTBLANK(E44:O44)>0,"",'02_의사결정·종합결과'!$E$53*(IF(E44="S",5,IF(E44="A",4,IF(E44="B",3,IF(E44="C",2,IF(E44="D",1,0))))))+'02_의사결정·종합결과'!$E$54*(IF(F44="S",5,IF(F44="A",4,IF(F44="B",3,IF(F44="C",2,IF(F44="D",1,0))))))+'02_의사결정·종합결과'!$E$55*(IF(G44="S",5,IF(G44="A",4,IF(G44="B",3,IF(G44="C",2,IF(G44="D",1,0))))))+'02_의사결정·종합결과'!$E$56*(IF(H44="S",5,IF(H44="A",4,IF(H44="B",3,IF(H44="C",2,IF(H44="D",1,0))))))+'02_의사결정·종합결과'!$E$57*(IF(I44="S",5,IF(I44="A",4,IF(I44="B",3,IF(I44="C",2,IF(I44="D",1,0))))))+'02_의사결정·종합결과'!$E$58*(IF(J44="S",5,IF(J44="A",4,IF(J44="B",3,IF(J44="C",2,IF(J44="D",1,0))))))+'02_의사결정·종합결과'!$E$59*(IF(K44="S",5,IF(K44="A",4,IF(K44="B",3,IF(K44="C",2,IF(K44="D",1,0))))))+'02_의사결정·종합결과'!$E$60*(IF(L44="S",5,IF(L44="A",4,IF(L44="B",3,IF(L44="C",2,IF(L44="D",1,0))))))+'02_의사결정·종합결과'!$E$61*(IF(M44="S",5,IF(M44="A",4,IF(M44="B",3,IF(M44="C",2,IF(M44="D",1,0))))))+'02_의사결정·종합결과'!$E$62*(IF(N44="S",5,IF(N44="A",4,IF(N44="B",3,IF(N44="C",2,IF(N44="D",1,0))))))+'02_의사결정·종합결과'!$E$63*(IF(O44="S",5,IF(O44="A",4,IF(O44="B",3,IF(O44="C",2,IF(O44="D",1,0))))))) -> 0 | Q44: =IF(P44="","",IF(P44>=4.5,"S",IF(P44>=3.5,"A",IF(P44>=2.5,"B",IF(P44>=1.5,"C","D"))))) -> D
A45: ='01_인적정보'!A6 -> 2 | B45: ='01_인적정보'!B6 -> BSS-002 | C45: ='01_인적정보'!C6 -> 강전용 | D45: ='01_인적정보'!H6 -> G6 | E45: ='07_결과취합'!N45 -> 0 | F45: ='07_결과취합'!O45 -> 0 | G45: ='07_결과취합'!P45 -> 0 | H45: ='07_결과취합'!Q45 -> 0 | I45: ='07_결과취합'!R45 -> 0 | J45: ='07_결과취합'!S45 -> 0 | K45: ='07_결과취합'!T45 -> 0 | L45: ='07_결과취합'!U45 -> 0 | ... O45: ='07_결과취합'!X45 -> 0 | P45: =IF(COUNTBLANK(E45:O45)>0,"",'02_의사결정·종합결과'!$E$53*(IF(E45="S",5,IF(E45="A",4,IF(E45="B",3,IF(E45="C",2,IF(E45="D",1,0))))))+'02_의사결정·종합결과'!$E$54*(IF(F45="S",5,IF(F45="A",4,IF(F45="B",3,IF(F45="C",2,IF(F45="D",1,0))))))+'02_의사결정·종합결과'!$E$55*(IF(G45="S",5,IF(G45="A",4,IF(G45="B",3,IF(G45="C",2,IF(G45="D",1,0))))))+'02_의사결정·종합결과'!$E$56*(IF(H45="S",5,IF(H45="A",4,IF(H45="B",3,IF(H45="C",2,IF(H45="D",1,0))))))+'02_의사결정·종합결과'!$E$57*(IF(I45="S",5,IF(I45="A",4,IF(I45="B",3,IF(I45="C",2,IF(I45="D",1,0))))))+'02_의사결정·종합결과'!$E$58*(IF(J45="S",5,IF(J45="A",4,IF(J45="B",3,IF(J45="C",2,IF(J45="D",1,0))))))+'02_의사결정·종합결과'!$E$59*(IF(K45="S",5,IF(K45="A",4,IF(K45="B",3,IF(K45="C",2,IF(K45="D",1,0))))))+'02_의사결정·종합결과'!$E$60*(IF(L45="S",5,IF(L45="A",4,IF(L45="B",3,IF(L45="C",2,IF(L45="D",1,0))))))+'02_의사결정·종합결과'!$E$61*(IF(M45="S",5,IF(M45="A",4,IF(M45="B",3,IF(M45="C",2,IF(M45="D",1,0))))))+'02_의사결정·종합결과'!$E$62*(IF(N45="S",5,IF(N45="A",4,IF(N45="B",3,IF(N45="C",2,IF(N45="D",1,0))))))+'02_의사결정·종합결과'!$E$63*(IF(O45="S",5,IF(O45="A",4,IF(O45="B",3,IF(O45="C",2,IF(O45="D",1,0))))))) -> 0 | Q45: =IF(P45="","",IF(P45>=4.5,"S",IF(P45>=3.5,"A",IF(P45>=2.5,"B",IF(P45>=1.5,"C","D"))))) -> D
A46: ='01_인적정보'!A7 -> 3 | B46: ='01_인적정보'!B7 -> BSS-003 | C46: ='01_인적정보'!C7 -> 김현민 | D46: ='01_인적정보'!H7 -> G6 | E46: ='07_결과취합'!N46 -> 0 | F46: ='07_결과취합'!O46 -> 0 | G46: ='07_결과취합'!P46 -> 0 | H46: ='07_결과취합'!Q46 -> 0 | I46: ='07_결과취합'!R46 -> 0 | J46: ='07_결과취합'!S46 -> 0 | K46: ='07_결과취합'!T46 -> 0 | L46: ='07_결과취합'!U46 -> 0 | ... O46: ='07_결과취합'!X46 -> 0 | P46: =IF(COUNTBLANK(E46:O46)>0,"",'02_의사결정·종합결과'!$E$53*(IF(E46="S",5,IF(E46="A",4,IF(E46="B",3,IF(E46="C",2,IF(E46="D",1,0))))))+'02_의사결정·종합결과'!$E$54*(IF(F46="S",5,IF(F46="A",4,IF(F46="B",3,IF(F46="C",2,IF(F46="D",1,0))))))+'02_의사결정·종합결과'!$E$55*(IF(G46="S",5,IF(G46="A",4,IF(G46="B",3,IF(G46="C",2,IF(G46="D",1,0))))))+'02_의사결정·종합결과'!$E$56*(IF(H46="S",5,IF(H46="A",4,IF(H46="B",3,IF(H46="C",2,IF(H46="D",1,0))))))+'02_의사결정·종합결과'!$E$57*(IF(I46="S",5,IF(I46="A",4,IF(I46="B",3,IF(I46="C",2,IF(I46="D",1,0))))))+'02_의사결정·종합결과'!$E$58*(IF(J46="S",5,IF(J46="A",4,IF(J46="B",3,IF(J46="C",2,IF(J46="D",1,0))))))+'02_의사결정·종합결과'!$E$59*(IF(K46="S",5,IF(K46="A",4,IF(K46="B",3,IF(K46="C",2,IF(K46="D",1,0))))))+'02_의사결정·종합결과'!$E$60*(IF(L46="S",5,IF(L46="A",4,IF(L46="B",3,IF(L46="C",2,IF(L46="D",1,0))))))+'02_의사결정·종합결과'!$E$61*(IF(M46="S",5,IF(M46="A",4,IF(M46="B",3,IF(M46="C",2,IF(M46="D",1,0))))))+'02_의사결정·종합결과'!$E$62*(IF(N46="S",5,IF(N46="A",4,IF(N46="B",3,IF(N46="C",2,IF(N46="D",1,0))))))+'02_의사결정·종합결과'!$E$63*(IF(O46="S",5,IF(O46="A",4,IF(O46="B",3,IF(O46="C",2,IF(O46="D",1,0))))))) -> 0 | Q46: =IF(P46="","",IF(P46>=4.5,"S",IF(P46>=3.5,"A",IF(P46>=2.5,"B",IF(P46>=1.5,"C","D"))))) -> D
