Workbook

Sheet 00_운영가이드
A1: 베이시스소프트 HR 통합관리 시스템 - 운영 가이드
A2: 1년 2회 평가(상·하반기) → 등급 결정 → 임금 조정 → 페이밴드 검증의 End-to-End 운영 도구
A4: ■ 우리가 하려는 일 (핵심 의사결정 4단계)
A5: 단계 | B5: 핵심 작업 | C5: 의사결정 | D5: 주요 내용
A6: STEP 1 | B6: 평가 실시 | C6: 연 2회(상반기·하반기) 개인별 3축 평가 | D6: 역할평가 + 공통역량평가 + 직무역량평가
A7: STEP 2 | B7: 등급 결정 | C7: 회사 전체 KPI + 개인 평가 결과 종합 | D7: 3축 가중통합 → 최종 등급(S/A/B/C/D) 산출
A8: STEP 3 | B8: 임금 조정 | C8: 평가 등급에 따라 차년도 기본연봉 인상 | D8: S 6% / A 5% / B 4% / C 3% / D 2% (+ 승진 가산)
A9: STEP 4 | B9: 페이밴드 관리 | C9: 전체 임직원 임금이 역할등급별 범위 내 유지 | D9: Min/Mid/Max 검증 → 이탈자 조정 권고
A12: ■ 우리가 가진 도구 (산출물)
A13: 도구 | B13: 파일/시트 | E13: 용도·운영 주체
A14: 통합 관리 시트 | B14: 본 파일 (HR 통합관리시스템 v5.xlsx) | E14: HR 담당자가 모든 평가 결과를 모아 종합 등급·인상률·페이밴드를 산출. 본 파일.
A15: 직무별 평가지 | B15: 평가지_2026_v2/평가지_{부서}_2026_v2.xlsx (부서별 6종) | E15: 부서장(1·2차 평가자)이 작성. HR이 배포·회수 후 [복사용 행]을 통합시트에 옮김.
A17: ■ HR 담당자 운영 흐름 (한 평가 사이클)
A18: 단계 | B18: 내용
A19: ① 준비 | B19: 01_인적정보 확인 + 15_직원별책무매핑에서 직원별 메인 책무 O/X 선택
A20: ② 배포 | B20: 평가지_{부서}_2026_v2.xlsx 6개 파일을 각 부서장에게 배포 (이메일/공유폴더)
A21: ③ 평가 | B21: 부서장(1·2차 평가자)이 각자 등급(S/A/B/C/D) 입력 → 시트가 가중평균·등급 자동 산출
A22: ④ 회수 | B22: 평가지 회수 (보통 평가 마감 후 1주일 내)
A23: ⑤ 입력 | B23: 각 평가지 직원 시트 하단 [복사용 입력 행] A~U 21개 셀 통째 복사 → 본 파일 07a/07b의 해당 사번 행 G~AA에 [값 붙여넣기]
A24: ⑥ 점검 | B24: 00_운영현황판에서 누락·이상 알림 확인 → 보완
A25: ⑦ 결과 확인 | B25: 08_종합평가 (최종등급) / 09_보상연계 (인상률·신규연봉) / 10_성과급관리 / 11_페이밴드검증 / 12_시뮬레이션
A27: ■ 본 파일 시트 역할 (18개)
A28: 시트 | B28: 역할 | G28: 유형
A29: 00_운영가이드 | B29: 본 시트 - 운영 흐름·시트 안내 | G29: 안내
A30: 00_운영현황판 | B30: 평가 진행률·이상 알림·등급 분포 한눈에 | G30: 대시보드
A31: 01_인적정보 | B31: 직원 마스터(34명). 사번·역할등급 입력 | G31: HR 입력
A32: 02_의사결정·종합결과 | B32: 가중치·인상률·페이밴드·평가자 비중 설정 | G32: HR 입력
A33: 03_전사업적평가 | B33: 전사 KPI 실적 입력 → 성과급 재원 가산 | G33: HR 입력
A34: 04_역할평가 | B34: 자동 산출 (07a/07b 입력값 기반) | G34: 자동
A35: 05_공통역량평가 | B35: 자동 산출 (11개 역량 가중합산) | G35: 자동
A36: 06_직무역량평가 | B36: 자동 산출 (개인별 메인 책무 평균) | G36: 자동
A37: 07a_상반기입력 | B37: 부서별 평가지의 [복사용 행]을 여기 G~AA에 붙여넣기 | G37: HR 입력 (핵심)
A38: 07b_하반기입력 | B38: 하반기 동일 구조 | G38: HR 입력 (핵심)
A39: 08_종합평가 | B39: 3축 가중통합 → 최종 등급 | G39: 자동
... A46: 15_직원별책무매핑 | B46: 직원별 메인 책무 O/X 선택 | G46: HR 입력
A48: ■ 색상 범례
B49: 노란셀 | C49: HR이 직접 입력 | F49: 연두셀 | G49: 자동 계산 - 수정 금지
B50: 회색셀 | C50: 참고 라벨 | F50: 주황셀 | G50: 안내·중요 표시
B51: S/A 등급 | C51: 탁월·우수 | F51: D 등급/이탈 | G51: 즉시 조치
A81: 본 시스템은 베이시스소프트의 임금·평가 운영을 위해 설계되었습니다. 사용 중 의문 사항은 컨설팅 담당자 또는 시앤피컨설팅 이석주 컨설턴트에게 문의해 주세요.

Sheet 00_운영현황판
A1: ★ HR 운영 현황판 (모든 평가 진행 상황 한눈에)
A2: 이 시트가 평가 사이클의 컨트롤 타워. 여기서 진행률·이상신호 확인 후 각 시트로 진입.
A3: ✻ 이 시트는 평가 사이클이 진행되는 동안 매일 가장 먼저 확인하는 페이지입니다. 진행률·이상 알림으로 현재 상태를 즉시 파악하세요.
A4: ■ 평가 진행 현황
A5: 지표 | B5: 상반기 진행 | C5: 하반기 진행 | D5: 상태
A6: 총 직원수 | B6: =COUNTA('01_인적정보'!C6:C65) | C6: =B6 | D6: =IF(B$6=0,"",IF(B6>=B$6,"✓ 완료",IF(B6>0,"진행중","미시작")))
A7: 역할평가 입력완료 | B7: =COUNTA('07a_상반기입력'!L6:L39) | C7: =COUNTA('07b_하반기입력'!L6:L39) | D7: =IF(B$6=0,"",IF(B7>=B$6,"✓ 완료",IF(B7>0,"진행중","미시작")))
A8: 공통역량 입력완료 | B8: =COUNTA('07a_상반기입력'!N6:N39) | C8: =COUNTA('07b_하반기입력'!N6:N39) | D8: =IF(B$6=0,"",IF(B8>=B$6,"✓ 완료",IF(B8>0,"진행중","미시작")))
A9: 직무역량 입력완료 | B9: =COUNTA('07a_상반기입력'!Y6:Y39) | C9: =COUNTA('07b_하반기입력'!Y6:Y39) | D9: =IF(B$6=0,"",IF(B9>=B$6,"✓ 완료",IF(B9>0,"진행중","미시작")))
A10: 종합평가 산출완료 | B10: =COUNTA('08_종합평가'!U6:U39) | C10: =B10 | D10: =IF(B$6=0,"",IF(B10>=B$6,"✓ 완료",IF(B10>0,"진행중","미시작")))
A12: ■ 이상 알림 (자동 점검)
A13: 가중치 합계 검증 (G6~G1) | B13: =IF(SUMPRODUCT(('02_의사결정·종합결과'!E16:E22<>1)*1)>0,"✗ 가중치 합계 ≠ 100% 행 존재","✓ 모든 가중치 OK")
A14: 상반기 등급 누락자 수 | B14: =COUNTA('01_인적정보'!B6:B39) - COUNTA('07a_상반기입력'!L6:L39)
A15: 하반기 등급 누락자 수 | B15: =COUNTA('01_인적정보'!B6:B39) - COUNTA('07b_하반기입력'!L6:L39)
A16: 페이밴드 이탈자 수 | B16: =SUMPRODUCT(('09_보상연계'!O6:O39<'09_보상연계'!L6:L39)+('09_보상연계'!O6:O39>'09_보상연계'!M6:M39))
A17: 페이밴드 검증 시트의 이탈자 (참조) | B17: =SUM('11_페이밴드검증'!H6:H12)
A19: ■ 평가 등급 분포 (전사 종합)
A20: 등급 | B20: S | C20: A | D20: B | E20: C | F20: D
A21: 인원수 | B21: =COUNTIF('08_종합평가'!U6:U39,"S") | C21: =COUNTIF('08_종합평가'!U6:U39,"A") | D21: =COUNTIF('08_종합평가'!U6:U39,"B") | E21: =COUNTIF('08_종합평가'!U6:U39,"C") | F21: =COUNTIF('08_종합평가'!U6:U39,"D")
A24: ■ 오늘 해야 할 일
A25: 1) 01_인적정보에서 직원 명단·역할등급(G5-M/G5-S 포함) 확인
A26: 2) 15_직원별책무매핑에서 직원별 메인 책무 선택 (신규 - 평가 시작 전 필수)
A27: 3) 부서별 평가지 6종 배포 (평가자에게 이메일/공유폴더 전달)
A28: 4) 평가지 회수 후 07a/07b 상·하반기 입력 시트에 등급 입력
A29: 5) 본 시트에서 진행률·이상알림 확인
A30: 6) 모두 완료 시 08~12 산출 시트에서 결과 확인

Sheet 01_인적정보
A1: 임직원 명부 마스터 (Master)
A2: 사번을 키로 모든 시트를 연결. 노란셀만 직접 수정. ★ G5는 M(부서장)/S(스페셜리스트)로 분리되어 있습니다.
A5: No. | B5: 사번 | C5: 성명 | D5: 직군 | E5: 직무 | F5: 부서 | G5: 기존직급 | H5: 역할등급 | I5: 입사일 | J5: 근속연수 | K5: 기존연봉 | L5: 주요 책무 수 | M5: 조회키(직무_등급) | N5: 비고
A6: 1 | B6: BSS-001 | C6: 이화형 | D6: 영업 | E6: 프로젝트영업 | F6: 스마트사업부 | G6: 전무 | H6: G6 | I6: 2014-01-08 | J6: =IFERROR(ROUND((TODAY()-DATEVALUE(I6))/365,1),"") | K6: 72500000 | L6: =IFERROR(INDEX('15_직원별책무매핑'!$E:$E,MATCH(B6,'15_직원별책무매핑'!$B:$B,0)),0) | M6: =E6&"_"&H6
A7: 2 | B7: BSS-002 | C7: 강전용 | D7: 연구&개발 | E7: 연구개발(R&D) | F7: R&D본부 | G7: 상무 | H7: G6 | I7: 2014-02-15 | J7: =IFERROR(ROUND((TODAY()-DATEVALUE(I7))/365,1),"") | K7: 68870000 | L7: =IFERROR(INDEX('15_직원별책무매핑'!$E:$E,MATCH(B7,'15_직원별책무매핑'!$B:$B,0)),0) | M7: =E7&"_"&H7
A8: 3 | B8: BSS-003 | C8: 김현민 | D8: 설계 | E8: BIM컨설팅 | F8: 컨설팅본부 | G8: 상무 | H8: G6 | I8: 2014-03-22 | J8: =IFERROR(ROUND((TODAY()-DATEVALUE(I8))/365,1),"") | K8: 67500000 | L8: =IFERROR(INDEX('15_직원별책무매핑'!$E:$E,MATCH(B8,'15_직원별책무매핑'!$B:$B,0)),0) | M8: =E8&"_"&H8
A9: 4 | B9: BSS-004 | C9: 이일곤 | D9: 경영관리 | E9: 경영전략기획 | F9: 경영전략실 | G9: 이사 | H9: G6 | I9: 2014-04-01 | J9: =IFERROR(ROUND((TODAY()-DATEVALUE(I9))/365,1),"") | K9: 64530000 | L9: =IFERROR(INDEX('15_직원별책무매핑'!$E:$E,MATCH(B9,'15_직원별책무매핑'!$B:$B,0)),0) | M9: =E9&"_"&H9
A10: 5 | B10: BSS-005 | C10: 송헌영 | D10: 경영관리 | E10: 경영전략기획 | F10: 경영전략실 | G10: 이사 | H10: G6 | I10: 2015-05-08 | J10: =IFERROR(ROUND((TODAY()-DATEVALUE(I10))/365,1),"") | K10: 65180000 | L10: =IFERROR(INDEX('15_직원별책무매핑'!$E:$E,MATCH(B10,'15_직원별책무매핑'!$B:$B,0)),0) | M10: =E10&"_"&H10
A11: 6 | B11: BSS-006 | C11: 이재용 | D11: 경영관리 | E11: 경영전략기획 | F11: 경영전략실 | G11: 이사 | H11: G6 | I11: 2015-06-15 | J11: =IFERROR(ROUND((TODAY()-DATEVALUE(I11))/365,1),"") | K11: 62000000 | L11: =IFERROR(INDEX('15_직원별책무매핑'!$E:$E,MATCH(B11,'15_직원별책무매핑'!$B:$B,0)),0) | M11: =E11&"_"&H11
A12: 7 | B12: BSS-007 | C12: 이진행 | D12: 교육 및 기술지원 | E12: 교육 | F12: 솔루션본부 | G12: 부장 | H12: G5-M | I12: 2015-07-22 | J12: =IFERROR(ROUND((TODAY()-DATEVALUE(I12))/365,1),"") | K12: 59700000 | L12: =IFERROR(INDEX('15_직원별책무매핑'!$E:$E,MATCH(B12,'15_직원별책무매핑'!$B:$B,0)),0) | M12: =E12&"_"&H12
A13: 8 | B13: BSS-008 | C13: 김민수 | D13: 교육 및 기술지원 | E13: 기술지원 | F13: 솔루션본부 | G13: 부장 | H13: G5-M | I13: 2015-08-01 | J13: =IFERROR(ROUND((TODAY()-DATEVALUE(I13))/365,1),"") | K13: 59050000 | L13: =IFERROR(INDEX('15_직원별책무매핑'!$E:$E,MATCH(B13,'15_직원별책무매핑'!$B:$B,0)),0) | M13: =E13&"_"&H13
A14: 9 | B14: BSS-009 | C14: 박남식 | D14: 설계 | E14: BIM컨설팅 | F14: 컨설팅본부 | G14: 부장 | H14: G5-M | I14: 2016-09-08 | J14: =IFERROR(ROUND((TODAY()-DATEVALUE(I14))/365,1),"") | K14: 59050000 | L14: =IFERROR(INDEX('15_직원별책무매핑'!$E:$E,MATCH(B14,'15_직원별책무매핑'!$B:$B,0)),0) | M14: =E14&"_"&H14
A15: 10 | B15: BSS-010 | C15: 신재민 | D15: 설계 | E15: BIM컨설팅 | F15: 컨설팅본부 | G15: 부장 | H15: G5-S | I15: 2016-10-15 | J15: =IFERROR(ROUND((TODAY()-DATEVALUE(I15))/365,1),"") | K15: 59050000 | L15: =IFERROR(INDEX('15_직원별책무매핑'!$E:$E,MATCH(B15,'15_직원별책무매핑'!$B:$B,0)),0) | M15: =E15&"_"&H15
A16: 11 | B16: BSS-011 | C16: 마장엽 | D16: 설계 | E16: BIM컨설팅 | F16: 컨설팅본부 | G16: 부장 | H16: G5-S | I16: 2016-11-22 | J16: =IFERROR(ROUND((TODAY()-DATEVALUE(I16))/365,1),"") | K16: 57760000 | L16: =IFERROR(INDEX('15_직원별책무매핑'!$E:$E,MATCH(B16,'15_직원별책무매핑'!$B:$B,0)),0) | M16: =E16&"_"&H16
A17: 12 | B17: BSS-012 | C17: 하은주 | D17: 경영관리 | E17: 경영전략기획 | F17: 마케팅팀 | G17: 부장 | H17: G5-M | I17: 2016-12-01 | J17: =IFERROR(ROUND((TODAY()-DATEVALUE(I17))/365,1),"") | K17: 57760000 | L17: =IFERROR(INDEX('15_직원별책무매핑'!$E:$E,MATCH(B17,'15_직원별책무매핑'!$B:$B,0)),0) | M17: =E17&"_"&H17
... A39: 34 | B39: BSS-034 | C39: 엄보근 | D39: 설계 | E39: BIM컨설팅 | F39: 컨설팅본부 | G39: 사원 | H39: G1 | I39: 2022-10-15 | J39: =IFERROR(ROUND((TODAY()-DATEVALUE(I39))/365,1),"") | K39: 32000000 | L39: =IFERROR(INDEX('15_직원별책무매핑'!$E:$E,MATCH(B39,'15_직원별책무매핑'!$B:$B,0)),0) | M39: =E39&"_"&H39
A42: ■ 자동 통계 (역할등급별/직군별/부서별)
A43: 역할등급 | B43: 인원 | L43: =IFERROR(INDEX('15_직원별책무매핑'!$E:$E,MATCH(B43,'15_직원별책무매핑'!$B:$B,0)),0)
A44: G6 | B44: =COUNTIF(H6:H85,"G6") | L44: =IFERROR(INDEX('15_직원별책무매핑'!$E:$E,MATCH(B44,'15_직원별책무매핑'!$B:$B,0)),0)
A45: G5-M | B45: =COUNTIF(H6:H85,"G5-M") | L45: =IFERROR(INDEX('15_직원별책무매핑'!$E:$E,MATCH(B45,'15_직원별책무매핑'!$B:$B,0)),0)
A46: G5-S | B46: =COUNTIF(H6:H85,"G5-S") | L46: =IFERROR(INDEX('15_직원별책무매핑'!$E:$E,MATCH(B46,'15_직원별책무매핑'!$B:$B,0)),0)
A47: G4 | B47: =COUNTIF(H6:H85,"G4") | L47: =IFERROR(INDEX('15_직원별책무매핑'!$E:$E,MATCH(B47,'15_직원별책무매핑'!$B:$B,0)),0)
A48: G3 | B48: =COUNTIF(H6:H85,"G3") | L48: =IFERROR(INDEX('15_직원별책무매핑'!$E:$E,MATCH(B48,'15_직원별책무매핑'!$B:$B,0)),0)
A49: G2 | B49: =COUNTIF(H6:H85,"G2") | L49: =IFERROR(INDEX('15_직원별책무매핑'!$E:$E,MATCH(B49,'15_직원별책무매핑'!$B:$B,0)),0)
A50: G1 | B50: =COUNTIF(H6:H85,"G1")

Sheet 02_의사결정·종합결과
A1: HR 의사결정 컨피그 (가중치·인상률·페이밴드)
A2: 이 시트에서 가중치·인상률·페이밴드를 정의. 모든 산출 시트가 자동 참조합니다.
A4: ■ ① 평가 방식·반기 가중치
A5: 평가 척도 | B5: 5점 | C5: 5점 또는 100점 (전 시트 일괄 적용)
A6: 평가 방식 | B6: 절대평가 | C6: 절대평가: 점수→등급 환산 / 상대평가: 분포 강제
A7: 상반기 가중치 | B7: 0.5 | C7: 평가차수별 가중치
A8: 하반기 가중치 | B8: =1-B7 | C8: 자동 계산
A10: 강제분포 비중 | B10: S | C10: A | D10: B | E10: C | F10: D
B11: 0.1 | C11: 0.15 | D11: 0.5 | E11: 0.15 | F11: 0.1
A14: ■ ② 직급별 3축 평가 가중치 (역할 + 공통역량 + 직무역량 = 100%) ★ G5-M/G5-S 분리
A15: 역할등급 | B15: 역할평가 W | C15: 공통역량 W | D15: 직무역량 W | E15: 합계 | F15: 검증 | G15: 설계 의도
A16: G6 | B16: 0.4 | C16: 0.25 | D16: 0.35 | E16: =B16+C16+D16 | F16: =IF(E16=1,"✓ OK","✗ ≠100%") | G16: 경영성과 책임·전사 의사결정 중심
A17: G5-M | B17: 0.35 | C17: 0.3 | D17: 0.35 | E17: =B17+C17+D17 | F17: =IF(E17=1,"✓ OK","✗ ≠100%") | G17: 조직 관리·부서장 성과 책임
A18: G5-S | B18: 0.3 | C18: 0.3 | D18: 0.4 | E18: =B18+C18+D18 | F18: =IF(E18=1,"✓ OK","✗ ≠100%") | G18: 실무 스페셜리스트·전문성 강조
A19: G4 | B19: 0.3 | C19: 0.3 | D19: 0.4 | E19: =B19+C19+D19 | F19: =IF(E19=1,"✓ OK","✗ ≠100%") | G19: 실무 책임자, 직무역량 강조
A20: G3 | B20: 0.25 | C20: 0.3 | D20: 0.45 | E20: =B20+C20+D20 | F20: =IF(E20=1,"✓ OK","✗ ≠100%") | G20: 핵심 실무자, 직무 깊이 가중
A21: G2 | B21: 0.2 | C21: 0.35 | D21: 0.45 | E21: =B21+C21+D21 | F21: =IF(E21=1,"✓ OK","✗ ≠100%") | G21: 실무자, 역량 개발 집중
A22: G1 | B22: 0.15 | C22: 0.35 | D22: 0.5 | E22: =B22+C22+D22 | F22: =IF(E22=1,"✓ OK","✗ ≠100%") | G22: 신입·실무 보조, 기본기 학습
A24: ■ ③ 평가 등급별 인상률·성과급률
A25: 구분 | B25: S | C25: A | D25: B | E25: C | F25: D | G25: 비고
A26: 기본연봉 인상률 | B26: 0.06 | C26: 0.05 | D26: 0.04 | E26: 0.03 | F26: 0.02 | G26: 09_보상연계에 자동 반영
A27: 성과급 지급률 | B27: 0.2 | C27: 0.15 | D27: 0.1 | E27: 0.05 | F27: 0 | G27: 10_성과급관리에 자동 반영
A28: 승진 가산률 | B28: 0.01 | C28: 승진(역할등급 상승) 시 기본연봉 인상률에 가산 | G28: Y/N 선택 시 자동 적용
A30: ■ ④ 페이밴드 (역할등급별 기본연봉 범위)
A31: 역할등급 | B31: 최소(Min) | C31: 중위(Mid) | D31: 최대(Max) | E31: Range Spread
A32: G6 | B32: 58000000 | C32: 69000000 | D32: 80000000 | E32: =(D32-B32)/B32
A33: G5-M | B33: 53000000 | C33: 63000000 | D33: 73000000 | E33: =(D33-B33)/B33
A34: G5-S | B34: 53000000 | C34: 63000000 | D34: 73000000 | E34: =(D34-B34)/B34
A35: G4 | B35: 49000000 | C35: 57500000 | D35: 66000000 | E35: =(D35-B35)/B35
A36: G3 | B36: 42000000 | C36: 49500000 | D36: 57000000 | E36: =(D36-B36)/B36
A37: G2 | B37: 36000000 | C37: 42500000 | D37: 49000000 | E37: =(D37-B37)/B37
A38: G1 | B38: 33000000 | C38: 38500000 | D38: 44000000 | E38: =(D38-B38)/B38
A40: ■ ⑤ 공통역량별 가중치 (11개 역량)
A41: No. | B41: 역량군 | C41: 핵심 역량 | D41: 가중치 | E41: 역량 설명
A42: C-1 | B42: 업무역량 | C42: 직무 전문성 | D42: 0.15 | E42: 직무에 필요한 전문 지식 및 기술을 충분히 보유하고 실무에 적절히 적용하는지 평가
A43: C-2 | B43: 업무역량 | C43: 분석력 | D43: 0.1 | E43: 데이터·수치를 기반으로 사고하며 업무 효율을 높이는 능력
A44: C-3 | B44: 업무역량 | C44: 기획/실행력 | D44: 0.1 | E44: 실행 가능한 목표 설정·계획 수립·체계적 실행 능력
A45: C-4 | B45: 조직역량 | C45: 자원·시간 관리 | D45: 0.1 | E45: 업무 우선순위 설정 및 시간 내 효과적 업무 완수 능력
A46: C-5 | B46: 조직역량 | C46: 협업 능력 | D46: 0.1 | E46: 팀원·타 부서와의 협업 태도와 적극적 협력
A47: C-6 | B47: 조직역량 | C47: 소통 능력 | D47: 0.1 | E47: 명확한 의견 전달·경청·효과적 커뮤니케이션
...

Sheet 03_전사업적평가
A1: 전사 업적 평가 (전사 KPI)
A2: 전사 KPI 달성도 → 성과급 가산 계수로 활용 (10_성과급관리에서 자동 참조)
A5: No. | B5: KPI | C5: 측정방법 | D5: 가중치 | E5: 목표 | F5: S 기준 | G5: A 기준 | H5: B 기준 | I5: C 기준 | J5: D 기준 | K5: 실적
A6: 1 | B6: 영업이익률 | C6: 영업이익 ÷ 매출액 × 100 | D6: 0.4 | E6: 0.12 | F6: 0.15 | G6: 0.12 | H6: 0.1 | I6: 0.08 | J6: 0.06
A7: 2 | B7: 매출 성장률 | C7: (금년-전년)/전년 × 100 | D7: 0.35 | E7: 0.07 | F7: 0.08 | G7: 0.07 | H7: 0.06 | I7: 0.05 | J7: 0.04
A8: 3 | B8: 프로젝트 납기·품질 준수율 | C8: 납기·품질 충족 ÷ 총 프로젝트 × 100 | D8: 0.25 | E8: 0.92 | F8: 0.93 | G8: 0.92 | H8: 0.91 | I8: 0.9 | J8: 0.89
A10: ■ 전사 KPI 종합
A11: 전사 종합 등급 | B11: =IFERROR(IF(COUNTBLANK(K6:K8)>0,"",IF(SUMPRODUCT(D6:D8,(K6:K8>=F6:F8)*1)>=0.8,"S",IF(SUMPRODUCT(D6:D8,(K6:K8>=G6:G8)*1)>=0.8,"A",IF(SUMPRODUCT(D6:D8,(K6:K8>=H6:H8)*1)>=0.8,"B",IF(SUMPRODUCT(D6:D8,(K6:K8>=I6:I8)*1)>=0.8,"C","D"))))),"-") | C11: 실적 입력 후 자동 산출. 10_성과급관리의 KPI 가산계수로 활용.

Sheet 04_역할평가
A1: 역할평가 — 역할등급별 5개 BARS 항목
A2: ★ [자동 산출 시트] - HR이 직접 입력하지 않습니다. 07a/07b 입력값을 참조해 자동 계산. 결과 검토용.
A4: ■ 등급 부여 기준 (BARS 행동기준)
A5: S (탁월) | B5: 역할정의를 현저히 초과 달성. 조직 전체에 긍정적 파급효과 창출
A6: A (우수) | B6: 역할정의를 충실히 수행하며 기대 수준을 상회. 자기주도적 성과
A7: B (양호) | B7: 역할정의에 부합하는 수준으로 안정적 수행. 기대 책임을 기한 내 완수
A8: C (미흡) | B8: 역할정의에 비해 일부 부족. 추가 지도·지원 필요
A9: D (부족) | B9: 역할 수행 수준이 현저히 미흡. 구체적 개선 계획 필요
A11: ■ 상반기 역할평가 (34명)
A12: No. | B12: 사번 | C12: 성명 | D12: 직무 | E12: 역할등급 | F12: 역할명 | G12: R-1 | H12: R-2 | I12: R-3 | J12: R-4 | K12: R-5 | L12: 5개 평균 | M12: 1차(종합) | N12: 2차(종합) | O12: 확정등급 | P12: 평가점수 | Q12: 강점·개선 소견
A13: ='01_인적정보'!A6 | B13: ='01_인적정보'!B6 | C13: ='01_인적정보'!C6 | D13: ='01_인적정보'!E6 | E13: ='01_인적정보'!H6 | F13: =IFERROR(VLOOKUP('01_인적정보'!M6,'13_직무역할DB'!$A$6:$D$70,4,FALSE),"") | G13: ='07a_상반기입력'!G6 | H13: ='07a_상반기입력'!H6 | I13: ='07a_상반기입력'!I6 | J13: ='07a_상반기입력'!J6 | K13: ='07a_상반기입력'!K6 | L13: =IFERROR((IF(G13="S",5,IF(G13="A",4,IF(G13="B",3,IF(G13="C",2,IF(G13="D",1,0)))))+IF(H13="S",5,IF(H13="A",4,IF(H13="B",3,IF(H13="C",2,IF(H13="D",1,0)))))+IF(I13="S",5,IF(I13="A",4,IF(I13="B",3,IF(I13="C",2,IF(I13="D",1,0)))))+IF(J13="S",5,IF(J13="A",4,IF(J13="B",3,IF(J13="C",2,IF(J13="D",1,0)))))+IF(K13="S",5,IF(K13="A",4,IF(K13="B",3,IF(K13="C",2,IF(K13="D",1,0))))))/5,"") | M13: ='07a_상반기입력'!L6 | N13: ='07a_상반기입력'!M6 | O13: =IF(N13<>"",N13,IF(M13<>"",M13,IF(L13="","",IF(L13>=4.5,"S",IF(L13>=3.5,"A",IF(L13>=2.5,"B",IF(L13>=1.5,"C","D"))))))) | P13: =IF(O13="","",IF(O13="S",5,IF(O13="A",4,IF(O13="B",3,IF(O13="C",2,IF(O13="D",1,0))))))
A14: ='01_인적정보'!A7 | B14: ='01_인적정보'!B7 | C14: ='01_인적정보'!C7 | D14: ='01_인적정보'!E7 | E14: ='01_인적정보'!H7 | F14: =IFERROR(VLOOKUP('01_인적정보'!M7,'13_직무역할DB'!$A$6:$D$70,4,FALSE),"") | G14: ='07a_상반기입력'!G7 | H14: ='07a_상반기입력'!H7 | I14: ='07a_상반기입력'!I7 | J14: ='07a_상반기입력'!J7 | K14: ='07a_상반기입력'!K7 | L14: =IFERROR((IF(G14="S",5,IF(G14="A",4,IF(G14="B",3,IF(G14="C",2,IF(G14="D",1,0)))))+IF(H14="S",5,IF(H14="A",4,IF(H14="B",3,IF(H14="C",2,IF(H14="D",1,0)))))+IF(I14="S",5,IF(I14="A",4,IF(I14="B",3,IF(I14="C",2,IF(I14="D",1,0)))))+IF(J14="S",5,IF(J14="A",4,IF(J14="B",3,IF(J14="C",2,IF(J14="D",1,0)))))+IF(K14="S",5,IF(K14="A",4,IF(K14="B",3,IF(K14="C",2,IF(K14="D",1,0))))))/5,"") | M14: ='07a_상반기입력'!L7 | N14: ='07a_상반기입력'!M7 | O14: =IF(N14<>"",N14,IF(M14<>"",M14,IF(L14="","",IF(L14>=4.5,"S",IF(L14>=3.5,"A",IF(L14>=2.5,"B",IF(L14>=1.5,"C","D"))))))) | P14: =IF(O14="","",IF(O14="S",5,IF(O14="A",4,IF(O14="B",3,IF(O14="C",2,IF(O14="D",1,0))))))
A15: ='01_인적정보'!A8 | B15: ='01_인적정보'!B8 | C15: ='01_인적정보'!C8 | D15: ='01_인적정보'!E8 | E15: ='01_인적정보'!H8 | F15: =IFERROR(VLOOKUP('01_인적정보'!M8,'13_직무역할DB'!$A$6:$D$70,4,FALSE),"") | G15: ='07a_상반기입력'!G8 | H15: ='07a_상반기입력'!H8 | I15: ='07a_상반기입력'!I8 | J15: ='07a_상반기입력'!J8 | K15: ='07a_상반기입력'!K8 | L15: =IFERROR((IF(G15="S",5,IF(G15="A",4,IF(G15="B",3,IF(G15="C",2,IF(G15="D",1,0)))))+IF(H15="S",5,IF(H15="A",4,IF(H15="B",3,IF(H15="C",2,IF(H15="D",1,0)))))+IF(I15="S",5,IF(I15="A",4,IF(I15="B",3,IF(I15="C",2,IF(I15="D",1,0)))))+IF(J15="S",5,IF(J15="A",4,IF(J15="B",3,IF(J15="C",2,IF(J15="D",1,0)))))+IF(K15="S",5,IF(K15="A",4,IF(K15="B",3,IF(K15="C",2,IF(K15="D",1,0))))))/5,"") | M15: ='07a_상반기입력'!L8 | N15: ='07a_상반기입력'!M8 | O15: =IF(N15<>"",N15,IF(M15<>"",M15,IF(L15="","",IF(L15>=4.5,"S",IF(L15>=3.5,"A",IF(L15>=2.5,"B",IF(L15>=1.5,"C","D"))))))) | P15: =IF(O15="","",IF(O15="S",5,IF(O15="A",4,IF(O15="B",3,IF(O15="C",2,IF(O15="D",1,0))))))
A16: ='01_인적정보'!A9 | B16: ='01_인적정보'!B9 | C16: ='01_인적정보'!C9 | D16: ='01_인적정보'!E9 | E16: ='01_인적정보'!H9 | F16: =IFERROR(VLOOKUP('01_인적정보'!M9,'13_직무역할DB'!$A$6:$D$70,4,FALSE),"") | G16: ='07a_상반기입력'!G9 | H16: ='07a_상반기입력'!H9 | I16: ='07a_상반기입력'!I9 | J16: ='07a_상반기입력'!J9 | K16: ='07a_상반기입력'!K9 | L16: =IFERROR((IF(G16="S",5,IF(G16="A",4,IF(G16="B",3,IF(G16="C",2,IF(G16="D",1,0)))))+IF(H16="S",5,IF(H16="A",4,IF(H16="B",3,IF(H16="C",2,IF(H16="D",1,0)))))+IF(I16="S",5,IF(I16="A",4,IF(I16="B",3,IF(I16="C",2,IF(I16="D",1,0)))))+IF(J16="S",5,IF(J16="A",4,IF(J16="B",3,IF(J16="C",2,IF(J16="D",1,0)))))+IF(K16="S",5,IF(K16="A",4,IF(K16="B",3,IF(K16="C",2,IF(K16="D",1,0))))))/5,"") | M16: ='07a_상반기입력'!L9 | N16: ='07a_상반기입력'!M9 | O16: =IF(N16<>"",N16,IF(M16<>"",M16,IF(L16="","",IF(L16>=4.5,"S",IF(L16>=3.5,"A",IF(L16>=2.5,"B",IF(L16>=1.5,"C","D"))))))) | P16: =IF(O16="","",IF(O16="S",5,IF(O16="A",4,IF(O16="B",3,IF(O16="C",2,IF(O16="D",1,0))))))
A17: ='01_인적정보'!A10 | B17: ='01_인적정보'!B10 | C17: ='01_인적정보'!C10 | D17: ='01_인적정보'!E10 | E17: ='01_인적정보'!H10 | F17: =IFERROR(VLOOKUP('01_인적정보'!M10,'13_직무역할DB'!$A$6:$D$70,4,FALSE),"") | G17: ='07a_상반기입력'!G10 | H17: ='07a_상반기입력'!H10 | I17: ='07a_상반기입력'!I10 | J17: ='07a_상반기입력'!J10 | K17: ='07a_상반기입력'!K10 | L17: =IFERROR((IF(G17="S",5,IF(G17="A",4,IF(G17="B",3,IF(G17="C",2,IF(G17="D",1,0)))))+IF(H17="S",5,IF(H17="A",4,IF(H17="B",3,IF(H17="C",2,IF(H17="D",1,0)))))+IF(I17="S",5,IF(I17="A",4,IF(I17="B",3,IF(I17="C",2,IF(I17="D",1,0)))))+IF(J17="S",5,IF(J17="A",4,IF(J17="B",3,IF(J17="C",2,IF(J17="D",1,0)))))+IF(K17="S",5,IF(K17="A",4,IF(K17="B",3,IF(K17="C",2,IF(K17="D",1,0))))))/5,"") | M17: ='07a_상반기입력'!L10 | N17: ='07a_상반기입력'!M10 | O17: =IF(N17<>"",N17,IF(M17<>"",M17,IF(L17="","",IF(L17>=4.5,"S",IF(L17>=3.5,"A",IF(L17>=2.5,"B",IF(L17>=1.5,"C","D"))))))) | P17: =IF(O17="","",IF(O17="S",5,IF(O17="A",4,IF(O17="B",3,IF(O17="C",2,IF(O17="D",1,0))))))
A18: ='01_인적정보'!A11 | B18: ='01_인적정보'!B11 | C18: ='01_인적정보'!C11 | D18: ='01_인적정보'!E11 | E18: ='01_인적정보'!H11 | F18: =IFERROR(VLOOKUP('01_인적정보'!M11,'13_직무역할DB'!$A$6:$D$70,4,FALSE),"") | G18: ='07a_상반기입력'!G11 | H18: ='07a_상반기입력'!H11 | I18: ='07a_상반기입력'!I11 | J18: ='07a_상반기입력'!J11 | K18: ='07a_상반기입력'!K11 | L18: =IFERROR((IF(G18="S",5,IF(G18="A",4,IF(G18="B",3,IF(G18="C",2,IF(G18="D",1,0)))))+IF(H18="S",5,IF(H18="A",4,IF(H18="B",3,IF(H18="C",2,IF(H18="D",1,0)))))+IF(I18="S",5,IF(I18="A",4,IF(I18="B",3,IF(I18="C",2,IF(I18="D",1,0)))))+IF(J18="S",5,IF(J18="A",4,IF(J18="B",3,IF(J18="C",2,IF(J18="D",1,0)))))+IF(K18="S",5,IF(K18="A",4,IF(K18="B",3,IF(K18="C",2,IF(K18="D",1,0))))))/5,"") | M18: ='07a_상반기입력'!L11 | N18: ='07a_상반기입력'!M11 | O18: =IF(N18<>"",N18,IF(M18<>"",M18,IF(L18="","",IF(L18>=4.5,"S",IF(L18>=3.5,"A",IF(L18>=2.5,"B",IF(L18>=1.5,"C","D"))))))) | P18: =IF(O18="","",IF(O18="S",5,IF(O18="A",4,IF(O18="B",3,IF(O18="C",2,IF(O18="D",1,0))))))
A19: ='01_인적정보'!A12 | B19: ='01_인적정보'!B12 | C19: ='01_인적정보'!C12 | D19: ='01_인적정보'!E12 | E19: ='01_인적정보'!H12 | F19: =IFERROR(VLOOKUP('01_인적정보'!M12,'13_직무역할DB'!$A$6:$D$70,4,FALSE),"") | G19: ='07a_상반기입력'!G12 | H19: ='07a_상반기입력'!H12 | I19: ='07a_상반기입력'!I12 | J19: ='07a_상반기입력'!J12 | K19: ='07a_상반기입력'!K12 | L19: =IFERROR((IF(G19="S",5,IF(G19="A",4,IF(G19="B",3,IF(G19="C",2,IF(G19="D",1,0)))))+IF(H19="S",5,IF(H19="A",4,IF(H19="B",3,IF(H19="C",2,IF(H19="D",1,0)))))+IF(I19="S",5,IF(I19="A",4,IF(I19="B",3,IF(I19="C",2,IF(I19="D",1,0)))))+IF(J19="S",5,IF(J19="A",4,IF(J19="B",3,IF(J19="C",2,IF(J19="D",1,0)))))+IF(K19="S",5,IF(K19="A",4,IF(K19="B",3,IF(K19="C",2,IF(K19="D",1,0))))))/5,"") | M19: ='07a_상반기입력'!L12 | N19: ='07a_상반기입력'!M12 | O19: =IF(N19<>"",N19,IF(M19<>"",M19,IF(L19="","",IF(L19>=4.5,"S",IF(L19>=3.5,"A",IF(L19>=2.5,"B",IF(L19>=1.5,"C","D"))))))) | P19: =IF(O19="","",IF(O19="S",5,IF(O19="A",4,IF(O19="B",3,IF(O19="C",2,IF(O19="D",1,0))))))
A20: ='01_인적정보'!A13 | B20: ='01_인적정보'!B13 | C20: ='01_인적정보'!C13 | D20: ='01_인적정보'!E13 | E20: ='01_인적정보'!H13 | F20: =IFERROR(VLOOKUP('01_인적정보'!M13,'13_직무역할DB'!$A$6:$D$70,4,FALSE),"") | G20: ='07a_상반기입력'!G13 | H20: ='07a_상반기입력'!H13 | I20: ='07a_상반기입력'!I13 | J20: ='07a_상반기입력'!J13 | K20: ='07a_상반기입력'!K13 | L20: =IFERROR((IF(G20="S",5,IF(G20="A",4,IF(G20="B",3,IF(G20="C",2,IF(G20="D",1,0)))))+IF(H20="S",5,IF(H20="A",4,IF(H20="B",3,IF(H20="C",2,IF(H20="D",1,0)))))+IF(I20="S",5,IF(I20="A",4,IF(I20="B",3,IF(I20="C",2,IF(I20="D",1,0)))))+IF(J20="S",5,IF(J20="A",4,IF(J20="B",3,IF(J20="C",2,IF(J20="D",1,0)))))+IF(K20="S",5,IF(K20="A",4,IF(K20="B",3,IF(K20="C",2,IF(K20="D",1,0))))))/5,"") | M20: ='07a_상반기입력'!L13 | N20: ='07a_상반기입력'!M13 | O20: =IF(N20<>"",N20,IF(M20<>"",M20,IF(L20="","",IF(L20>=4.5,"S",IF(L20>=3.5,"A",IF(L20>=2.5,"B",IF(L20>=1.5,"C","D"))))))) | P20: =IF(O20="","",IF(O20="S",5,IF(O20="A",4,IF(O20="B",3,IF(O20="C",2,IF(O20="D",1,0))))))
A21: ='01_인적정보'!A14 | B21: ='01_인적정보'!B14 | C21: ='01_인적정보'!C14 | D21: ='01_인적정보'!E14 | E21: ='01_인적정보'!H14 | F21: =IFERROR(VLOOKUP('01_인적정보'!M14,'13_직무역할DB'!$A$6:$D$70,4,FALSE),"") | G21: ='07a_상반기입력'!G14 | H21: ='07a_상반기입력'!H14 | I21: ='07a_상반기입력'!I14 | J21: ='07a_상반기입력'!J14 | K21: ='07a_상반기입력'!K14 | L21: =IFERROR((IF(G21="S",5,IF(G21="A",4,IF(G21="B",3,IF(G21="C",2,IF(G21="D",1,0)))))+IF(H21="S",5,IF(H21="A",4,IF(H21="B",3,IF(H21="C",2,IF(H21="D",1,0)))))+IF(I21="S",5,IF(I21="A",4,IF(I21="B",3,IF(I21="C",2,IF(I21="D",1,0)))))+IF(J21="S",5,IF(J21="A",4,IF(J21="B",3,IF(J21="C",2,IF(J21="D",1,0)))))+IF(K21="S",5,IF(K21="A",4,IF(K21="B",3,IF(K21="C",2,IF(K21="D",1,0))))))/5,"") | M21: ='07a_상반기입력'!L14 | N21: ='07a_상반기입력'!M14 | O21: =IF(N21<>"",N21,IF(M21<>"",M21,IF(L21="","",IF(L21>=4.5,"S",IF(L21>=3.5,"A",IF(L21>=2.5,"B",IF(L21>=1.5,"C","D"))))))) | P21: =IF(O21="","",IF(O21="S",5,IF(O21="A",4,IF(O21="B",3,IF(O21="C",2,IF(O21="D",1,0))))))
A22: ='01_인적정보'!A15 | B22: ='01_인적정보'!B15 | C22: ='01_인적정보'!C15 | D22: ='01_인적정보'!E15 | E22: ='01_인적정보'!H15 | F22: =IFERROR(VLOOKUP('01_인적정보'!M15,'13_직무역할DB'!$A$6:$D$70,4,FALSE),"") | G22: ='07a_상반기입력'!G15 | H22: ='07a_상반기입력'!H15 | I22: ='07a_상반기입력'!I15 | J22: ='07a_상반기입력'!J15 | K22: ='07a_상반기입력'!K15 | L22: =IFERROR((IF(G22="S",5,IF(G22="A",4,IF(G22="B",3,IF(G22="C",2,IF(G22="D",1,0)))))+IF(H22="S",5,IF(H22="A",4,IF(H22="B",3,IF(H22="C",2,IF(H22="D",1,0)))))+IF(I22="S",5,IF(I22="A",4,IF(I22="B",3,IF(I22="C",2,IF(I22="D",1,0)))))+IF(J22="S",5,IF(J22="A",4,IF(J22="B",3,IF(J22="C",2,IF(J22="D",1,0)))))+IF(K22="S",5,IF(K22="A",4,IF(K22="B",3,IF(K22="C",2,IF(K22="D",1,0))))))/5,"") | M22: ='07a_상반기입력'!L15 | N22: ='07a_상반기입력'!M15 | O22: =IF(N22<>"",N22,IF(M22<>"",M22,IF(L22="","",IF(L22>=4.5,"S",IF(L22>=3.5,"A",IF(L22>=2.5,"B",IF(L22>=1.5,"C","D"))))))) | P22: =IF(O22="","",IF(O22="S",5,IF(O22="A",4,IF(O22="B",3,IF(O22="C",2,IF(O22="D",1,0))))))
A23: ='01_인적정보'!A16 | B23: ='01_인적정보'!B16 | C23: ='01_인적정보'!C16 | D23: ='01_인적정보'!E16 | E23: ='01_인적정보'!H16 | F23: =IFERROR(VLOOKUP('01_인적정보'!M16,'13_직무역할DB'!$A$6:$D$70,4,FALSE),"") | G23: ='07a_상반기입력'!G16 | H23: ='07a_상반기입력'!H16 | I23: ='07a_상반기입력'!I16 | J23: ='07a_상반기입력'!J16 | K23: ='07a_상반기입력'!K16 | L23: =IFERROR((IF(G23="S",5,IF(G23="A",4,IF(G23="B",3,IF(G23="C",2,IF(G23="D",1,0)))))+IF(H23="S",5,IF(H23="A",4,IF(H23="B",3,IF(H23="C",2,IF(H23="D",1,0)))))+IF(I23="S",5,IF(I23="A",4,IF(I23="B",3,IF(I23="C",2,IF(I23="D",1,0)))))+IF(J23="S",5,IF(J23="A",4,IF(J23="B",3,IF(J23="C",2,IF(J23="D",1,0)))))+IF(K23="S",5,IF(K23="A",4,IF(K23="B",3,IF(K23="C",2,IF(K23="D",1,0))))))/5,"") | M23: ='07a_상반기입력'!L16 | N23: ='07a_상반기입력'!M16 | O23: =IF(N23<>"",N23,IF(M23<>"",M23,IF(L23="","",IF(L23>=4.5,"S",IF(L23>=3.5,"A",IF(L23>=2.5,"B",IF(L23>=1.5,"C","D"))))))) | P23: =IF(O23="","",IF(O23="S",5,IF(O23="A",4,IF(O23="B",3,IF(O23="C",2,IF(O23="D",1,0))))))
A24: ='01_인적정보'!A17 | B24: ='01_인적정보'!B17 | C24: ='01_인적정보'!C17 | D24: ='01_인적정보'!E17 | E24: ='01_인적정보'!H17 | F24: =IFERROR(VLOOKUP('01_인적정보'!M17,'13_직무역할DB'!$A$6:$D$70,4,FALSE),"") | G24: ='07a_상반기입력'!G17 | H24: ='07a_상반기입력'!H17 | I24: ='07a_상반기입력'!I17 | J24: ='07a_상반기입력'!J17 | K24: ='07a_상반기입력'!K17 | L24: =IFERROR((IF(G24="S",5,IF(G24="A",4,IF(G24="B",3,IF(G24="C",2,IF(G24="D",1,0)))))+IF(H24="S",5,IF(H24="A",4,IF(H24="B",3,IF(H24="C",2,IF(H24="D",1,0)))))+IF(I24="S",5,IF(I24="A",4,IF(I24="B",3,IF(I24="C",2,IF(I24="D",1,0)))))+IF(J24="S",5,IF(J24="A",4,IF(J24="B",3,IF(J24="C",2,IF(J24="D",1,0)))))+IF(K24="S",5,IF(K24="A",4,IF(K24="B",3,IF(K24="C",2,IF(K24="D",1,0))))))/5,"") | M24: ='07a_상반기입력'!L17 | N24: ='07a_상반기입력'!M17 | O24: =IF(N24<>"",N24,IF(M24<>"",M24,IF(L24="","",IF(L24>=4.5,"S",IF(L24>=3.5,"A",IF(L24>=2.5,"B",IF(L24>=1.5,"C","D"))))))) | P24: =IF(O24="","",IF(O24="S",5,IF(O24="A",4,IF(O24="B",3,IF(O24="C",2,IF(O24="D",1,0))))))
... A46: ='01_인적정보'!A39 | B46: ='01_인적정보'!B39 | C46: ='01_인적정보'!C39 | D46: ='01_인적정보'!E39 | E46: ='01_인적정보'!H39 | F46: =IFERROR(VLOOKUP('01_인적정보'!M39,'13_직무역할DB'!$A$6:$D$70,4,FALSE),"") | G46: ='07a_상반기입력'!G39 | H46: ='07a_상반기입력'!H39 | I46: ='07a_상반기입력'!I39 | J46: ='07a_상반기입력'!J39 | K46: ='07a_상반기입력'!K39 | L46: =IFERROR((IF(G46="S",5,IF(G46="A",4,IF(G46="B",3,IF(G46="C",2,IF(G46="D",1,0)))))+IF(H46="S",5,IF(H46="A",4,IF(H46="B",3,IF(H46="C",2,IF(H46="D",1,0)))))+IF(I46="S",5,IF(I46="A",4,IF(I46="B",3,IF(I46="C",2,IF(I46="D",1,0)))))+IF(J46="S",5,IF(J46="A",4,IF(J46="B",3,IF(J46="C",2,IF(J46="D",1,0)))))+IF(K46="S",5,IF(K46="A",4,IF(K46="B",3,IF(K46="C",2,IF(K46="D",1,0))))))/5,"") | M46: ='07a_상반기입력'!L39 | N46: ='07a_상반기입력'!M39 | O46: =IF(N46<>"",N46,IF(M46<>"",M46,IF(L46="","",IF(L46>=4.5,"S",IF(L46>=3.5,"A",IF(L46>=2.5,"B",IF(L46>=1.5,"C","D"))))))) | P46: =IF(O46="","",IF(O46="S",5,IF(O46="A",4,IF(O46="B",3,IF(O46="C",2,IF(O46="D",1,0))))))
A56: ■ 하반기 역할평가 (34명)
A57: No. | B57: 사번 | C57: 성명 | D57: 직무 | E57: 역할등급 | F57: 역할명 | G57: R-1 | H57: R-2 | I57: R-3 | J57: R-4 | K57: R-5 | L57: 5개 평균 | M57: 1차(종합) | N57: 2차(종합) | O57: 확정등급 | P57: 평가점수 | Q57: 강점·개선 소견
A58: ='01_인적정보'!A6 | B58: ='01_인적정보'!B6 | C58: ='01_인적정보'!C6 | D58: ='01_인적정보'!E6 | E58: ='01_인적정보'!H6 | F58: =IFERROR(VLOOKUP('01_인적정보'!M6,'13_직무역할DB'!$A$6:$D$70,4,FALSE),"") | G58: ='07b_하반기입력'!G6 | H58: ='07b_하반기입력'!H6 | I58: ='07b_하반기입력'!I6 | J58: ='07b_하반기입력'!J6 | K58: ='07b_하반기입력'!K6 | L58: =IFERROR((IF(G58="S",5,IF(G58="A",4,IF(G58="B",3,IF(G58="C",2,IF(G58="D",1,0)))))+IF(H58="S",5,IF(H58="A",4,IF(H58="B",3,IF(H58="C",2,IF(H58="D",1,0)))))+IF(I58="S",5,IF(I58="A",4,IF(I58="B",3,IF(I58="C",2,IF(I58="D",1,0)))))+IF(J58="S",5,IF(J58="A",4,IF(J58="B",3,IF(J58="C",2,IF(J58="D",1,0)))))+IF(K58="S",5,IF(K58="A",4,IF(K58="B",3,IF(K58="C",2,IF(K58="D",1,0))))))/5,"") | M58: ='07b_하반기입력'!L6 | N58: ='07b_하반기입력'!M6 | O58: =IF(N58<>"",N58,IF(M58<>"",M58,IF(L58="","",IF(L58>=4.5,"S",IF(L58>=3.5,"A",IF(L58>=2.5,"B",IF(L58>=1.5,"C","D"))))))) | P58: =IF(O58="","",IF(O58="S",5,IF(O58="A",4,IF(O58="B",3,IF(O58="C",2,IF(O58="D",1,0))))))
A59: ='01_인적정보'!A7 | B59: ='01_인적정보'!B7 | C59: ='01_인적정보'!C7 | D59: ='01_인적정보'!E7 | E59: ='01_인적정보'!H7 | F59: =IFERROR(VLOOKUP('01_인적정보'!M7,'13_직무역할DB'!$A$6:$D$70,4,FALSE),"") | G59: ='07b_하반기입력'!G7 | H59: ='07b_하반기입력'!H7 | I59: ='07b_하반기입력'!I7 | J59: ='07b_하반기입력'!J7 | K59: ='07b_하반기입력'!K7 | L59: =IFERROR((IF(G59="S",5,IF(G59="A",4,IF(G59="B",3,IF(G59="C",2,IF(G59="D",1,0)))))+IF(H59="S",5,IF(H59="A",4,IF(H59="B",3,IF(H59="C",2,IF(H59="D",1,0)))))+IF(I59="S",5,IF(I59="A",4,IF(I59="B",3,IF(I59="C",2,IF(I59="D",1,0)))))+IF(J59="S",5,IF(J59="A",4,IF(J59="B",3,IF(J59="C",2,IF(J59="D",1,0)))))+IF(K59="S",5,IF(K59="A",4,IF(K59="B",3,IF(K59="C",2,IF(K59="D",1,0))))))/5,"") | M59: ='07b_하반기입력'!L7 | N59: ='07b_하반기입력'!M7 | O59: =IF(N59<>"",N59,IF(M59<>"",M59,IF(L59="","",IF(L59>=4.5,"S",IF(L59>=3.5,"A",IF(L59>=2.5,"B",IF(L59>=1.5,"C","D"))))))) | P59: =IF(O59="","",IF(O59="S",5,IF(O59="A",4,IF(O59="B",3,IF(O59="C",2,IF(O59="D",1,0))))))
A60: ='01_인적정보'!A8 | B60: ='01_인적정보'!B8 | C60: ='01_인적정보'!C8 | D60: ='01_인적정보'!E8 | E60: ='01_인적정보'!H8 | F60: =IFERROR(VLOOKUP('01_인적정보'!M8,'13_직무역할DB'!$A$6:$D$70,4,FALSE),"") | G60: ='07b_하반기입력'!G8 | H60: ='07b_하반기입력'!H8 | I60: ='07b_하반기입력'!I8 | J60: ='07b_하반기입력'!J8 | K60: ='07b_하반기입력'!K8 | L60: =IFERROR((IF(G60="S",5,IF(G60="A",4,IF(G60="B",3,IF(G60="C",2,IF(G60="D",1,0)))))+IF(H60="S",5,IF(H60="A",4,IF(H60="B",3,IF(H60="C",2,IF(H60="D",1,0)))))+IF(I60="S",5,IF(I60="A",4,IF(I60="B",3,IF(I60="C",2,IF(I60="D",1,0)))))+IF(J60="S",5,IF(J60="A",4,IF(J60="B",3,IF(J60="C",2,IF(J60="D",1,0)))))+IF(K60="S",5,IF(K60="A",4,IF(K60="B",3,IF(K60="C",2,IF(K60="D",1,0))))))/5,"") | M60: ='07b_하반기입력'!L8 | N60: ='07b_하반기입력'!M8 | O60: =IF(N60<>"",N60,IF(M60<>"",M60,IF(L60="","",IF(L60>=4.5,"S",IF(L60>=3.5,"A",IF(L60>=2.5,"B",IF(L60>=1.5,"C","D"))))))) | P60: =IF(O60="","",IF(O60="S",5,IF(O60="A",4,IF(O60="B",3,IF(O60="C",2,IF(O60="D",1,0))))))
A61: ='01_인적정보'!A9 | B61: ='01_인적정보'!B9 | C61: ='01_인적정보'!C9 | D61: ='01_인적정보'!E9 | E61: ='01_인적정보'!H9 | F61: =IFERROR(VLOOKUP('01_인적정보'!M9,'13_직무역할DB'!$A$6:$D$70,4,FALSE),"") | G61: ='07b_하반기입력'!G9 | H61: ='07b_하반기입력'!H9 | I61: ='07b_하반기입력'!I9 | J61: ='07b_하반기입력'!J9 | K61: ='07b_하반기입력'!K9 | L61: =IFERROR((IF(G61="S",5,IF(G61="A",4,IF(G61="B",3,IF(G61="C",2,IF(G61="D",1,0)))))+IF(H61="S",5,IF(H61="A",4,IF(H61="B",3,IF(H61="C",2,IF(H61="D",1,0)))))+IF(I61="S",5,IF(I61="A",4,IF(I61="B",3,IF(I61="C",2,IF(I61="D",1,0)))))+IF(J61="S",5,IF(J61="A",4,IF(J61="B",3,IF(J61="C",2,IF(J61="D",1,0)))))+IF(K61="S",5,IF(K61="A",4,IF(K61="B",3,IF(K61="C",2,IF(K61="D",1,0))))))/5,"") | M61: ='07b_하반기입력'!L9 | N61: ='07b_하반기입력'!M9 | O61: =IF(N61<>"",N61,IF(M61<>"",M61,IF(L61="","",IF(L61>=4.5,"S",IF(L61>=3.5,"A",IF(L61>=2.5,"B",IF(L61>=1.5,"C","D"))))))) | P61: =IF(O61="","",IF(O61="S",5,IF(O61="A",4,IF(O61="B",3,IF(O61="C",2,IF(O61="D",1,0))))))
A62: ='01_인적정보'!A10 | B62: ='01_인적정보'!B10 | C62: ='01_인적정보'!C10 | D62: ='01_인적정보'!E10 | E62: ='01_인적정보'!H10 | F62: =IFERROR(VLOOKUP('01_인적정보'!M10,'13_직무역할DB'!$A$6:$D$70,4,FALSE),"") | G62: ='07b_하반기입력'!G10 | H62: ='07b_하반기입력'!H10 | I62: ='07b_하반기입력'!I10 | J62: ='07b_하반기입력'!J10 | K62: ='07b_하반기입력'!K10 | L62: =IFERROR((IF(G62="S",5,IF(G62="A",4,IF(G62="B",3,IF(G62="C",2,IF(G62="D",1,0)))))+IF(H62="S",5,IF(H62="A",4,IF(H62="B",3,IF(H62="C",2,IF(H62="D",1,0)))))+IF(I62="S",5,IF(I62="A",4,IF(I62="B",3,IF(I62="C",2,IF(I62="D",1,0)))))+IF(J62="S",5,IF(J62="A",4,IF(J62="B",3,IF(J62="C",2,IF(J62="D",1,0)))))+IF(K62="S",5,IF(K62="A",4,IF(K62="B",3,IF(K62="C",2,IF(K62="D",1,0))))))/5,"") | M62: ='07b_하반기입력'!L10 | N62: ='07b_하반기입력'!M10 | O62: =IF(N62<>"",N62,IF(M62<>"",M62,IF(L62="","",IF(L62>=4.5,"S",IF(L62>=3.5,"A",IF(L62>=2.5,"B",IF(L62>=1.5,"C","D"))))))) | P62: =IF(O62="","",IF(O62="S",5,IF(O62="A",4,IF(O62="B",3,IF(O62="C",2,IF(O62="D",1,0))))))
A63: ='01_인적정보'!A11 | B63: ='01_인적정보'!B11 | C63: ='01_인적정보'!C11 | D63: ='01_인적정보'!E11 | E63: ='01_인적정보'!H11 | F63: =IFERROR(VLOOKUP('01_인적정보'!M11,'13_직무역할DB'!$A$6:$D$70,4,FALSE),"") | G63: ='07b_하반기입력'!G11 | H63: ='07b_하반기입력'!H11 | I63: ='07b_하반기입력'!I11 | J63: ='07b_하반기입력'!J11 | K63: ='07b_하반기입력'!K11 | L63: =IFERROR((IF(G63="S",5,IF(G63="A",4,IF(G63="B",3,IF(G63="C",2,IF(G63="D",1,0)))))+IF(H63="S",5,IF(H63="A",4,IF(H63="B",3,IF(H63="C",2,IF(H63="D",1,0)))))+IF(I63="S",5,IF(I63="A",4,IF(I63="B",3,IF(I63="C",2,IF(I63="D",1,0)))))+IF(J63="S",5,IF(J63="A",4,IF(J63="B",3,IF(J63="C",2,IF(J63="D",1,0)))))+IF(K63="S",5,IF(K63="A",4,IF(K63="B",3,IF(K63="C",2,IF(K63="D",1,0))))))/5,"") | M63: ='07b_하반기입력'!L11 | N63: ='07b_하반기입력'!M11 | O63: =IF(N63<>"",N63,IF(M63<>"",M63,IF(L63="","",IF(L63>=4.5,"S",IF(L63>=3.5,"A",IF(L63>=2.5,"B",IF(L63>=1.5,"C","D"))))))) | P63: =IF(O63="","",IF(O63="S",5,IF(O63="A",4,IF(O63="B",3,IF(O63="C",2,IF(O63="D",1,0))))))
A64: ='01_인적정보'!A12 | B64: ='01_인적정보'!B12 | C64: ='01_인적정보'!C12 | D64: ='01_인적정보'!E12 | E64: ='01_인적정보'!H12 | F64: =IFERROR(VLOOKUP('01_인적정보'!M12,'13_직무역할DB'!$A$6:$D$70,4,FALSE),"") | G64: ='07b_하반기입력'!G12 | H64: ='07b_하반기입력'!H12 | I64: ='07b_하반기입력'!I12 | J64: ='07b_하반기입력'!J12 | K64: ='07b_하반기입력'!K12 | L64: =IFERROR((IF(G64="S",5,IF(G64="A",4,IF(G64="B",3,IF(G64="C",2,IF(G64="D",1,0)))))+IF(H64="S",5,IF(H64="A",4,IF(H64="B",3,IF(H64="C",2,IF(H64="D",1,0)))))+IF(I64="S",5,IF(I64="A",4,IF(I64="B",3,IF(I64="C",2,IF(I64="D",1,0)))))+IF(J64="S",5,IF(J64="A",4,IF(J64="B",3,IF(J64="C",2,IF(J64="D",1,0)))))+IF(K64="S",5,IF(K64="A",4,IF(K64="B",3,IF(K64="C",2,IF(K64="D",1,0))))))/5,"") | M64: ='07b_하반기입력'!L12 | N64: ='07b_하반기입력'!M12 | O64: =IF(N64<>"",N64,IF(M64<>"",M64,IF(L64="","",IF(L64>=4.5,"S",IF(L64>=3.5,"A",IF(L64>=2.5,"B",IF(L64>=1.5,"C","D"))))))) | P64: =IF(O64="","",IF(O64="S",5,IF(O64="A",4,IF(O64="B",3,IF(O64="C",2,IF(O64="D",1,0))))))
A65: ='01_인적정보'!A13 | B65: ='01_인적정보'!B13 | C65: ='01_인적정보'!C13 | D65: ='01_인적정보'!E13 | E65: ='01_인적정보'!H13 | F65: =IFERROR(VLOOKUP('01_인적정보'!M13,'13_직무역할DB'!$A$6:$D$70,4,FALSE),"") | G65: ='07b_하반기입력'!G13 | H65: ='07b_하반기입력'!H13 | I65: ='07b_하반기입력'!I13 | J65: ='07b_하반기입력'!J13 | K65: ='07b_하반기입력'!K13 | L65: =IFERROR((IF(G65="S",5,IF(G65="A",4,IF(G65="B",3,IF(G65="C",2,IF(G65="D",1,0)))))+IF(H65="S",5,IF(H65="A",4,IF(H65="B",3,IF(H65="C",2,IF(H65="D",1,0)))))+IF(I65="S",5,IF(I65="A",4,IF(I65="B",3,IF(I65="C",2,IF(I65="D",1,0)))))+IF(J65="S",5,IF(J65="A",4,IF(J65="B",3,IF(J65="C",2,IF(J65="D",1,0)))))+IF(K65="S",5,IF(K65="A",4,IF(K65="B",3,IF(K65="C",2,IF(K65="D",1,0))))))/5,"") | M65: ='07b_하반기입력'!L13 | N65: ='07b_하반기입력'!M13 | O65: =IF(N65<>"",N65,IF(M65<>"",M65,IF(L65="","",IF(L65>=4.5,"S",IF(L65>=3.5,"A",IF(L65>=2.5,"B",IF(L65>=1.5,"C","D"))))))) | P65: =IF(O65="","",IF(O65="S",5,IF(O65="A",4,IF(O65="B",3,IF(O65="C",2,IF(O65="D",1,0))))))
A66: ='01_인적정보'!A14 | B66: ='01_인적정보'!B14 | C66: ='01_인적정보'!C14 | D66: ='01_인적정보'!E14 | E66: ='01_인적정보'!H14 | F66: =IFERROR(VLOOKUP('01_인적정보'!M14,'13_직무역할DB'!$A$6:$D$70,4,FALSE),"") | G66: ='07b_하반기입력'!G14 | H66: ='07b_하반기입력'!H14 | I66: ='07b_하반기입력'!I14 | J66: ='07b_하반기입력'!J14 | K66: ='07b_하반기입력'!K14 | L66: =IFERROR((IF(G66="S",5,IF(G66="A",4,IF(G66="B",3,IF(G66="C",2,IF(G66="D",1,0)))))+IF(H66="S",5,IF(H66="A",4,IF(H66="B",3,IF(H66="C",2,IF(H66="D",1,0)))))+IF(I66="S",5,IF(I66="A",4,IF(I66="B",3,IF(I66="C",2,IF(I66="D",1,0)))))+IF(J66="S",5,IF(J66="A",4,IF(J66="B",3,IF(J66="C",2,IF(J66="D",1,0)))))+IF(K66="S",5,IF(K66="A",4,IF(K66="B",3,IF(K66="C",2,IF(K66="D",1,0))))))/5,"") | M66: ='07b_하반기입력'!L14 | N66: ='07b_하반기입력'!M14 | O66: =IF(N66<>"",N66,IF(M66<>"",M66,IF(L66="","",IF(L66>=4.5,"S",IF(L66>=3.5,"A",IF(L66>=2.5,"B",IF(L66>=1.5,"C","D"))))))) | P66: =IF(O66="","",IF(O66="S",5,IF(O66="A",4,IF(O66="B",3,IF(O66="C",2,IF(O66="D",1,0))))))
A67: ='01_인적정보'!A15 | B67: ='01_인적정보'!B15 | C67: ='01_인적정보'!C15 | D67: ='01_인적정보'!E15 | E67: ='01_인적정보'!H15 | F67: =IFERROR(VLOOKUP('01_인적정보'!M15,'13_직무역할DB'!$A$6:$D$70,4,FALSE),"") | G67: ='07b_하반기입력'!G15 | H67: ='07b_하반기입력'!H15 | I67: ='07b_하반기입력'!I15 | J67: ='07b_하반기입력'!J15 | K67: ='07b_하반기입력'!K15 | L67: =IFERROR((IF(G67="S",5,IF(G67="A",4,IF(G67="B",3,IF(G67="C",2,IF(G67="D",1,0)))))+IF(H67="S",5,IF(H67="A",4,IF(H67="B",3,IF(H67="C",2,IF(H67="D",1,0)))))+IF(I67="S",5,IF(I67="A",4,IF(I67="B",3,IF(I67="C",2,IF(I67="D",1,0)))))+IF(J67="S",5,IF(J67="A",4,IF(J67="B",3,IF(J67="C",2,IF(J67="D",1,0)))))+IF(K67="S",5,IF(K67="A",4,IF(K67="B",3,IF(K67="C",2,IF(K67="D",1,0))))))/5,"") | M67: ='07b_하반기입력'!L15 | N67: ='07b_하반기입력'!M15 | O67: =IF(N67<>"",N67,IF(M67<>"",M67,IF(L67="","",IF(L67>=4.5,"S",IF(L67>=3.5,"A",IF(L67>=2.5,"B",IF(L67>=1.5,"C","D"))))))) | P67: =IF(O67="","",IF(O67="S",5,IF(O67="A",4,IF(O67="B",3,IF(O67="C",2,IF(O67="D",1,0))))))
A68: ='01_인적정보'!A16 | B68: ='01_인적정보'!B16 | C68: ='01_인적정보'!C16 | D68: ='01_인적정보'!E16 | E68: ='01_인적정보'!H16 | F68: =IFERROR(VLOOKUP('01_인적정보'!M16,'13_직무역할DB'!$A$6:$D$70,4,FALSE),"") | G68: ='07b_하반기입력'!G16 | H68: ='07b_하반기입력'!H16 | I68: ='07b_하반기입력'!I16 | J68: ='07b_하반기입력'!J16 | K68: ='07b_하반기입력'!K16 | L68: =IFERROR((IF(G68="S",5,IF(G68="A",4,IF(G68="B",3,IF(G68="C",2,IF(G68="D",1,0)))))+IF(H68="S",5,IF(H68="A",4,IF(H68="B",3,IF(H68="C",2,IF(H68="D",1,0)))))+IF(I68="S",5,IF(I68="A",4,IF(I68="B",3,IF(I68="C",2,IF(I68="D",1,0)))))+IF(J68="S",5,IF(J68="A",4,IF(J68="B",3,IF(J68="C",2,IF(J68="D",1,0)))))+IF(K68="S",5,IF(K68="A",4,IF(K68="B",3,IF(K68="C",2,IF(K68="D",1,0))))))/5,"") | M68: ='07b_하반기입력'!L16 | N68: ='07b_하반기입력'!M16 | O68: =IF(N68<>"",N68,IF(M68<>"",M68,IF(L68="","",IF(L68>=4.5,"S",IF(L68>=3.5,"A",IF(L68>=2.5,"B",IF(L68>=1.5,"C","D"))))))) | P68: =IF(O68="","",IF(O68="S",5,IF(O68="A",4,IF(O68="B",3,IF(O68="C",2,IF(O68="D",1,0))))))
A69: ='01_인적정보'!A17 | B69: ='01_인적정보'!B17 | C69: ='01_인적정보'!C17 | D69: ='01_인적정보'!E17 | E69: ='01_인적정보'!H17 | F69: =IFERROR(VLOOKUP('01_인적정보'!M17,'13_직무역할DB'!$A$6:$D$70,4,FALSE),"") | G69: ='07b_하반기입력'!G17 | H69: ='07b_하반기입력'!H17 | I69: ='07b_하반기입력'!I17 | J69: ='07b_하반기입력'!J17 | K69: ='07b_하반기입력'!K17 | L69: =IFERROR((IF(G69="S",5,IF(G69="A",4,IF(G69="B",3,IF(G69="C",2,IF(G69="D",1,0)))))+IF(H69="S",5,IF(H69="A",4,IF(H69="B",3,IF(H69="C",2,IF(H69="D",1,0)))))+IF(I69="S",5,IF(I69="A",4,IF(I69="B",3,IF(I69="C",2,IF(I69="D",1,0)))))+IF(J69="S",5,IF(J69="A",4,IF(J69="B",3,IF(J69="C",2,IF(J69="D",1,0)))))+IF(K69="S",5,IF(K69="A",4,IF(K69="B",3,IF(K69="C",2,IF(K69="D",1,0))))))/5,"") | M69: ='07b_하반기입력'!L17 | N69: ='07b_하반기입력'!M17 | O69: =IF(N69<>"",N69,IF(M69<>"",M69,IF(L69="","",IF(L69>=4.5,"S",IF(L69>=3.5,"A",IF(L69>=2.5,"B",IF(L69>=1.5,"C","D"))))))) | P69: =IF(O69="","",IF(O69="S",5,IF(O69="A",4,IF(O69="B",3,IF(O69="C",2,IF(O69="D",1,0))))))
... A91: ='01_인적정보'!A39 | B91: ='01_인적정보'!B39 | C91: ='01_인적정보'!C39 | D91: ='01_인적정보'!E39 | E91: ='01_인적정보'!H39 | F91: =IFERROR(VLOOKUP('01_인적정보'!M39,'13_직무역할DB'!$A$6:$D$70,4,FALSE),"") | G91: ='07b_하반기입력'!G39 | H91: ='07b_하반기입력'!H39 | I91: ='07b_하반기입력'!I39 | J91: ='07b_하반기입력'!J39 | K91: ='07b_하반기입력'!K39 | L91: =IFERROR((IF(G91="S",5,IF(G91="A",4,IF(G91="B",3,IF(G91="C",2,IF(G91="D",1,0)))))+IF(H91="S",5,IF(H91="A",4,IF(H91="B",3,IF(H91="C",2,IF(H91="D",1,0)))))+IF(I91="S",5,IF(I91="A",4,IF(I91="B",3,IF(I91="C",2,IF(I91="D",1,0)))))+IF(J91="S",5,IF(J91="A",4,IF(J91="B",3,IF(J91="C",2,IF(J91="D",1,0)))))+IF(K91="S",5,IF(K91="A",4,IF(K91="B",3,IF(K91="C",2,IF(K91="D",1,0))))))/5,"") | M91: ='07b_하반기입력'!L39 | N91: ='07b_하반기입력'!M39 | O91: =IF(N91<>"",N91,IF(M91<>"",M91,IF(L91="","",IF(L91>=4.5,"S",IF(L91>=3.5,"A",IF(L91>=2.5,"B",IF(L91>=1.5,"C","D"))))))) | P91: =IF(O91="","",IF(O91="S",5,IF(O91="A",4,IF(O91="B",3,IF(O91="C",2,IF(O91="D",1,0))))))

Sheet 05_공통역량평가
A1: 공통역량평가 — 전사 공통 11개 역량 (1·2차 평가자 평균)
A2: ★ [자동 산출 시트] - 07a/07b의 11개 역량 등급을 가중합산. 결과 검토용.
A4: ■ 상반기 공통역량평가
A5: No. | B5: 사번 | C5: 성명 | D5: 역할등급 | E5: C-1 직무 전문성 | F5: C-2 분석력 | G5: C-3 기획/실행력 | H5: C-4 자원·시간 관리 | I5: C-5 협업 능력 | J5: C-6 소통 능력 | K5: C-7 윤리/책임감 | L5: C-8 업무 태도 | M5: C-9 혁신 역량 | N5: C-10 프로세스 개선 | O5: C-11 지속가능 기여 | P5: 가중합산 | Q5: 등급 | R5: 소견
A6: ='01_인적정보'!A6 | B6: ='01_인적정보'!B6 | C6: ='01_인적정보'!C6 | D6: ='01_인적정보'!H6 | E6: ='07a_상반기입력'!N6 | F6: ='07a_상반기입력'!O6 | G6: ='07a_상반기입력'!P6 | H6: ='07a_상반기입력'!Q6 | I6: ='07a_상반기입력'!R6 | J6: ='07a_상반기입력'!S6 | K6: ='07a_상반기입력'!T6 | L6: ='07a_상반기입력'!U6 | ... O6: ='07a_상반기입력'!X6 | P6: =IFERROR(IF(COUNTBLANK(E6:O6)>0,"",0.15*IF(E6="S",5,IF(E6="A",4,IF(E6="B",3,IF(E6="C",2,IF(E6="D",1,0)))))+0.1*IF(F6="S",5,IF(F6="A",4,IF(F6="B",3,IF(F6="C",2,IF(F6="D",1,0)))))+0.1*IF(G6="S",5,IF(G6="A",4,IF(G6="B",3,IF(G6="C",2,IF(G6="D",1,0)))))+0.1*IF(H6="S",5,IF(H6="A",4,IF(H6="B",3,IF(H6="C",2,IF(H6="D",1,0)))))+0.1*IF(I6="S",5,IF(I6="A",4,IF(I6="B",3,IF(I6="C",2,IF(I6="D",1,0)))))+0.1*IF(J6="S",5,IF(J6="A",4,IF(J6="B",3,IF(J6="C",2,IF(J6="D",1,0)))))+0.1*IF(K6="S",5,IF(K6="A",4,IF(K6="B",3,IF(K6="C",2,IF(K6="D",1,0)))))+0.1*IF(L6="S",5,IF(L6="A",4,IF(L6="B",3,IF(L6="C",2,IF(L6="D",1,0)))))+0.05*IF(M6="S",5,IF(M6="A",4,IF(M6="B",3,IF(M6="C",2,IF(M6="D",1,0)))))+0.05*IF(N6="S",5,IF(N6="A",4,IF(N6="B",3,IF(N6="C",2,IF(N6="D",1,0)))))+0.05*IF(O6="S",5,IF(O6="A",4,IF(O6="B",3,IF(O6="C",2,IF(O6="D",1,0)))))),"") | Q6: =IF(P6="","",IF(P6>=4.5,"S",IF(P6>=3.5,"A",IF(P6>=2.5,"B",IF(P6>=1.5,"C","D")))))
A7: ='01_인적정보'!A7 | B7: ='01_인적정보'!B7 | C7: ='01_인적정보'!C7 | D7: ='01_인적정보'!H7 | E7: ='07a_상반기입력'!N7 | F7: ='07a_상반기입력'!O7 | G7: ='07a_상반기입력'!P7 | H7: ='07a_상반기입력'!Q7 | I7: ='07a_상반기입력'!R7 | J7: ='07a_상반기입력'!S7 | K7: ='07a_상반기입력'!T7 | L7: ='07a_상반기입력'!U7 | ... O7: ='07a_상반기입력'!X7 | P7: =IFERROR(IF(COUNTBLANK(E7:O7)>0,"",0.15*IF(E7="S",5,IF(E7="A",4,IF(E7="B",3,IF(E7="C",2,IF(E7="D",1,0)))))+0.1*IF(F7="S",5,IF(F7="A",4,IF(F7="B",3,IF(F7="C",2,IF(F7="D",1,0)))))+0.1*IF(G7="S",5,IF(G7="A",4,IF(G7="B",3,IF(G7="C",2,IF(G7="D",1,0)))))+0.1*IF(H7="S",5,IF(H7="A",4,IF(H7="B",3,IF(H7="C",2,IF(H7="D",1,0)))))+0.1*IF(I7="S",5,IF(I7="A",4,IF(I7="B",3,IF(I7="C",2,IF(I7="D",1,0)))))+0.1*IF(J7="S",5,IF(J7="A",4,IF(J7="B",3,IF(J7="C",2,IF(J7="D",1,0)))))+0.1*IF(K7="S",5,IF(K7="A",4,IF(K7="B",3,IF(K7="C",2,IF(K7="D",1,0)))))+0.1*IF(L7="S",5,IF(L7="A",4,IF(L7="B",3,IF(L7="C",2,IF(L7="D",1,0)))))+0.05*IF(M7="S",5,IF(M7="A",4,IF(M7="B",3,IF(M7="C",2,IF(M7="D",1,0)))))+0.05*IF(N7="S",5,IF(N7="A",4,IF(N7="B",3,IF(N7="C",2,IF(N7="D",1,0)))))+0.05*IF(O7="S",5,IF(O7="A",4,IF(O7="B",3,IF(O7="C",2,IF(O7="D",1,0)))))),"") | Q7: =IF(P7="","",IF(P7>=4.5,"S",IF(P7>=3.5,"A",IF(P7>=2.5,"B",IF(P7>=1.5,"C","D")))))
A8: ='01_인적정보'!A8 | B8: ='01_인적정보'!B8 | C8: ='01_인적정보'!C8 | D8: ='01_인적정보'!H8 | E8: ='07a_상반기입력'!N8 | F8: ='07a_상반기입력'!O8 | G8: ='07a_상반기입력'!P8 | H8: ='07a_상반기입력'!Q8 | I8: ='07a_상반기입력'!R8 | J8: ='07a_상반기입력'!S8 | K8: ='07a_상반기입력'!T8 | L8: ='07a_상반기입력'!U8 | ... O8: ='07a_상반기입력'!X8 | P8: =IFERROR(IF(COUNTBLANK(E8:O8)>0,"",0.15*IF(E8="S",5,IF(E8="A",4,IF(E8="B",3,IF(E8="C",2,IF(E8="D",1,0)))))+0.1*IF(F8="S",5,IF(F8="A",4,IF(F8="B",3,IF(F8="C",2,IF(F8="D",1,0)))))+0.1*IF(G8="S",5,IF(G8="A",4,IF(G8="B",3,IF(G8="C",2,IF(G8="D",1,0)))))+0.1*IF(H8="S",5,IF(H8="A",4,IF(H8="B",3,IF(H8="C",2,IF(H8="D",1,0)))))+0.1*IF(I8="S",5,IF(I8="A",4,IF(I8="B",3,IF(I8="C",2,IF(I8="D",1,0)))))+0.1*IF(J8="S",5,IF(J8="A",4,IF(J8="B",3,IF(J8="C",2,IF(J8="D",1,0)))))+0.1*IF(K8="S",5,IF(K8="A",4,IF(K8="B",3,IF(K8="C",2,IF(K8="D",1,0)))))+0.1*IF(L8="S",5,IF(L8="A",4,IF(L8="B",3,IF(L8="C",2,IF(L8="D",1,0)))))+0.05*IF(M8="S",5,IF(M8="A",4,IF(M8="B",3,IF(M8="C",2,IF(M8="D",1,0)))))+0.05*IF(N8="S",5,IF(N8="A",4,IF(N8="B",3,IF(N8="C",2,IF(N8="D",1,0)))))+0.05*IF(O8="S",5,IF(O8="A",4,IF(O8="B",3,IF(O8="C",2,IF(O8="D",1,0)))))),"") | Q8: =IF(P8="","",IF(P8>=4.5,"S",IF(P8>=3.5,"A",IF(P8>=2.5,"B",IF(P8>=1.5,"C","D")))))
A9: ='01_인적정보'!A9 | B9: ='01_인적정보'!B9 | C9: ='01_인적정보'!C9 | D9: ='01_인적정보'!H9 | E9: ='07a_상반기입력'!N9 | F9: ='07a_상반기입력'!O9 | G9: ='07a_상반기입력'!P9 | H9: ='07a_상반기입력'!Q9 | I9: ='07a_상반기입력'!R9 | J9: ='07a_상반기입력'!S9 | K9: ='07a_상반기입력'!T9 | L9: ='07a_상반기입력'!U9 | ... O9: ='07a_상반기입력'!X9 | P9: =IFERROR(IF(COUNTBLANK(E9:O9)>0,"",0.15*IF(E9="S",5,IF(E9="A",4,IF(E9="B",3,IF(E9="C",2,IF(E9="D",1,0)))))+0.1*IF(F9="S",5,IF(F9="A",4,IF(F9="B",3,IF(F9="C",2,IF(F9="D",1,0)))))+0.1*IF(G9="S",5,IF(G9="A",4,IF(G9="B",3,IF(G9="C",2,IF(G9="D",1,0)))))+0.1*IF(H9="S",5,IF(H9="A",4,IF(H9="B",3,IF(H9="C",2,IF(H9="D",1,0)))))+0.1*IF(I9="S",5,IF(I9="A",4,IF(I9="B",3,IF(I9="C",2,IF(I9="D",1,0)))))+0.1*IF(J9="S",5,IF(J9="A",4,IF(J9="B",3,IF(J9="C",2,IF(J9="D",1,0)))))+0.1*IF(K9="S",5,IF(K9="A",4,IF(K9="B",3,IF(K9="C",2,IF(K9="D",1,0)))))+0.1*IF(L9="S",5,IF(L9="A",4,IF(L9="B",3,IF(L9="C",2,IF(L9="D",1,0)))))+0.05*IF(M9="S",5,IF(M9="A",4,IF(M9="B",3,IF(M9="C",2,IF(M9="D",1,0)))))+0.05*IF(N9="S",5,IF(N9="A",4,IF(N9="B",3,IF(N9="C",2,IF(N9="D",1,0)))))+0.05*IF(O9="S",5,IF(O9="A",4,IF(O9="B",3,IF(O9="C",2,IF(O9="D",1,0)))))),"") | Q9: =IF(P9="","",IF(P9>=4.5,"S",IF(P9>=3.5,"A",IF(P9>=2.5,"B",IF(P9>=1.5,"C","D")))))
A10: ='01_인적정보'!A10 | B10: ='01_인적정보'!B10 | C10: ='01_인적정보'!C10 | D10: ='01_인적정보'!H10 | E10: ='07a_상반기입력'!N10 | F10: ='07a_상반기입력'!O10 | G10: ='07a_상반기입력'!P10 | H10: ='07a_상반기입력'!Q10 | I10: ='07a_상반기입력'!R10 | J10: ='07a_상반기입력'!S10 | K10: ='07a_상반기입력'!T10 | L10: ='07a_상반기입력'!U10 | ... O10: ='07a_상반기입력'!X10 | P10: =IFERROR(IF(COUNTBLANK(E10:O10)>0,"",0.15*IF(E10="S",5,IF(E10="A",4,IF(E10="B",3,IF(E10="C",2,IF(E10="D",1,0)))))+0.1*IF(F10="S",5,IF(F10="A",4,IF(F10="B",3,IF(F10="C",2,IF(F10="D",1,0)))))+0.1*IF(G10="S",5,IF(G10="A",4,IF(G10="B",3,IF(G10="C",2,IF(G10="D",1,0)))))+0.1*IF(H10="S",5,IF(H10="A",4,IF(H10="B",3,IF(H10="C",2,IF(H10="D",1,0)))))+0.1*IF(I10="S",5,IF(I10="A",4,IF(I10="B",3,IF(I10="C",2,IF(I10="D",1,0)))))+0.1*IF(J10="S",5,IF(J10="A",4,IF(J10="B",3,IF(J10="C",2,IF(J10="D",1,0)))))+0.1*IF(K10="S",5,IF(K10="A",4,IF(K10="B",3,IF(K10="C",2,IF(K10="D",1,0)))))+0.1*IF(L10="S",5,IF(L10="A",4,IF(L10="B",3,IF(L10="C",2,IF(L10="D",1,0)))))+0.05*IF(M10="S",5,IF(M10="A",4,IF(M10="B",3,IF(M10="C",2,IF(M10="D",1,0)))))+0.05*IF(N10="S",5,IF(N10="A",4,IF(N10="B",3,IF(N10="C",2,IF(N10="D",1,0)))))+0.05*IF(O10="S",5,IF(O10="A",4,IF(O10="B",3,IF(O10="C",2,IF(O10="D",1,0)))))),"") | Q10: =IF(P10="","",IF(P10>=4.5,"S",IF(P10>=3.5,"A",IF(P10>=2.5,"B",IF(P10>=1.5,"C","D")))))
A11: ='01_인적정보'!A11 | B11: ='01_인적정보'!B11 | C11: ='01_인적정보'!C11 | D11: ='01_인적정보'!H11 | E11: ='07a_상반기입력'!N11 | F11: ='07a_상반기입력'!O11 | G11: ='07a_상반기입력'!P11 | H11: ='07a_상반기입력'!Q11 | I11: ='07a_상반기입력'!R11 | J11: ='07a_상반기입력'!S11 | K11: ='07a_상반기입력'!T11 | L11: ='07a_상반기입력'!U11 | ... O11: ='07a_상반기입력'!X11 | P11: =IFERROR(IF(COUNTBLANK(E11:O11)>0,"",0.15*IF(E11="S",5,IF(E11="A",4,IF(E11="B",3,IF(E11="C",2,IF(E11="D",1,0)))))+0.1*IF(F11="S",5,IF(F11="A",4,IF(F11="B",3,IF(F11="C",2,IF(F11="D",1,0)))))+0.1*IF(G11="S",5,IF(G11="A",4,IF(G11="B",3,IF(G11="C",2,IF(G11="D",1,0)))))+0.1*IF(H11="S",5,IF(H11="A",4,IF(H11="B",3,IF(H11="C",2,IF(H11="D",1,0)))))+0.1*IF(I11="S",5,IF(I11="A",4,IF(I11="B",3,IF(I11="C",2,IF(I11="D",1,0)))))+0.1*IF(J11="S",5,IF(J11="A",4,IF(J11="B",3,IF(J11="C",2,IF(J11="D",1,0)))))+0.1*IF(K11="S",5,IF(K11="A",4,IF(K11="B",3,IF(K11="C",2,IF(K11="D",1,0)))))+0.1*IF(L11="S",5,IF(L11="A",4,IF(L11="B",3,IF(L11="C",2,IF(L11="D",1,0)))))+0.05*IF(M11="S",5,IF(M11="A",4,IF(M11="B",3,IF(M11="C",2,IF(M11="D",1,0)))))+0.05*IF(N11="S",5,IF(N11="A",4,IF(N11="B",3,IF(N11="C",2,IF(N11="D",1,0)))))+0.05*IF(O11="S",5,IF(O11="A",4,IF(O11="B",3,IF(O11="C",2,IF(O11="D",1,0)))))),"") | Q11: =IF(P11="","",IF(P11>=4.5,"S",IF(P11>=3.5,"A",IF(P11>=2.5,"B",IF(P11>=1.5,"C","D")))))
A12: ='01_인적정보'!A12 | B12: ='01_인적정보'!B12 | C12: ='01_인적정보'!C12 | D12: ='01_인적정보'!H12 | E12: ='07a_상반기입력'!N12 | F12: ='07a_상반기입력'!O12 | G12: ='07a_상반기입력'!P12 | H12: ='07a_상반기입력'!Q12 | I12: ='07a_상반기입력'!R12 | J12: ='07a_상반기입력'!S12 | K12: ='07a_상반기입력'!T12 | L12: ='07a_상반기입력'!U12 | ... O12: ='07a_상반기입력'!X12 | P12: =IFERROR(IF(COUNTBLANK(E12:O12)>0,"",0.15*IF(E12="S",5,IF(E12="A",4,IF(E12="B",3,IF(E12="C",2,IF(E12="D",1,0)))))+0.1*IF(F12="S",5,IF(F12="A",4,IF(F12="B",3,IF(F12="C",2,IF(F12="D",1,0)))))+0.1*IF(G12="S",5,IF(G12="A",4,IF(G12="B",3,IF(G12="C",2,IF(G12="D",1,0)))))+0.1*IF(H12="S",5,IF(H12="A",4,IF(H12="B",3,IF(H12="C",2,IF(H12="D",1,0)))))+0.1*IF(I12="S",5,IF(I12="A",4,IF(I12="B",3,IF(I12="C",2,IF(I12="D",1,0)))))+0.1*IF(J12="S",5,IF(J12="A",4,IF(J12="B",3,IF(J12="C",2,IF(J12="D",1,0)))))+0.1*IF(K12="S",5,IF(K12="A",4,IF(K12="B",3,IF(K12="C",2,IF(K12="D",1,0)))))+0.1*IF(L12="S",5,IF(L12="A",4,IF(L12="B",3,IF(L12="C",2,IF(L12="D",1,0)))))+0.05*IF(M12="S",5,IF(M12="A",4,IF(M12="B",3,IF(M12="C",2,IF(M12="D",1,0)))))+0.05*IF(N12="S",5,IF(N12="A",4,IF(N12="B",3,IF(N12="C",2,IF(N12="D",1,0)))))+0.05*IF(O12="S",5,IF(O12="A",4,IF(O12="B",3,IF(O12="C",2,IF(O12="D",1,0)))))),"") | Q12: =IF(P12="","",IF(P12>=4.5,"S",IF(P12>=3.5,"A",IF(P12>=2.5,"B",IF(P12>=1.5,"C","D")))))
A13: ='01_인적정보'!A13 | B13: ='01_인적정보'!B13 | C13: ='01_인적정보'!C13 | D13: ='01_인적정보'!H13 | E13: ='07a_상반기입력'!N13 | F13: ='07a_상반기입력'!O13 | G13: ='07a_상반기입력'!P13 | H13: ='07a_상반기입력'!Q13 | I13: ='07a_상반기입력'!R13 | J13: ='07a_상반기입력'!S13 | K13: ='07a_상반기입력'!T13 | L13: ='07a_상반기입력'!U13 | ... O13: ='07a_상반기입력'!X13 | P13: =IFERROR(IF(COUNTBLANK(E13:O13)>0,"",0.15*IF(E13="S",5,IF(E13="A",4,IF(E13="B",3,IF(E13="C",2,IF(E13="D",1,0)))))+0.1*IF(F13="S",5,IF(F13="A",4,IF(F13="B",3,IF(F13="C",2,IF(F13="D",1,0)))))+0.1*IF(G13="S",5,IF(G13="A",4,IF(G13="B",3,IF(G13="C",2,IF(G13="D",1,0)))))+0.1*IF(H13="S",5,IF(H13="A",4,IF(H13="B",3,IF(H13="C",2,IF(H13="D",1,0)))))+0.1*IF(I13="S",5,IF(I13="A",4,IF(I13="B",3,IF(I13="C",2,IF(I13="D",1,0)))))+0.1*IF(J13="S",5,IF(J13="A",4,IF(J13="B",3,IF(J13="C",2,IF(J13="D",1,0)))))+0.1*IF(K13="S",5,IF(K13="A",4,IF(K13="B",3,IF(K13="C",2,IF(K13="D",1,0)))))+0.1*IF(L13="S",5,IF(L13="A",4,IF(L13="B",3,IF(L13="C",2,IF(L13="D",1,0)))))+0.05*IF(M13="S",5,IF(M13="A",4,IF(M13="B",3,IF(M13="C",2,IF(M13="D",1,0)))))+0.05*IF(N13="S",5,IF(N13="A",4,IF(N13="B",3,IF(N13="C",2,IF(N13="D",1,0)))))+0.05*IF(O13="S",5,IF(O13="A",4,IF(O13="B",3,IF(O13="C",2,IF(O13="D",1,0)))))),"") | Q13: =IF(P13="","",IF(P13>=4.5,"S",IF(P13>=3.5,"A",IF(P13>=2.5,"B",IF(P13>=1.5,"C","D")))))
A14: ='01_인적정보'!A14 | B14: ='01_인적정보'!B14 | C14: ='01_인적정보'!C14 | D14: ='01_인적정보'!H14 | E14: ='07a_상반기입력'!N14 | F14: ='07a_상반기입력'!O14 | G14: ='07a_상반기입력'!P14 | H14: ='07a_상반기입력'!Q14 | I14: ='07a_상반기입력'!R14 | J14: ='07a_상반기입력'!S14 | K14: ='07a_상반기입력'!T14 | L14: ='07a_상반기입력'!U14 | ... O14: ='07a_상반기입력'!X14 | P14: =IFERROR(IF(COUNTBLANK(E14:O14)>0,"",0.15*IF(E14="S",5,IF(E14="A",4,IF(E14="B",3,IF(E14="C",2,IF(E14="D",1,0)))))+0.1*IF(F14="S",5,IF(F14="A",4,IF(F14="B",3,IF(F14="C",2,IF(F14="D",1,0)))))+0.1*IF(G14="S",5,IF(G14="A",4,IF(G14="B",3,IF(G14="C",2,IF(G14="D",1,0)))))+0.1*IF(H14="S",5,IF(H14="A",4,IF(H14="B",3,IF(H14="C",2,IF(H14="D",1,0)))))+0.1*IF(I14="S",5,IF(I14="A",4,IF(I14="B",3,IF(I14="C",2,IF(I14="D",1,0)))))+0.1*IF(J14="S",5,IF(J14="A",4,IF(J14="B",3,IF(J14="C",2,IF(J14="D",1,0)))))+0.1*IF(K14="S",5,IF(K14="A",4,IF(K14="B",3,IF(K14="C",2,IF(K14="D",1,0)))))+0.1*IF(L14="S",5,IF(L14="A",4,IF(L14="B",3,IF(L14="C",2,IF(L14="D",1,0)))))+0.05*IF(M14="S",5,IF(M14="A",4,IF(M14="B",3,IF(M14="C",2,IF(M14="D",1,0)))))+0.05*IF(N14="S",5,IF(N14="A",4,IF(N14="B",3,IF(N14="C",2,IF(N14="D",1,0)))))+0.05*IF(O14="S",5,IF(O14="A",4,IF(O14="B",3,IF(O14="C",2,IF(O14="D",1,0)))))),"") | Q14: =IF(P14="","",IF(P14>=4.5,"S",IF(P14>=3.5,"A",IF(P14>=2.5,"B",IF(P14>=1.5,"C","D")))))
A15: ='01_인적정보'!A15 | B15: ='01_인적정보'!B15 | C15: ='01_인적정보'!C15 | D15: ='01_인적정보'!H15 | E15: ='07a_상반기입력'!N15 | F15: ='07a_상반기입력'!O15 | G15: ='07a_상반기입력'!P15 | H15: ='07a_상반기입력'!Q15 | I15: ='07a_상반기입력'!R15 | J15: ='07a_상반기입력'!S15 | K15: ='07a_상반기입력'!T15 | L15: ='07a_상반기입력'!U15 | ... O15: ='07a_상반기입력'!X15 | P15: =IFERROR(IF(COUNTBLANK(E15:O15)>0,"",0.15*IF(E15="S",5,IF(E15="A",4,IF(E15="B",3,IF(E15="C",2,IF(E15="D",1,0)))))+0.1*IF(F15="S",5,IF(F15="A",4,IF(F15="B",3,IF(F15="C",2,IF(F15="D",1,0)))))+0.1*IF(G15="S",5,IF(G15="A",4,IF(G15="B",3,IF(G15="C",2,IF(G15="D",1,0)))))+0.1*IF(H15="S",5,IF(H15="A",4,IF(H15="B",3,IF(H15="C",2,IF(H15="D",1,0)))))+0.1*IF(I15="S",5,IF(I15="A",4,IF(I15="B",3,IF(I15="C",2,IF(I15="D",1,0)))))+0.1*IF(J15="S",5,IF(J15="A",4,IF(J15="B",3,IF(J15="C",2,IF(J15="D",1,0)))))+0.1*IF(K15="S",5,IF(K15="A",4,IF(K15="B",3,IF(K15="C",2,IF(K15="D",1,0)))))+0.1*IF(L15="S",5,IF(L15="A",4,IF(L15="B",3,IF(L15="C",2,IF(L15="D",1,0)))))+0.05*IF(M15="S",5,IF(M15="A",4,IF(M15="B",3,IF(M15="C",2,IF(M15="D",1,0)))))+0.05*IF(N15="S",5,IF(N15="A",4,IF(N15="B",3,IF(N15="C",2,IF(N15="D",1,0)))))+0.05*IF(O15="S",5,IF(O15="A",4,IF(O15="B",3,IF(O15="C",2,IF(O15="D",1,0)))))),"") | Q15: =IF(P15="","",IF(P15>=4.5,"S",IF(P15>=3.5,"A",IF(P15>=2.5,"B",IF(P15>=1.5,"C","D")))))
A16: ='01_인적정보'!A16 | B16: ='01_인적정보'!B16 | C16: ='01_인적정보'!C16 | D16: ='01_인적정보'!H16 | E16: ='07a_상반기입력'!N16 | F16: ='07a_상반기입력'!O16 | G16: ='07a_상반기입력'!P16 | H16: ='07a_상반기입력'!Q16 | I16: ='07a_상반기입력'!R16 | J16: ='07a_상반기입력'!S16 | K16: ='07a_상반기입력'!T16 | L16: ='07a_상반기입력'!U16 | ... O16: ='07a_상반기입력'!X16 | P16: =IFERROR(IF(COUNTBLANK(E16:O16)>0,"",0.15*IF(E16="S",5,IF(E16="A",4,IF(E16="B",3,IF(E16="C",2,IF(E16="D",1,0)))))+0.1*IF(F16="S",5,IF(F16="A",4,IF(F16="B",3,IF(F16="C",2,IF(F16="D",1,0)))))+0.1*IF(G16="S",5,IF(G16="A",4,IF(G16="B",3,IF(G16="C",2,IF(G16="D",1,0)))))+0.1*IF(H16="S",5,IF(H16="A",4,IF(H16="B",3,IF(H16="C",2,IF(H16="D",1,0)))))+0.1*IF(I16="S",5,IF(I16="A",4,IF(I16="B",3,IF(I16="C",2,IF(I16="D",1,0)))))+0.1*IF(J16="S",5,IF(J16="A",4,IF(J16="B",3,IF(J16="C",2,IF(J16="D",1,0)))))+0.1*IF(K16="S",5,IF(K16="A",4,IF(K16="B",3,IF(K16="C",2,IF(K16="D",1,0)))))+0.1*IF(L16="S",5,IF(L16="A",4,IF(L16="B",3,IF(L16="C",2,IF(L16="D",1,0)))))+0.05*IF(M16="S",5,IF(M16="A",4,IF(M16="B",3,IF(M16="C",2,IF(M16="D",1,0)))))+0.05*IF(N16="S",5,IF(N16="A",4,IF(N16="B",3,IF(N16="C",2,IF(N16="D",1,0)))))+0.05*IF(O16="S",5,IF(O16="A",4,IF(O16="B",3,IF(O16="C",2,IF(O16="D",1,0)))))),"") | Q16: =IF(P16="","",IF(P16>=4.5,"S",IF(P16>=3.5,"A",IF(P16>=2.5,"B",IF(P16>=1.5,"C","D")))))
A17: ='01_인적정보'!A17 | B17: ='01_인적정보'!B17 | C17: ='01_인적정보'!C17 | D17: ='01_인적정보'!H17 | E17: ='07a_상반기입력'!N17 | F17: ='07a_상반기입력'!O17 | G17: ='07a_상반기입력'!P17 | H17: ='07a_상반기입력'!Q17 | I17: ='07a_상반기입력'!R17 | J17: ='07a_상반기입력'!S17 | K17: ='07a_상반기입력'!T17 | L17: ='07a_상반기입력'!U17 | ... O17: ='07a_상반기입력'!X17 | P17: =IFERROR(IF(COUNTBLANK(E17:O17)>0,"",0.15*IF(E17="S",5,IF(E17="A",4,IF(E17="B",3,IF(E17="C",2,IF(E17="D",1,0)))))+0.1*IF(F17="S",5,IF(F17="A",4,IF(F17="B",3,IF(F17="C",2,IF(F17="D",1,0)))))+0.1*IF(G17="S",5,IF(G17="A",4,IF(G17="B",3,IF(G17="C",2,IF(G17="D",1,0)))))+0.1*IF(H17="S",5,IF(H17="A",4,IF(H17="B",3,IF(H17="C",2,IF(H17="D",1,0)))))+0.1*IF(I17="S",5,IF(I17="A",4,IF(I17="B",3,IF(I17="C",2,IF(I17="D",1,0)))))+0.1*IF(J17="S",5,IF(J17="A",4,IF(J17="B",3,IF(J17="C",2,IF(J17="D",1,0)))))+0.1*IF(K17="S",5,IF(K17="A",4,IF(K17="B",3,IF(K17="C",2,IF(K17="D",1,0)))))+0.1*IF(L17="S",5,IF(L17="A",4,IF(L17="B",3,IF(L17="C",2,IF(L17="D",1,0)))))+0.05*IF(M17="S",5,IF(M17="A",4,IF(M17="B",3,IF(M17="C",2,IF(M17="D",1,0)))))+0.05*IF(N17="S",5,IF(N17="A",4,IF(N17="B",3,IF(N17="C",2,IF(N17="D",1,0)))))+0.05*IF(O17="S",5,IF(O17="A",4,IF(O17="B",3,IF(O17="C",2,IF(O17="D",1,0)))))),"") | Q17: =IF(P17="","",IF(P17>=4.5,"S",IF(P17>=3.5,"A",IF(P17>=2.5,"B",IF(P17>=1.5,"C","D")))))
... A39: ='01_인적정보'!A39 | B39: ='01_인적정보'!B39 | C39: ='01_인적정보'!C39 | D39: ='01_인적정보'!H39 | E39: ='07a_상반기입력'!N39 | F39: ='07a_상반기입력'!O39 | G39: ='07a_상반기입력'!P39 | H39: ='07a_상반기입력'!Q39 | I39: ='07a_상반기입력'!R39 | J39: ='07a_상반기입력'!S39 | K39: ='07a_상반기입력'!T39 | L39: ='07a_상반기입력'!U39 | ... O39: ='07a_상반기입력'!X39 | P39: =IFERROR(IF(COUNTBLANK(E39:O39)>0,"",0.15*IF(E39="S",5,IF(E39="A",4,IF(E39="B",3,IF(E39="C",2,IF(E39="D",1,0)))))+0.1*IF(F39="S",5,IF(F39="A",4,IF(F39="B",3,IF(F39="C",2,IF(F39="D",1,0)))))+0.1*IF(G39="S",5,IF(G39="A",4,IF(G39="B",3,IF(G39="C",2,IF(G39="D",1,0)))))+0.1*IF(H39="S",5,IF(H39="A",4,IF(H39="B",3,IF(H39="C",2,IF(H39="D",1,0)))))+0.1*IF(I39="S",5,IF(I39="A",4,IF(I39="B",3,IF(I39="C",2,IF(I39="D",1,0)))))+0.1*IF(J39="S",5,IF(J39="A",4,IF(J39="B",3,IF(J39="C",2,IF(J39="D",1,0)))))+0.1*IF(K39="S",5,IF(K39="A",4,IF(K39="B",3,IF(K39="C",2,IF(K39="D",1,0)))))+0.1*IF(L39="S",5,IF(L39="A",4,IF(L39="B",3,IF(L39="C",2,IF(L39="D",1,0)))))+0.05*IF(M39="S",5,IF(M39="A",4,IF(M39="B",3,IF(M39="C",2,IF(M39="D",1,0)))))+0.05*IF(N39="S",5,IF(N39="A",4,IF(N39="B",3,IF(N39="C",2,IF(N39="D",1,0)))))+0.05*IF(O39="S",5,IF(O39="A",4,IF(O39="B",3,IF(O39="C",2,IF(O39="D",1,0)))))),"") | Q39: =IF(P39="","",IF(P39>=4.5,"S",IF(P39>=3.5,"A",IF(P39>=2.5,"B",IF(P39>=1.5,"C","D")))))
A44: ■ 하반기 공통역량평가
A45: No. | B45: 사번 | C45: 성명 | D45: 역할등급 | E45: C-1 직무 전문성 | F45: C-2 분석력 | G45: C-3 기획/실행력 | H45: C-4 자원·시간 관리 | I45: C-5 협업 능력 | J45: C-6 소통 능력 | K45: C-7 윤리/책임감 | L45: C-8 업무 태도 | M45: C-9 혁신 역량 | N45: C-10 프로세스 개선 | O45: C-11 지속가능 기여 | P45: 가중합산 | Q45: 등급 | R45: 소견
A46: ='01_인적정보'!A6 | B46: ='01_인적정보'!B6 | C46: ='01_인적정보'!C6 | D46: ='01_인적정보'!H6 | E46: ='07b_하반기입력'!N6 | F46: ='07b_하반기입력'!O6 | G46: ='07b_하반기입력'!P6 | H46: ='07b_하반기입력'!Q6 | I46: ='07b_하반기입력'!R6 | J46: ='07b_하반기입력'!S6 | K46: ='07b_하반기입력'!T6 | L46: ='07b_하반기입력'!U6 | ... O46: ='07b_하반기입력'!X6 | P46: =IFERROR(IF(COUNTBLANK(E46:O46)>0,"",0.15*IF(E46="S",5,IF(E46="A",4,IF(E46="B",3,IF(E46="C",2,IF(E46="D",1,0)))))+0.1*IF(F46="S",5,IF(F46="A",4,IF(F46="B",3,IF(F46="C",2,IF(F46="D",1,0)))))+0.1*IF(G46="S",5,IF(G46="A",4,IF(G46="B",3,IF(G46="C",2,IF(G46="D",1,0)))))+0.1*IF(H46="S",5,IF(H46="A",4,IF(H46="B",3,IF(H46="C",2,IF(H46="D",1,0)))))+0.1*IF(I46="S",5,IF(I46="A",4,IF(I46="B",3,IF(I46="C",2,IF(I46="D",1,0)))))+0.1*IF(J46="S",5,IF(J46="A",4,IF(J46="B",3,IF(J46="C",2,IF(J46="D",1,0)))))+0.1*IF(K46="S",5,IF(K46="A",4,IF(K46="B",3,IF(K46="C",2,IF(K46="D",1,0)))))+0.1*IF(L46="S",5,IF(L46="A",4,IF(L46="B",3,IF(L46="C",2,IF(L46="D",1,0)))))+0.05*IF(M46="S",5,IF(M46="A",4,IF(M46="B",3,IF(M46="C",2,IF(M46="D",1,0)))))+0.05*IF(N46="S",5,IF(N46="A",4,IF(N46="B",3,IF(N46="C",2,IF(N46="D",1,0)))))+0.05*IF(O46="S",5,IF(O46="A",4,IF(O46="B",3,IF(O46="C",2,IF(O46="D",1,0)))))),"") | Q46: =IF(P46="","",IF(P46>=4.5,"S",IF(P46>=3.5,"A",IF(P46>=2.5,"B",IF(P46>=1.5,"C","D")))))
A47: ='01_인적정보'!A7 | B47: ='01_인적정보'!B7 | C47: ='01_인적정보'!C7 | D47: ='01_인적정보'!H7 | E47: ='07b_하반기입력'!N7 | F47: ='07b_하반기입력'!O7 | G47: ='07b_하반기입력'!P7 | H47: ='07b_하반기입력'!Q7 | I47: ='07b_하반기입력'!R7 | J47: ='07b_하반기입력'!S7 | K47: ='07b_하반기입력'!T7 | L47: ='07b_하반기입력'!U7 | ... O47: ='07b_하반기입력'!X7 | P47: =IFERROR(IF(COUNTBLANK(E47:O47)>0,"",0.15*IF(E47="S",5,IF(E47="A",4,IF(E47="B",3,IF(E47="C",2,IF(E47="D",1,0)))))+0.1*IF(F47="S",5,IF(F47="A",4,IF(F47="B",3,IF(F47="C",2,IF(F47="D",1,0)))))+0.1*IF(G47="S",5,IF(G47="A",4,IF(G47="B",3,IF(G47="C",2,IF(G47="D",1,0)))))+0.1*IF(H47="S",5,IF(H47="A",4,IF(H47="B",3,IF(H47="C",2,IF(H47="D",1,0)))))+0.1*IF(I47="S",5,IF(I47="A",4,IF(I47="B",3,IF(I47="C",2,IF(I47="D",1,0)))))+0.1*IF(J47="S",5,IF(J47="A",4,IF(J47="B",3,IF(J47="C",2,IF(J47="D",1,0)))))+0.1*IF(K47="S",5,IF(K47="A",4,IF(K47="B",3,IF(K47="C",2,IF(K47="D",1,0)))))+0.1*IF(L47="S",5,IF(L47="A",4,IF(L47="B",3,IF(L47="C",2,IF(L47="D",1,0)))))+0.05*IF(M47="S",5,IF(M47="A",4,IF(M47="B",3,IF(M47="C",2,IF(M47="D",1,0)))))+0.05*IF(N47="S",5,IF(N47="A",4,IF(N47="B",3,IF(N47="C",2,IF(N47="D",1,0)))))+0.05*IF(O47="S",5,IF(O47="A",4,IF(O47="B",3,IF(O47="C",2,IF(O47="D",1,0)))))),"") | Q47: =IF(P47="","",IF(P47>=4.5,"S",IF(P47>=3.5,"A",IF(P47>=2.5,"B",IF(P47>=1.5,"C","D")))))
A48: ='01_인적정보'!A8 | B48: ='01_인적정보'!B8 | C48: ='01_인적정보'!C8 | D48: ='01_인적정보'!H8 | E48: ='07b_하반기입력'!N8 | F48: ='07b_하반기입력'!O8 | G48: ='07b_하반기입력'!P8 | H48: ='07b_하반기입력'!Q8 | I48: ='07b_하반기입력'!R8 | J48: ='07b_하반기입력'!S8 | K48: ='07b_하반기입력'!T8 | L48: ='07b_하반기입력'!U8 | ... O48: ='07b_하반기입력'!X8 | P48: =IFERROR(IF(COUNTBLANK(E48:O48)>0,"",0.15*IF(E48="S",5,IF(E48="A",4,IF(E48="B",3,IF(E48="C",2,IF(E48="D",1,0)))))+0.1*IF(F48="S",5,IF(F48="A",4,IF(F48="B",3,IF(F48="C",2,IF(F48="D",1,0)))))+0.1*IF(G48="S",5,IF(G48="A",4,IF(G48="B",3,IF(G48="C",2,IF(G48="D",1,0)))))+0.1*IF(H48="S",5,IF(H48="A",4,IF(H48="B",3,IF(H48="C",2,IF(H48="D",1,0)))))+0.1*IF(I48="S",5,IF(I48="A",4,IF(I48="B",3,IF(I48="C",2,IF(I48="D",1,0)))))+0.1*IF(J48="S",5,IF(J48="A",4,IF(J48="B",3,IF(J48="C",2,IF(J48="D",1,0)))))+0.1*IF(K48="S",5,IF(K48="A",4,IF(K48="B",3,IF(K48="C",2,IF(K48="D",1,0)))))+0.1*IF(L48="S",5,IF(L48="A",4,IF(L48="B",3,IF(L48="C",2,IF(L48="D",1,0)))))+0.05*IF(M48="S",5,IF(M48="A",4,IF(M48="B",3,IF(M48="C",2,IF(M48="D",1,0)))))+0.05*IF(N48="S",5,IF(N48="A",4,IF(N48="B",3,IF(N48="C",2,IF(N48="D",1,0)))))+0.05*IF(O48="S",5,IF(O48="A",4,IF(O48="B",3,IF(O48="C",2,IF(O48="D",1,0)))))),"") | Q48: =IF(P48="","",IF(P48>=4.5,"S",IF(P48>=3.5,"A",IF(P48>=2.5,"B",IF(P48>=1.5,"C","D")))))
