Workbook

Sheet 00_운영가이드
A1: d
A2: 1년 2회 평가(상·하반기) → 등급 결정 → 임금 조정 → 페이밴드 검증의 End-to-End 운영 도구
A4: ■ 우리가 하려는 일 (핵심 의사결정 4단계)
A5: 단계 | B5: 핵심 작업 | C5: 의사결정 | D5: 주요 내용
A6: STEP 1 | B6: 평가 실시 | C6: 연 2회(상반기·하반기) 개인별 3축 평가 | D6: 역할평가 + 공통역량평가 + 직무역량평가
A7: STEP 2 | B7: 등급 결정 | C7: 회사 전체 KPI + 개인 평가 결과 종합 | D7: 3축 가중통합 → 최종 등급(S/A/B/C/D) 산출
A8: STEP 3 | B8: 임금 조정 | C8: 평가 등급에 따라 차년도 기본연봉 인상 | D8: S 6% / A 5% / B 4% / C 3% / D 2% (+ 승진 가산)
A9: STEP 4 | B9: 페이밴드 관리 | C9: 전체 임직원 임금이 역할등급별 범위 내 유지 | D9: Min/Mid/Max 검증 → 이탈자 조정 권고
A12: ■ 우리가 가진 도구 (산출물)
A13: 도구 | B13: 파일/시트 | E13: 용도·운영 주체
A14: 통합 관리 시트 | B14: 본 파일 (HR 통합관리시스템 v5.xlsx) | E14: HR 담당자가 모든 평가 결과를 모아 종합 등급·인상률·페이밴드를 산출. 본 파일.
A15: 직무별 평가지 | B15: 평가지_2026_v2/평가지_{부서}_2026_v2.xlsx (부서별 6종) | E15: 부서장(1·2차 평가자)이 작성. HR이 배포·회수 후 [복사용 행]을 통합시트에 옮김.
A17: ■ HR 담당자 운영 흐름 (한 평가 사이클)
A18: 단계 | B18: 내용
A19: ① 준비 | B19: 01_인적정보 확인 + 15_직원별책무매핑에서 직원별 메인 책무 O/X 선택
A20: ② 배포 | B20: 평가지_{부서}_2026_v2.xlsx 6개 파일을 각 부서장에게 배포 (이메일/공유폴더)
A21: ③ 평가 | B21: 부서장(1·2차 평가자)이 각자 등급(S/A/B/C/D) 입력 → 시트가 가중평균·등급 자동 산출
A22: ④ 회수 | B22: 평가지 회수 (보통 평가 마감 후 1주일 내)
A23: ⑤ 입력 | B23: 각 평가지 직원 시트 하단 [복사용 입력 행] A~U 21개 셀 통째 복사 → 본 파일 07a/07b의 해당 사번 행 G~AA에 [값 붙여넣기]
A24: ⑥ 점검 | B24: 00_운영현황판에서 누락·이상 알림 확인 → 보완
A25: ⑦ 결과 확인 | B25: 08_종합평가 (최종등급) / 09_보상연계 (인상률·신규연봉) / 10_성과급관리 / 11_페이밴드검증 / 12_시뮬레이션
A27: ■ 본 파일 시트 역할 (18개)
A28: 시트 | B28: 역할 | G28: 유형
A29: 00_운영가이드 | B29: 본 시트 - 운영 흐름·시트 안내 | G29: 안내
A30: 00_운영현황판 | B30: 평가 진행률·이상 알림·등급 분포 한눈에 | G30: 대시보드
A31: 01_인적정보 | B31: 직원 마스터(34명). 사번·역할등급 입력 | G31: HR 입력
A32: 02_의사결정·종합결과 | B32: 가중치·인상률·페이밴드·평가자 비중 설정 | G32: HR 입력
A33: 03_전사업적평가 | B33: 전사 KPI 실적 입력 → 성과급 재원 가산 | G33: HR 입력
A34: 04_역할평가 | B34: 자동 산출 (07a/07b 입력값 기반) | G34: 자동
A35: 05_공통역량평가 | B35: 자동 산출 (11개 역량 가중합산) | G35: 자동
A36: 06_직무역량평가 | B36: 자동 산출 (개인별 메인 책무 평균) | G36: 자동
A37: 07a_상반기입력 | B37: 부서별 평가지의 [복사용 행]을 여기 G~AA에 붙여넣기 | G37: HR 입력 (핵심)
A38: 07b_하반기입력 | B38: 하반기 동일 구조 | G38: HR 입력 (핵심)
A39: 08_종합평가 | B39: 3축 가중통합 → 최종 등급 | G39: 자동
... A46: 15_직원별책무매핑 | B46: 직원별 메인 책무 O/X 선택 | G46: HR 입력
A48: ■ 색상 범례
B49: 노란셀 | C49: HR이 직접 입력 | F49: 연두셀 | G49: 자동 계산 - 수정 금지
B50: 회색셀 | C50: 참고 라벨 | F50: 주황셀 | G50: 안내·중요 표시
B51: S/A 등급 | C51: 탁월·우수 | F51: D 등급/이탈 | G51: 즉시 조치
A81: 본 시스템은 베이시스소프트의 임금·평가 운영을 위해 설계되었습니다. 사용 중 의문 사항은 컨설팅 담당자 또는 시앤피컨설팅 이석주 컨설턴트에게 문의해 주세요.

Sheet 00_운영현황판
A1: ★ HR 운영 현황판 (모든 평가 진행 상황 한눈에)
A2: 이 시트가 평가 사이클의 컨트롤 타워. 여기서 진행률·이상신호 확인 후 각 시트로 진입.
A3: ✻ 이 시트는 평가 사이클이 진행되는 동안 매일 가장 먼저 확인하는 페이지입니다. 진행률·이상 알림으로 현재 상태를 즉시 파악하세요.
A4: ■ 평가 진행 현황
A5: 지표 | B5: 상반기 진행 | C5: 하반기 진행 | D5: 상태
A6: 총 직원수 | B6: =COUNTA('01_인적정보'!C6:C65) -> 34 | C6: =B6 -> 34 | D6: =IF(B$6=0,"",IF(B6>=B$6,"✓ 완료",IF(B6>0,"진행중","미시작"))) -> ✓ 완료
A7: 역할평가 입력완료 | B7: =COUNTA('07a_상반기입력'!L6:L39) -> 0 | C7: =COUNTA('07b_하반기입력'!L6:L39) -> 0 | D7: =IF(B$6=0,"",IF(B7>=B$6,"✓ 완료",IF(B7>0,"진행중","미시작"))) -> 미시작
A8: 공통역량 입력완료 | B8: =COUNTA('07a_상반기입력'!N6:N39) -> 0 | C8: =COUNTA('07b_하반기입력'!N6:N39) -> 0 | D8: =IF(B$6=0,"",IF(B8>=B$6,"✓ 완료",IF(B8>0,"진행중","미시작"))) -> 미시작
A9: 직무역량 입력완료 | B9: =COUNTA('07a_상반기입력'!Y6:Y39) -> 0 | C9: =COUNTA('07b_하반기입력'!Y6:Y39) -> 0 | D9: =IF(B$6=0,"",IF(B9>=B$6,"✓ 완료",IF(B9>0,"진행중","미시작"))) -> 미시작
A10: 종합평가 산출완료 | B10: =COUNTA('08_종합평가'!U6:U39) -> 34 | C10: =B10 -> 34 | D10: =IF(B$6=0,"",IF(B10>=B$6,"✓ 완료",IF(B10>0,"진행중","미시작"))) -> ✓ 완료
A12: ■ 이상 알림 (자동 점검)
A13: 가중치 합계 검증 (G6~G1) | B13: =IF(SUMPRODUCT(('02_의사결정·종합결과'!E16:E22<>1)*1)>0,"✗ 가중치 합계 ≠ 100% 행 존재","✓ 모든 가중치 OK") -> ✓ 모든 가중치 OK
A14: 상반기 등급 누락자 수 | B14: =COUNTA('01_인적정보'!B6:B39) - COUNTA('07a_상반기입력'!L6:L39) -> 34
A15: 하반기 등급 누락자 수 | B15: =COUNTA('01_인적정보'!B6:B39) - COUNTA('07b_하반기입력'!L6:L39) -> 34
A16: 페이밴드 이탈자 수 | B16: =SUMPRODUCT(('09_보상연계'!O6:O39<'09_보상연계'!L6:L39)+('09_보상연계'!O6:O39>'09_보상연계'!M6:M39)) -> 30
A17: 페이밴드 검증 시트의 이탈자 (참조) | B17: =SUM('11_페이밴드검증'!H6:H12) -> 4
A19: ■ 평가 등급 분포 (전사 종합)
A20: 등급 | B20: S | C20: A | D20: B | E20: C | F20: D
A21: 인원수 | B21: =COUNTIF('08_종합평가'!U6:U39,"S") -> 0 | C21: =COUNTIF('08_종합평가'!U6:U39,"A") -> 0 | D21: =COUNTIF('08_종합평가'!U6:U39,"B") -> 0 | E21: =COUNTIF('08_종합평가'!U6:U39,"C") -> 0 | F21: =COUNTIF('08_종합평가'!U6:U39,"D") -> 34
A24: ■ 오늘 해야 할 일
A25: 1) 01_인적정보에서 직원 명단·역할등급(G5-M/G5-S 포함) 확인
A26: 2) 15_직원별책무매핑에서 직원별 메인 책무 선택 (신규 - 평가 시작 전 필수)
A27: 3) 부서별 평가지 6종 배포 (평가자에게 이메일/공유폴더 전달)
A28: 4) 평가지 회수 후 07a/07b 상·하반기 입력 시트에 등급 입력
A29: 5) 본 시트에서 진행률·이상알림 확인
A30: 6) 모두 완료 시 08~12 산출 시트에서 결과 확인

Sheet 01_인적정보
A1: 임직원 명부 마스터 (Master)
A2: 사번을 키로 모든 시트를 연결. 노란셀만 직접 수정. ★ G5는 M(부서장)/S(스페셜리스트)로 분리되어 있습니다.
A5: No. | B5: 사번 | C5: 성명 | D5: 직군 | E5: 직무 | F5: 부서 | G5: 기존직급 | H5: 역할등급 | I5: 입사일 | J5: 근속연수 | K5: 기존연봉 | L5: 주요 책무 수 | M5: 조회키(직무_등급) | N5: 비고
A6: 1 | B6: BSS-001 | C6: 이화형 | D6: 영업 | E6: 프로젝트영업 | F6: 스마트사업부 | G6: 전무 | H6: G6 | I6: 2014-01-08 | J6: =IFERROR(ROUND((TODAY()-DATEVALUE(I6))/365,1),"") -> 12.4 | K6: 72500000 | L6: =IFERROR(INDEX('15_직원별책무매핑'!$E:$E,MATCH(B6,'15_직원별책무매핑'!$B:$B,0)),0) -> 0 | M6: =E6&"_"&H6 -> 프로젝트영업_G6
A7: 2 | B7: BSS-002 | C7: 강전용 | D7: 연구&개발 | E7: 연구개발(R&D) | F7: R&D본부 | G7: 상무 | H7: G6 | I7: 2014-02-15 | J7: =IFERROR(ROUND((TODAY()-DATEVALUE(I7))/365,1),"") -> 12.2 | K7: 68870000 | L7: =IFERROR(INDEX('15_직원별책무매핑'!$E:$E,MATCH(B7,'15_직원별책무매핑'!$B:$B,0)),0) -> 0 | M7: =E7&"_"&H7 -> 연구개발(R&D)_G6
A8: 3 | B8: BSS-003 | C8: 김현민 | D8: 설계 | E8: BIM컨설팅 | F8: 컨설팅본부 | G8: 상무 | H8: G6 | I8: 2014-03-22 | J8: =IFERROR(ROUND((TODAY()-DATEVALUE(I8))/365,1),"") -> 12.2 | K8: 67500000 | L8: =IFERROR(INDEX('15_직원별책무매핑'!$E:$E,MATCH(B8,'15_직원별책무매핑'!$B:$B,0)),0) -> 0 | M8: =E8&"_"&H8 -> BIM컨설팅_G6
A9: 4 | B9: BSS-004 | C9: 이일곤 | D9: 경영관리 | E9: 경영전략기획 | F9: 경영전략실 | G9: 이사 | H9: G6 | I9: 2014-04-01 | J9: =IFERROR(ROUND((TODAY()-DATEVALUE(I9))/365,1),"") -> 12.1 | K9: 64530000 | L9: =IFERROR(INDEX('15_직원별책무매핑'!$E:$E,MATCH(B9,'15_직원별책무매핑'!$B:$B,0)),0) -> 0 | M9: =E9&"_"&H9 -> 경영전략기획_G6
A10: 5 | B10: BSS-005 | C10: 송헌영 | D10: 경영관리 | E10: 경영전략기획 | F10: 경영전략실 | G10: 이사 | H10: G6 | I10: 2015-05-08 | J10: =IFERROR(ROUND((TODAY()-DATEVALUE(I10))/365,1),"") -> 11 | K10: 65180000 | L10: =IFERROR(INDEX('15_직원별책무매핑'!$E:$E,MATCH(B10,'15_직원별책무매핑'!$B:$B,0)),0) -> 0 | M10: =E10&"_"&H10 -> 경영전략기획_G6
A11: 6 | B11: BSS-006 | C11: 이재용 | D11: 경영관리 | E11: 경영전략기획 | F11: 경영전략실 | G11: 이사 | H11: G6 | I11: 2015-06-15 | J11: =IFERROR(ROUND((TODAY()-DATEVALUE(I11))/365,1),"") -> 10.9 | K11: 62000000 | L11: =IFERROR(INDEX('15_직원별책무매핑'!$E:$E,MATCH(B11,'15_직원별책무매핑'!$B:$B,0)),0) -> 0 | M11: =E11&"_"&H11 -> 경영전략기획_G6
A12: 7 | B12: BSS-007 | C12: 이진행 | D12: 교육 및 기술지원 | E12: 교육 | F12: 솔루션본부 | G12: 부장 | H12: G5-M | I12: 2015-07-22 | J12: =IFERROR(ROUND((TODAY()-DATEVALUE(I12))/365,1),"") -> 10.8 | K12: 59700000 | L12: =IFERROR(INDEX('15_직원별책무매핑'!$E:$E,MATCH(B12,'15_직원별책무매핑'!$B:$B,0)),0) -> 0 | M12: =E12&"_"&H12 -> 교육_G5-M
A13: 8 | B13: BSS-008 | C13: 김민수 | D13: 교육 및 기술지원 | E13: 기술지원 | F13: 솔루션본부 | G13: 부장 | H13: G5-M | I13: 2015-08-01 | J13: =IFERROR(ROUND((TODAY()-DATEVALUE(I13))/365,1),"") -> 10.8 | K13: 59050000 | L13: =IFERROR(INDEX('15_직원별책무매핑'!$E:$E,MATCH(B13,'15_직원별책무매핑'!$B:$B,0)),0) -> 0 | M13: =E13&"_"&H13 -> 기술지원_G5-M
A14: 9 | B14: BSS-009 | C14: 박남식 | D14: 설계 | E14: BIM컨설팅 | F14: 컨설팅본부 | G14: 부장 | H14: G5-M | I14: 2016-09-08 | J14: =IFERROR(ROUND((TODAY()-DATEVALUE(I14))/365,1),"") -> 9.7 | K14: 59050000 | L14: =IFERROR(INDEX('15_직원별책무매핑'!$E:$E,MATCH(B14,'15_직원별책무매핑'!$B:$B,0)),0) -> 0 | M14: =E14&"_"&H14 -> BIM컨설팅_G5-M
A15: 10 | B15: BSS-010 | C15: 신재민 | D15: 설계 | E15: BIM컨설팅 | F15: 컨설팅본부 | G15: 부장 | H15: G5-S | I15: 2016-10-15 | J15: =IFERROR(ROUND((TODAY()-DATEVALUE(I15))/365,1),"") -> 9.6 | K15: 59050000 | L15: =IFERROR(INDEX('15_직원별책무매핑'!$E:$E,MATCH(B15,'15_직원별책무매핑'!$B:$B,0)),0) -> 0 | M15: =E15&"_"&H15 -> BIM컨설팅_G5-S
A16: 11 | B16: BSS-011 | C16: 마장엽 | D16: 설계 | E16: BIM컨설팅 | F16: 컨설팅본부 | G16: 부장 | H16: G5-S | I16: 2016-11-22 | J16: =IFERROR(ROUND((TODAY()-DATEVALUE(I16))/365,1),"") -> 9.5 | K16: 57760000 | L16: =IFERROR(INDEX('15_직원별책무매핑'!$E:$E,MATCH(B16,'15_직원별책무매핑'!$B:$B,0)),0) -> 0 | M16: =E16&"_"&H16 -> BIM컨설팅_G5-S
A17: 12 | B17: BSS-012 | C17: 하은주 | D17: 경영관리 | E17: 경영전략기획 | F17: 마케팅팀 | G17: 부장 | H17: G5-M | I17: 2016-12-01 | J17: =IFERROR(ROUND((TODAY()-DATEVALUE(I17))/365,1),"") -> 9.5 | K17: 57760000 | L17: =IFERROR(INDEX('15_직원별책무매핑'!$E:$E,MATCH(B17,'15_직원별책무매핑'!$B:$B,0)),0) -> 0 | M17: =E17&"_"&H17 -> 경영전략기획_G5-M
... A39: 34 | B39: BSS-034 | C39: 엄보근 | D39: 설계 | E39: BIM컨설팅 | F39: 컨설팅본부 | G39: 사원 | H39: G1 | I39: 2022-10-15 | J39: =IFERROR(ROUND((TODAY()-DATEVALUE(I39))/365,1),"") -> 3.6 | K39: 32000000 | L39: =IFERROR(INDEX('15_직원별책무매핑'!$E:$E,MATCH(B39,'15_직원별책무매핑'!$B:$B,0)),0) -> 0 | M39: =E39&"_"&H39 -> BIM컨설팅_G1
A42: ■ 자동 통계 (역할등급별/직군별/부서별)
A43: 역할등급 | B43: 인원 | L43: =IFERROR(INDEX('15_직원별책무매핑'!$E:$E,MATCH(B43,'15_직원별책무매핑'!$B:$B,0)),0) -> 0
A44: G6 | B44: =COUNTIF(H6:H85,"G6") -> 6 | L44: =IFERROR(INDEX('15_직원별책무매핑'!$E:$E,MATCH(B44,'15_직원별책무매핑'!$B:$B,0)),0) -> 0
A45: G5-M | B45: =COUNTIF(H6:H85,"G5-M") -> 4 | L45: =IFERROR(INDEX('15_직원별책무매핑'!$E:$E,MATCH(B45,'15_직원별책무매핑'!$B:$B,0)),0) -> 0
A46: G5-S | B46: =COUNTIF(H6:H85,"G5-S") -> 6 | L46: =IFERROR(INDEX('15_직원별책무매핑'!$E:$E,MATCH(B46,'15_직원별책무매핑'!$B:$B,0)),0) -> 0
A47: G4 | B47: =COUNTIF(H6:H85,"G4") -> 2 | L47: =IFERROR(INDEX('15_직원별책무매핑'!$E:$E,MATCH(B47,'15_직원별책무매핑'!$B:$B,0)),0) -> 0
A48: G3 | B48: =COUNTIF(H6:H85,"G3") -> 2 | L48: =IFERROR(INDEX('15_직원별책무매핑'!$E:$E,MATCH(B48,'15_직원별책무매핑'!$B:$B,0)),0) -> 0
A49: G2 | B49: =COUNTIF(H6:H85,"G2") -> 6 | L49: =IFERROR(INDEX('15_직원별책무매핑'!$E:$E,MATCH(B49,'15_직원별책무매핑'!$B:$B,0)),0) -> 0
A50: G1 | B50: =COUNTIF(H6:H85,"G1") -> 8

Sheet 02_의사결정·종합결과
A1: HR 의사결정 컨피그 (가중치·인상률·페이밴드)
A2: 이 시트에서 가중치·인상률·페이밴드를 정의. 모든 산출 시트가 자동 참조합니다.
A4: ■ ① 평가 방식·반기 가중치
A5: 평가 척도 | B5: 5점 | C5: 5점 또는 100점 (전 시트 일괄 적용)
A6: 평가 방식 | B6: 절대평가 | C6: 절대평가: 점수→등급 환산 / 상대평가: 분포 강제
A7: 상반기 가중치 | B7: 0.5 | C7: 평가차수별 가중치
A8: 하반기 가중치 | B8: =1-B7 -> 0.5 | C8: 자동 계산
A10: 강제분포 비중 | B10: S | C10: A | D10: B | E10: C | F10: D
B11: 0.1 | C11: 0.15 | D11: 0.5 | E11: 0.15 | F11: 0.1
A14: ■ ② 직급별 3축 평가 가중치 (역할 + 공통역량 + 직무역량 = 100%) ★ G5-M/G5-S 분리
A15: 역할등급 | B15: 역할평가 W | C15: 공통역량 W | D15: 직무역량 W | E15: 합계 | F15: 검증 | G15: 설계 의도
A16: G6 | B16: 0.4 | C16: 0.25 | D16: 0.35 | E16: =B16+C16+D16 -> 1 | F16: =IF(E16=1,"✓ OK","✗ ≠100%") -> ✓ OK | G16: 경영성과 책임·전사 의사결정 중심
A17: G5-M | B17: 0.35 | C17: 0.3 | D17: 0.35 | E17: =B17+C17+D17 -> 1 | F17: =IF(E17=1,"✓ OK","✗ ≠100%") -> ✓ OK | G17: 조직 관리·부서장 성과 책임
A18: G5-S | B18: 0.3 | C18: 0.3 | D18: 0.4 | E18: =B18+C18+D18 -> 1 | F18: =IF(E18=1,"✓ OK","✗ ≠100%") -> ✓ OK | G18: 실무 스페셜리스트·전문성 강조
A19: G4 | B19: 0.3 | C19: 0.3 | D19: 0.4 | E19: =B19+C19+D19 -> 1 | F19: =IF(E19=1,"✓ OK","✗ ≠100%") -> ✓ OK | G19: 실무 책임자, 직무역량 강조
A20: G3 | B20: 0.25 | C20: 0.3 | D20: 0.45 | E20: =B20+C20+D20 -> 1 | F20: =IF(E20=1,"✓ OK","✗ ≠100%") -> ✓ OK | G20: 핵심 실무자, 직무 깊이 가중
A21: G2 | B21: 0.2 | C21: 0.35 | D21: 0.45 | E21: =B21+C21+D21 -> 1 | F21: =IF(E21=1,"✓ OK","✗ ≠100%") -> ✓ OK | G21: 실무자, 역량 개발 집중
A22: G1 | B22: 0.15 | C22: 0.35 | D22: 0.5 | E22: =B22+C22+D22 -> 1 | F22: =IF(E22=1,"✓ OK","✗ ≠100%") -> ✓ OK | G22: 신입·실무 보조, 기본기 학습
A24: ■ ③ 평가 등급별 인상률·성과급률
A25: 구분 | B25: S | C25: A | D25: B | E25: C | F25: D | G25: 비고
A26: 기본연봉 인상률 | B26: 0.06 | C26: 0.05 | D26: 0.04 | E26: 0.03 | F26: 0.02 | G26: 09_보상연계에 자동 반영
A27: 성과급 지급률 | B27: 0.2 | C27: 0.15 | D27: 0.1 | E27: 0.05 | F27: 0 | G27: 10_성과급관리에 자동 반영
A28: 승진 가산률 | B28: 0.01 | C28: 승진(역할등급 상승) 시 기본연봉 인상률에 가산 | G28: Y/N 선택 시 자동 적용
A30: ■ ④ 페이밴드 (역할등급별 기본연봉 범위)
A31: 역할등급 | B31: 최소(Min) | C31: 중위(Mid) | D31: 최대(Max) | E31: Range Spread
A32: G6 | B32: 58000000 | C32: 69000000 | D32: 80000000 | E32: =(D32-B32)/B32 -> 0.37931034
A33: G5-M | B33: 53000000 | C33: 63000000 | D33: 73000000 | E33: =(D33-B33)/B33 -> 0.37735849
A34: G5-S | B34: 53000000 | C34: 63000000 | D34: 73000000 | E34: =(D34-B34)/B34 -> 0.37735849
A35: G4 | B35: 49000000 | C35: 57500000 | D35: 66000000 | E35: =(D35-B35)/B35 -> 0.34693878
A36: G3 | B36: 42000000 | C36: 49500000 | D36: 57000000 | E36: =(D36-B36)/B36 -> 0.35714286
A37: G2 | B37: 36000000 | C37: 42500000 | D37: 49000000 | E37: =(D37-B37)/B37 -> 0.36111111
A38: G1 | B38: 33000000 | C38: 38500000 | D38: 44000000 | E38: =(D38-B38)/B38 -> 0.33333333
A40: ■ ⑤ 공통역량별 가중치 (11개 역량)
A41: No. | B41: 역량군 | C41: 핵심 역량 | D41: 가중치 | E41: 역량 설명
A42: C-1 | B42: 업무역량 | C42: 직무 전문성 | D42: 0.15 | E42: 직무에 필요한 전문 지식 및 기술을 충분히 보유하고 실무에 적절히 적용하는지 평가
A43: C-2 | B43: 업무역량 | C43: 분석력 | D43: 0.1 | E43: 데이터·수치를 기반으로 사고하며 업무 효율을 높이는 능력
A44: C-3 | B44: 업무역량 | C44: 기획/실행력 | D44: 0.1 | E44: 실행 가능한 목표 설정·계획 수립·체계적 실행 능력
A45: C-4 | B45: 조직역량 | C45: 자원·시간 관리 | D45: 0.1 | E45: 업무 우선순위 설정 및 시간 내 효과적 업무 완수 능력
A46: C-5 | B46: 조직역량 | C46: 협업 능력 | D46: 0.1 | E46: 팀원·타 부서와의 협업 태도와 적극적 협력
A47: C-6 | B47: 조직역량 | C47: 소통 능력 | D47: 0.1 | E47: 명확한 의견 전달·경청·효과적 커뮤니케이션
...

Sheet 03_전사업적평가
A1: 전사 업적 평가 (전사 KPI)
A2: 전사 KPI 달성도 → 성과급 가산 계수로 활용 (10_성과급관리에서 자동 참조)
A5: No. | B5: KPI | C5: 측정방법 | D5: 가중치 | E5: 목표 | F5: S 기준 | G5: A 기준 | H5: B 기준 | I5: C 기준 | J5: D 기준 | K5: 실적
A6: 1 | B6: 영업이익률 | C6: 영업이익 ÷ 매출액 × 100 | D6: 0.4 | E6: 0.12 | F6: 0.15 | G6: 0.12 | H6: 0.1 | I6: 0.08 | J6: 0.06
A7: 2 | B7: 매출 성장률 | C7: (금년-전년)/전년 × 100 | D7: 0.35 | E7: 0.07 | F7: 0.08 | G7: 0.07 | H7: 0.06 | I7: 0.05 | J7: 0.04
A8: 3 | B8: 프로젝트 납기·품질 준수율 | C8: 납기·품질 충족 ÷ 총 프로젝트 × 100 | D8: 0.25 | E8: 0.92 | F8: 0.93 | G8: 0.92 | H8: 0.91 | I8: 0.9 | J8: 0.89
A10: ■ 전사 KPI 종합
A11: 전사 종합 등급 | B11: =IFERROR(IF(COUNTBLANK(K6:K8)>0,"",IF(SUMPRODUCT(D6:D8,(K6:K8>=F6:F8)*1)>=0.8,"S",IF(SUMPRODUCT(D6:D8,(K6:K8>=G6:G8)*1)>=0.8,"A",IF(SUMPRODUCT(D6:D8,(K6:K8>=H6:H8)*1)>=0.8,"B",IF(SUMPRODUCT(D6:D8,(K6:K8>=I6:I8)*1)>=0.8,"C","D"))))),"-") | C11: 실적 입력 후 자동 산출. 10_성과급관리의 KPI 가산계수로 활용.

Sheet 04_역할평가
A1: 역할평가 (자동 산출)
A2: 07a/07b의 1·2차 평가자 종합 등급 → 02_의사결정의 평가자 가중치 적용 → 확정 등급
A4: ■ 상반기 역할평가
A5: No. | B5: 사번 | C5: 성명 | D5: 직무 | E5: 역할등급 | F5: 역할(1차) | G5: 역할(2차) | H5: 가중평균(점수) | I5: 확정등급
A6: ='01_인적정보'!A6 -> 1 | B6: ='01_인적정보'!B6 -> BSS-001 | C6: ='01_인적정보'!C6 -> 이화형 | D6: ='01_인적정보'!E6 -> 프로젝트영업 | E6: ='01_인적정보'!H6 -> G6 | F6: ='07a_상반기입력'!G6 -> 0 | G6: ='07a_상반기입력'!H6 -> 0 | H6: =IFERROR(IF(AND(F6<>"",G6<>""),'02_의사결정·종합결과'!$B$67*IF(F6="S",5,IF(F6="A",4,IF(F6="B",3,IF(F6="C",2,IF(F6="D",1,0)))))+'02_의사결정·종합결과'!$B$68*IF(G6="S",5,IF(G6="A",4,IF(G6="B",3,IF(G6="C",2,IF(G6="D",1,0))))),IF(F6<>"",IF(F6="S",5,IF(F6="A",4,IF(F6="B",3,IF(F6="C",2,IF(F6="D",1,0))))),IF(G6<>"",IF(G6="S",5,IF(G6="A",4,IF(G6="B",3,IF(G6="C",2,IF(G6="D",1,0))))),""))),"") -> 0 | I6: =IF(H6="","",IF(H6>=4.5,"S",IF(H6>=3.5,"A",IF(H6>=2.5,"B",IF(H6>=1.5,"C","D"))))) -> D
A7: ='01_인적정보'!A7 -> 2 | B7: ='01_인적정보'!B7 -> BSS-002 | C7: ='01_인적정보'!C7 -> 강전용 | D7: ='01_인적정보'!E7 -> 연구개발(R&D) | E7: ='01_인적정보'!H7 -> G6 | F7: ='07a_상반기입력'!G7 -> 0 | G7: ='07a_상반기입력'!H7 -> 0 | H7: =IFERROR(IF(AND(F7<>"",G7<>""),'02_의사결정·종합결과'!$B$67*IF(F7="S",5,IF(F7="A",4,IF(F7="B",3,IF(F7="C",2,IF(F7="D",1,0)))))+'02_의사결정·종합결과'!$B$68*IF(G7="S",5,IF(G7="A",4,IF(G7="B",3,IF(G7="C",2,IF(G7="D",1,0))))),IF(F7<>"",IF(F7="S",5,IF(F7="A",4,IF(F7="B",3,IF(F7="C",2,IF(F7="D",1,0))))),IF(G7<>"",IF(G7="S",5,IF(G7="A",4,IF(G7="B",3,IF(G7="C",2,IF(G7="D",1,0))))),""))),"") -> 0 | I7: =IF(H7="","",IF(H7>=4.5,"S",IF(H7>=3.5,"A",IF(H7>=2.5,"B",IF(H7>=1.5,"C","D"))))) -> D
A8: ='01_인적정보'!A8 -> 3 | B8: ='01_인적정보'!B8 -> BSS-003 | C8: ='01_인적정보'!C8 -> 김현민 | D8: ='01_인적정보'!E8 -> BIM컨설팅 | E8: ='01_인적정보'!H8 -> G6 | F8: ='07a_상반기입력'!G8 -> 0 | G8: ='07a_상반기입력'!H8 -> 0 | H8: =IFERROR(IF(AND(F8<>"",G8<>""),'02_의사결정·종합결과'!$B$67*IF(F8="S",5,IF(F8="A",4,IF(F8="B",3,IF(F8="C",2,IF(F8="D",1,0)))))+'02_의사결정·종합결과'!$B$68*IF(G8="S",5,IF(G8="A",4,IF(G8="B",3,IF(G8="C",2,IF(G8="D",1,0))))),IF(F8<>"",IF(F8="S",5,IF(F8="A",4,IF(F8="B",3,IF(F8="C",2,IF(F8="D",1,0))))),IF(G8<>"",IF(G8="S",5,IF(G8="A",4,IF(G8="B",3,IF(G8="C",2,IF(G8="D",1,0))))),""))),"") -> 0 | I8: =IF(H8="","",IF(H8>=4.5,"S",IF(H8>=3.5,"A",IF(H8>=2.5,"B",IF(H8>=1.5,"C","D"))))) -> D
A9: ='01_인적정보'!A9 -> 4 | B9: ='01_인적정보'!B9 -> BSS-004 | C9: ='01_인적정보'!C9 -> 이일곤 | D9: ='01_인적정보'!E9 -> 경영전략기획 | E9: ='01_인적정보'!H9 -> G6 | F9: ='07a_상반기입력'!G9 -> 0 | G9: ='07a_상반기입력'!H9 -> 0 | H9: =IFERROR(IF(AND(F9<>"",G9<>""),'02_의사결정·종합결과'!$B$67*IF(F9="S",5,IF(F9="A",4,IF(F9="B",3,IF(F9="C",2,IF(F9="D",1,0)))))+'02_의사결정·종합결과'!$B$68*IF(G9="S",5,IF(G9="A",4,IF(G9="B",3,IF(G9="C",2,IF(G9="D",1,0))))),IF(F9<>"",IF(F9="S",5,IF(F9="A",4,IF(F9="B",3,IF(F9="C",2,IF(F9="D",1,0))))),IF(G9<>"",IF(G9="S",5,IF(G9="A",4,IF(G9="B",3,IF(G9="C",2,IF(G9="D",1,0))))),""))),"") -> 0 | I9: =IF(H9="","",IF(H9>=4.5,"S",IF(H9>=3.5,"A",IF(H9>=2.5,"B",IF(H9>=1.5,"C","D"))))) -> D
A10: ='01_인적정보'!A10 -> 5 | B10: ='01_인적정보'!B10 -> BSS-005 | C10: ='01_인적정보'!C10 -> 송헌영 | D10: ='01_인적정보'!E10 -> 경영전략기획 | E10: ='01_인적정보'!H10 -> G6 | F10: ='07a_상반기입력'!G10 -> 0 | G10: ='07a_상반기입력'!H10 -> 0 | H10: =IFERROR(IF(AND(F10<>"",G10<>""),'02_의사결정·종합결과'!$B$67*IF(F10="S",5,IF(F10="A",4,IF(F10="B",3,IF(F10="C",2,IF(F10="D",1,0)))))+'02_의사결정·종합결과'!$B$68*IF(G10="S",5,IF(G10="A",4,IF(G10="B",3,IF(G10="C",2,IF(G10="D",1,0))))),IF(F10<>"",IF(F10="S",5,IF(F10="A",4,IF(F10="B",3,IF(F10="C",2,IF(F10="D",1,0))))),IF(G10<>"",IF(G10="S",5,IF(G10="A",4,IF(G10="B",3,IF(G10="C",2,IF(G10="D",1,0))))),""))),"") -> 0 | I10: =IF(H10="","",IF(H10>=4.5,"S",IF(H10>=3.5,"A",IF(H10>=2.5,"B",IF(H10>=1.5,"C","D"))))) -> D
A11: ='01_인적정보'!A11 -> 6 | B11: ='01_인적정보'!B11 -> BSS-006 | C11: ='01_인적정보'!C11 -> 이재용 | D11: ='01_인적정보'!E11 -> 경영전략기획 | E11: ='01_인적정보'!H11 -> G6 | F11: ='07a_상반기입력'!G11 -> 0 | G11: ='07a_상반기입력'!H11 -> 0 | H11: =IFERROR(IF(AND(F11<>"",G11<>""),'02_의사결정·종합결과'!$B$67*IF(F11="S",5,IF(F11="A",4,IF(F11="B",3,IF(F11="C",2,IF(F11="D",1,0)))))+'02_의사결정·종합결과'!$B$68*IF(G11="S",5,IF(G11="A",4,IF(G11="B",3,IF(G11="C",2,IF(G11="D",1,0))))),IF(F11<>"",IF(F11="S",5,IF(F11="A",4,IF(F11="B",3,IF(F11="C",2,IF(F11="D",1,0))))),IF(G11<>"",IF(G11="S",5,IF(G11="A",4,IF(G11="B",3,IF(G11="C",2,IF(G11="D",1,0))))),""))),"") -> 0 | I11: =IF(H11="","",IF(H11>=4.5,"S",IF(H11>=3.5,"A",IF(H11>=2.5,"B",IF(H11>=1.5,"C","D"))))) -> D
A12: ='01_인적정보'!A12 -> 7 | B12: ='01_인적정보'!B12 -> BSS-007 | C12: ='01_인적정보'!C12 -> 이진행 | D12: ='01_인적정보'!E12 -> 교육 | E12: ='01_인적정보'!H12 -> G5-M | F12: ='07a_상반기입력'!G12 -> 0 | G12: ='07a_상반기입력'!H12 -> 0 | H12: =IFERROR(IF(AND(F12<>"",G12<>""),'02_의사결정·종합결과'!$B$67*IF(F12="S",5,IF(F12="A",4,IF(F12="B",3,IF(F12="C",2,IF(F12="D",1,0)))))+'02_의사결정·종합결과'!$B$68*IF(G12="S",5,IF(G12="A",4,IF(G12="B",3,IF(G12="C",2,IF(G12="D",1,0))))),IF(F12<>"",IF(F12="S",5,IF(F12="A",4,IF(F12="B",3,IF(F12="C",2,IF(F12="D",1,0))))),IF(G12<>"",IF(G12="S",5,IF(G12="A",4,IF(G12="B",3,IF(G12="C",2,IF(G12="D",1,0))))),""))),"") -> 0 | I12: =IF(H12="","",IF(H12>=4.5,"S",IF(H12>=3.5,"A",IF(H12>=2.5,"B",IF(H12>=1.5,"C","D"))))) -> D
A13: ='01_인적정보'!A13 -> 8 | B13: ='01_인적정보'!B13 -> BSS-008 | C13: ='01_인적정보'!C13 -> 김민수 | D13: ='01_인적정보'!E13 -> 기술지원 | E13: ='01_인적정보'!H13 -> G5-M | F13: ='07a_상반기입력'!G13 -> 0 | G13: ='07a_상반기입력'!H13 -> 0 | H13: =IFERROR(IF(AND(F13<>"",G13<>""),'02_의사결정·종합결과'!$B$67*IF(F13="S",5,IF(F13="A",4,IF(F13="B",3,IF(F13="C",2,IF(F13="D",1,0)))))+'02_의사결정·종합결과'!$B$68*IF(G13="S",5,IF(G13="A",4,IF(G13="B",3,IF(G13="C",2,IF(G13="D",1,0))))),IF(F13<>"",IF(F13="S",5,IF(F13="A",4,IF(F13="B",3,IF(F13="C",2,IF(F13="D",1,0))))),IF(G13<>"",IF(G13="S",5,IF(G13="A",4,IF(G13="B",3,IF(G13="C",2,IF(G13="D",1,0))))),""))),"") -> 0 | I13: =IF(H13="","",IF(H13>=4.5,"S",IF(H13>=3.5,"A",IF(H13>=2.5,"B",IF(H13>=1.5,"C","D"))))) -> D
A14: ='01_인적정보'!A14 -> 9 | B14: ='01_인적정보'!B14 -> BSS-009 | C14: ='01_인적정보'!C14 -> 박남식 | D14: ='01_인적정보'!E14 -> BIM컨설팅 | E14: ='01_인적정보'!H14 -> G5-M | F14: ='07a_상반기입력'!G14 -> 0 | G14: ='07a_상반기입력'!H14 -> 0 | H14: =IFERROR(IF(AND(F14<>"",G14<>""),'02_의사결정·종합결과'!$B$67*IF(F14="S",5,IF(F14="A",4,IF(F14="B",3,IF(F14="C",2,IF(F14="D",1,0)))))+'02_의사결정·종합결과'!$B$68*IF(G14="S",5,IF(G14="A",4,IF(G14="B",3,IF(G14="C",2,IF(G14="D",1,0))))),IF(F14<>"",IF(F14="S",5,IF(F14="A",4,IF(F14="B",3,IF(F14="C",2,IF(F14="D",1,0))))),IF(G14<>"",IF(G14="S",5,IF(G14="A",4,IF(G14="B",3,IF(G14="C",2,IF(G14="D",1,0))))),""))),"") -> 0 | I14: =IF(H14="","",IF(H14>=4.5,"S",IF(H14>=3.5,"A",IF(H14>=2.5,"B",IF(H14>=1.5,"C","D"))))) -> D
A15: ='01_인적정보'!A15 -> 10 | B15: ='01_인적정보'!B15 -> BSS-010 | C15: ='01_인적정보'!C15 -> 신재민 | D15: ='01_인적정보'!E15 -> BIM컨설팅 | E15: ='01_인적정보'!H15 -> G5-S | F15: ='07a_상반기입력'!G15 -> 0 | G15: ='07a_상반기입력'!H15 -> 0 | H15: =IFERROR(IF(AND(F15<>"",G15<>""),'02_의사결정·종합결과'!$B$67*IF(F15="S",5,IF(F15="A",4,IF(F15="B",3,IF(F15="C",2,IF(F15="D",1,0)))))+'02_의사결정·종합결과'!$B$68*IF(G15="S",5,IF(G15="A",4,IF(G15="B",3,IF(G15="C",2,IF(G15="D",1,0))))),IF(F15<>"",IF(F15="S",5,IF(F15="A",4,IF(F15="B",3,IF(F15="C",2,IF(F15="D",1,0))))),IF(G15<>"",IF(G15="S",5,IF(G15="A",4,IF(G15="B",3,IF(G15="C",2,IF(G15="D",1,0))))),""))),"") -> 0 | I15: =IF(H15="","",IF(H15>=4.5,"S",IF(H15>=3.5,"A",IF(H15>=2.5,"B",IF(H15>=1.5,"C","D"))))) -> D
A16: ='01_인적정보'!A16 -> 11 | B16: ='01_인적정보'!B16 -> BSS-011 | C16: ='01_인적정보'!C16 -> 마장엽 | D16: ='01_인적정보'!E16 -> BIM컨설팅 | E16: ='01_인적정보'!H16 -> G5-S | F16: ='07a_상반기입력'!G16 -> 0 | G16: ='07a_상반기입력'!H16 -> 0 | H16: =IFERROR(IF(AND(F16<>"",G16<>""),'02_의사결정·종합결과'!$B$67*IF(F16="S",5,IF(F16="A",4,IF(F16="B",3,IF(F16="C",2,IF(F16="D",1,0)))))+'02_의사결정·종합결과'!$B$68*IF(G16="S",5,IF(G16="A",4,IF(G16="B",3,IF(G16="C",2,IF(G16="D",1,0))))),IF(F16<>"",IF(F16="S",5,IF(F16="A",4,IF(F16="B",3,IF(F16="C",2,IF(F16="D",1,0))))),IF(G16<>"",IF(G16="S",5,IF(G16="A",4,IF(G16="B",3,IF(G16="C",2,IF(G16="D",1,0))))),""))),"") -> 0 | I16: =IF(H16="","",IF(H16>=4.5,"S",IF(H16>=3.5,"A",IF(H16>=2.5,"B",IF(H16>=1.5,"C","D"))))) -> D
A17: ='01_인적정보'!A17 -> 12 | B17: ='01_인적정보'!B17 -> BSS-012 | C17: ='01_인적정보'!C17 -> 하은주 | D17: ='01_인적정보'!E17 -> 경영전략기획 | E17: ='01_인적정보'!H17 -> G5-M | F17: ='07a_상반기입력'!G17 -> 0 | G17: ='07a_상반기입력'!H17 -> 0 | H17: =IFERROR(IF(AND(F17<>"",G17<>""),'02_의사결정·종합결과'!$B$67*IF(F17="S",5,IF(F17="A",4,IF(F17="B",3,IF(F17="C",2,IF(F17="D",1,0)))))+'02_의사결정·종합결과'!$B$68*IF(G17="S",5,IF(G17="A",4,IF(G17="B",3,IF(G17="C",2,IF(G17="D",1,0))))),IF(F17<>"",IF(F17="S",5,IF(F17="A",4,IF(F17="B",3,IF(F17="C",2,IF(F17="D",1,0))))),IF(G17<>"",IF(G17="S",5,IF(G17="A",4,IF(G17="B",3,IF(G17="C",2,IF(G17="D",1,0))))),""))),"") -> 0 | I17: =IF(H17="","",IF(H17>=4.5,"S",IF(H17>=3.5,"A",IF(H17>=2.5,"B",IF(H17>=1.5,"C","D"))))) -> D
... A39: ='01_인적정보'!A39 -> 34 | B39: ='01_인적정보'!B39 -> BSS-034 | C39: ='01_인적정보'!C39 -> 엄보근 | D39: ='01_인적정보'!E39 -> BIM컨설팅 | E39: ='01_인적정보'!H39 -> G1 | F39: ='07a_상반기입력'!G39 -> 0 | G39: ='07a_상반기입력'!H39 -> 0 | H39: =IFERROR(IF(AND(F39<>"",G39<>""),'02_의사결정·종합결과'!$B$67*IF(F39="S",5,IF(F39="A",4,IF(F39="B",3,IF(F39="C",2,IF(F39="D",1,0)))))+'02_의사결정·종합결과'!$B$68*IF(G39="S",5,IF(G39="A",4,IF(G39="B",3,IF(G39="C",2,IF(G39="D",1,0))))),IF(F39<>"",IF(F39="S",5,IF(F39="A",4,IF(F39="B",3,IF(F39="C",2,IF(F39="D",1,0))))),IF(G39<>"",IF(G39="S",5,IF(G39="A",4,IF(G39="B",3,IF(G39="C",2,IF(G39="D",1,0))))),""))),"") -> 0 | I39: =IF(H39="","",IF(H39>=4.5,"S",IF(H39>=3.5,"A",IF(H39>=2.5,"B",IF(H39>=1.5,"C","D"))))) -> D
A44: ■ 하반기 역할평가
A45: No. | B45: 사번 | C45: 성명 | D45: 직무 | E45: 역할등급 | F45: 역할(1차) | G45: 역할(2차) | H45: 가중평균(점수) | I45: 확정등급
A46: ='01_인적정보'!A6 -> 1 | B46: ='01_인적정보'!B6 -> BSS-001 | C46: ='01_인적정보'!C6 -> 이화형 | D46: ='01_인적정보'!E6 -> 프로젝트영업 | E46: ='01_인적정보'!H6 -> G6 | F46: ='07b_하반기입력'!G6 -> 0 | G46: ='07b_하반기입력'!H6 -> 0 | H46: =IFERROR(IF(AND(F46<>"",G46<>""),'02_의사결정·종합결과'!$B$67*IF(F46="S",5,IF(F46="A",4,IF(F46="B",3,IF(F46="C",2,IF(F46="D",1,0)))))+'02_의사결정·종합결과'!$B$68*IF(G46="S",5,IF(G46="A",4,IF(G46="B",3,IF(G46="C",2,IF(G46="D",1,0))))),IF(F46<>"",IF(F46="S",5,IF(F46="A",4,IF(F46="B",3,IF(F46="C",2,IF(F46="D",1,0))))),IF(G46<>"",IF(G46="S",5,IF(G46="A",4,IF(G46="B",3,IF(G46="C",2,IF(G46="D",1,0))))),""))),"") -> 0 | I46: =IF(H46="","",IF(H46>=4.5,"S",IF(H46>=3.5,"A",IF(H46>=2.5,"B",IF(H46>=1.5,"C","D"))))) -> D
A47: ='01_인적정보'!A7 -> 2 | B47: ='01_인적정보'!B7 -> BSS-002 | C47: ='01_인적정보'!C7 -> 강전용 | D47: ='01_인적정보'!E7 -> 연구개발(R&D) | E47: ='01_인적정보'!H7 -> G6 | F47: ='07b_하반기입력'!G7 -> 0 | G47: ='07b_하반기입력'!H7 -> 0 | H47: =IFERROR(IF(AND(F47<>"",G47<>""),'02_의사결정·종합결과'!$B$67*IF(F47="S",5,IF(F47="A",4,IF(F47="B",3,IF(F47="C",2,IF(F47="D",1,0)))))+'02_의사결정·종합결과'!$B$68*IF(G47="S",5,IF(G47="A",4,IF(G47="B",3,IF(G47="C",2,IF(G47="D",1,0))))),IF(F47<>"",IF(F47="S",5,IF(F47="A",4,IF(F47="B",3,IF(F47="C",2,IF(F47="D",1,0))))),IF(G47<>"",IF(G47="S",5,IF(G47="A",4,IF(G47="B",3,IF(G47="C",2,IF(G47="D",1,0))))),""))),"") -> 0 | I47: =IF(H47="","",IF(H47>=4.5,"S",IF(H47>=3.5,"A",IF(H47>=2.5,"B",IF(H47>=1.5,"C","D"))))) -> D
A48: ='01_인적정보'!A8 -> 3 | B48: ='01_인적정보'!B8 -> BSS-003 | C48: ='01_인적정보'!C8 -> 김현민 | D48: ='01_인적정보'!E8 -> BIM컨설팅 | E48: ='01_인적정보'!H8 -> G6 | F48: ='07b_하반기입력'!G8 -> 0 | G48: ='07b_하반기입력'!H8 -> 0 | H48: =IFERROR(IF(AND(F48<>"",G48<>""),'02_의사결정·종합결과'!$B$67*IF(F48="S",5,IF(F48="A",4,IF(F48="B",3,IF(F48="C",2,IF(F48="D",1,0)))))+'02_의사결정·종합결과'!$B$68*IF(G48="S",5,IF(G48="A",4,IF(G48="B",3,IF(G48="C",2,IF(G48="D",1,0))))),IF(F48<>"",IF(F48="S",5,IF(F48="A",4,IF(F48="B",3,IF(F48="C",2,IF(F48="D",1,0))))),IF(G48<>"",IF(G48="S",5,IF(G48="A",4,IF(G48="B",3,IF(G48="C",2,IF(G48="D",1,0))))),""))),"") -> 0 | I48: =IF(H48="","",IF(H48>=4.5,"S",IF(H48>=3.5,"A",IF(H48>=2.5,"B",IF(H48>=1.5,"C","D"))))) -> D
A49: ='01_인적정보'!A9 -> 4 | B49: ='01_인적정보'!B9 -> BSS-004 | C49: ='01_인적정보'!C9 -> 이일곤 | D49: ='01_인적정보'!E9 -> 경영전략기획 | E49: ='01_인적정보'!H9 -> G6 | F49: ='07b_하반기입력'!G9 -> 0 | G49: ='07b_하반기입력'!H9 -> 0 | H49: =IFERROR(IF(AND(F49<>"",G49<>""),'02_의사결정·종합결과'!$B$67*IF(F49="S",5,IF(F49="A",4,IF(F49="B",3,IF(F49="C",2,IF(F49="D",1,0)))))+'02_의사결정·종합결과'!$B$68*IF(G49="S",5,IF(G49="A",4,IF(G49="B",3,IF(G49="C",2,IF(G49="D",1,0))))),IF(F49<>"",IF(F49="S",5,IF(F49="A",4,IF(F49="B",3,IF(F49="C",2,IF(F49="D",1,0))))),IF(G49<>"",IF(G49="S",5,IF(G49="A",4,IF(G49="B",3,IF(G49="C",2,IF(G49="D",1,0))))),""))),"") -> 0 | I49: =IF(H49="","",IF(H49>=4.5,"S",IF(H49>=3.5,"A",IF(H49>=2.5,"B",IF(H49>=1.5,"C","D"))))) -> D
A50: ='01_인적정보'!A10 -> 5 | B50: ='01_인적정보'!B10 -> BSS-005 | C50: ='01_인적정보'!C10 -> 송헌영 | D50: ='01_인적정보'!E10 -> 경영전략기획 | E50: ='01_인적정보'!H10 -> G6 | F50: ='07b_하반기입력'!G10 -> 0 | G50: ='07b_하반기입력'!H10 -> 0 | H50: =IFERROR(IF(AND(F50<>"",G50<>""),'02_의사결정·종합결과'!$B$67*IF(F50="S",5,IF(F50="A",4,IF(F50="B",3,IF(F50="C",2,IF(F50="D",1,0)))))+'02_의사결정·종합결과'!$B$68*IF(G50="S",5,IF(G50="A",4,IF(G50="B",3,IF(G50="C",2,IF(G50="D",1,0))))),IF(F50<>"",IF(F50="S",5,IF(F50="A",4,IF(F50="B",3,IF(F50="C",2,IF(F50="D",1,0))))),IF(G50<>"",IF(G50="S",5,IF(G50="A",4,IF(G50="B",3,IF(G50="C",2,IF(G50="D",1,0))))),""))),"") -> 0 | I50: =IF(H50="","",IF(H50>=4.5,"S",IF(H50>=3.5,"A",IF(H50>=2.5,"B",IF(H50>=1.5,"C","D"))))) -> D
A51: ='01_인적정보'!A11 -> 6 | B51: ='01_인적정보'!B11 -> BSS-006 | C51: ='01_인적정보'!C11 -> 이재용 | D51: ='01_인적정보'!E11 -> 경영전략기획 | E51: ='01_인적정보'!H11 -> G6 | F51: ='07b_하반기입력'!G11 -> 0 | G51: ='07b_하반기입력'!H11 -> 0 | H51: =IFERROR(IF(AND(F51<>"",G51<>""),'02_의사결정·종합결과'!$B$67*IF(F51="S",5,IF(F51="A",4,IF(F51="B",3,IF(F51="C",2,IF(F51="D",1,0)))))+'02_의사결정·종합결과'!$B$68*IF(G51="S",5,IF(G51="A",4,IF(G51="B",3,IF(G51="C",2,IF(G51="D",1,0))))),IF(F51<>"",IF(F51="S",5,IF(F51="A",4,IF(F51="B",3,IF(F51="C",2,IF(F51="D",1,0))))),IF(G51<>"",IF(G51="S",5,IF(G51="A",4,IF(G51="B",3,IF(G51="C",2,IF(G51="D",1,0))))),""))),"") -> 0 | I51: =IF(H51="","",IF(H51>=4.5,"S",IF(H51>=3.5,"A",IF(H51>=2.5,"B",IF(H51>=1.5,"C","D"))))) -> D
A52: ='01_인적정보'!A12 -> 7 | B52: ='01_인적정보'!B12 -> BSS-007 | C52: ='01_인적정보'!C12 -> 이진행 | D52: ='01_인적정보'!E12 -> 교육 | E52: ='01_인적정보'!H12 -> G5-M | F52: ='07b_하반기입력'!G12 -> 0 | G52: ='07b_하반기입력'!H12 -> 0 | H52: =IFERROR(IF(AND(F52<>"",G52<>""),'02_의사결정·종합결과'!$B$67*IF(F52="S",5,IF(F52="A",4,IF(F52="B",3,IF(F52="C",2,IF(F52="D",1,0)))))+'02_의사결정·종합결과'!$B$68*IF(G52="S",5,IF(G52="A",4,IF(G52="B",3,IF(G52="C",2,IF(G52="D",1,0))))),IF(F52<>"",IF(F52="S",5,IF(F52="A",4,IF(F52="B",3,IF(F52="C",2,IF(F52="D",1,0))))),IF(G52<>"",IF(G52="S",5,IF(G52="A",4,IF(G52="B",3,IF(G52="C",2,IF(G52="D",1,0))))),""))),"") -> 0 | I52: =IF(H52="","",IF(H52>=4.5,"S",IF(H52>=3.5,"A",IF(H52>=2.5,"B",IF(H52>=1.5,"C","D"))))) -> D
A53: ='01_인적정보'!A13 -> 8 | B53: ='01_인적정보'!B13 -> BSS-008 | C53: ='01_인적정보'!C13 -> 김민수 | D53: ='01_인적정보'!E13 -> 기술지원 | E53: ='01_인적정보'!H13 -> G5-M | F53: ='07b_하반기입력'!G13 -> 0 | G53: ='07b_하반기입력'!H13 -> 0 | H53: =IFERROR(IF(AND(F53<>"",G53<>""),'02_의사결정·종합결과'!$B$67*IF(F53="S",5,IF(F53="A",4,IF(F53="B",3,IF(F53="C",2,IF(F53="D",1,0)))))+'02_의사결정·종합결과'!$B$68*IF(G53="S",5,IF(G53="A",4,IF(G53="B",3,IF(G53="C",2,IF(G53="D",1,0))))),IF(F53<>"",IF(F53="S",5,IF(F53="A",4,IF(F53="B",3,IF(F53="C",2,IF(F53="D",1,0))))),IF(G53<>"",IF(G53="S",5,IF(G53="A",4,IF(G53="B",3,IF(G53="C",2,IF(G53="D",1,0))))),""))),"") -> 0 | I53: =IF(H53="","",IF(H53>=4.5,"S",IF(H53>=3.5,"A",IF(H53>=2.5,"B",IF(H53>=1.5,"C","D"))))) -> D
A54: ='01_인적정보'!A14 -> 9 | B54: ='01_인적정보'!B14 -> BSS-009 | C54: ='01_인적정보'!C14 -> 박남식 | D54: ='01_인적정보'!E14 -> BIM컨설팅 | E54: ='01_인적정보'!H14 -> G5-M | F54: ='07b_하반기입력'!G14 -> 0 | G54: ='07b_하반기입력'!H14 -> 0 | H54: =IFERROR(IF(AND(F54<>"",G54<>""),'02_의사결정·종합결과'!$B$67*IF(F54="S",5,IF(F54="A",4,IF(F54="B",3,IF(F54="C",2,IF(F54="D",1,0)))))+'02_의사결정·종합결과'!$B$68*IF(G54="S",5,IF(G54="A",4,IF(G54="B",3,IF(G54="C",2,IF(G54="D",1,0))))),IF(F54<>"",IF(F54="S",5,IF(F54="A",4,IF(F54="B",3,IF(F54="C",2,IF(F54="D",1,0))))),IF(G54<>"",IF(G54="S",5,IF(G54="A",4,IF(G54="B",3,IF(G54="C",2,IF(G54="D",1,0))))),""))),"") -> 0 | I54: =IF(H54="","",IF(H54>=4.5,"S",IF(H54>=3.5,"A",IF(H54>=2.5,"B",IF(H54>=1.5,"C","D"))))) -> D
A55: ='01_인적정보'!A15 -> 10 | B55: ='01_인적정보'!B15 -> BSS-010 | C55: ='01_인적정보'!C15 -> 신재민 | D55: ='01_인적정보'!E15 -> BIM컨설팅 | E55: ='01_인적정보'!H15 -> G5-S | F55: ='07b_하반기입력'!G15 -> 0 | G55: ='07b_하반기입력'!H15 -> 0 | H55: =IFERROR(IF(AND(F55<>"",G55<>""),'02_의사결정·종합결과'!$B$67*IF(F55="S",5,IF(F55="A",4,IF(F55="B",3,IF(F55="C",2,IF(F55="D",1,0)))))+'02_의사결정·종합결과'!$B$68*IF(G55="S",5,IF(G55="A",4,IF(G55="B",3,IF(G55="C",2,IF(G55="D",1,0))))),IF(F55<>"",IF(F55="S",5,IF(F55="A",4,IF(F55="B",3,IF(F55="C",2,IF(F55="D",1,0))))),IF(G55<>"",IF(G55="S",5,IF(G55="A",4,IF(G55="B",3,IF(G55="C",2,IF(G55="D",1,0))))),""))),"") -> 0 | I55: =IF(H55="","",IF(H55>=4.5,"S",IF(H55>=3.5,"A",IF(H55>=2.5,"B",IF(H55>=1.5,"C","D"))))) -> D
A56: ='01_인적정보'!A16 -> 11 | B56: ='01_인적정보'!B16 -> BSS-011 | C56: ='01_인적정보'!C16 -> 마장엽 | D56: ='01_인적정보'!E16 -> BIM컨설팅 | E56: ='01_인적정보'!H16 -> G5-S | F56: ='07b_하반기입력'!G16 -> 0 | G56: ='07b_하반기입력'!H16 -> 0 | H56: =IFERROR(IF(AND(F56<>"",G56<>""),'02_의사결정·종합결과'!$B$67*IF(F56="S",5,IF(F56="A",4,IF(F56="B",3,IF(F56="C",2,IF(F56="D",1,0)))))+'02_의사결정·종합결과'!$B$68*IF(G56="S",5,IF(G56="A",4,IF(G56="B",3,IF(G56="C",2,IF(G56="D",1,0))))),IF(F56<>"",IF(F56="S",5,IF(F56="A",4,IF(F56="B",3,IF(F56="C",2,IF(F56="D",1,0))))),IF(G56<>"",IF(G56="S",5,IF(G56="A",4,IF(G56="B",3,IF(G56="C",2,IF(G56="D",1,0))))),""))),"") -> 0 | I56: =IF(H56="","",IF(H56>=4.5,"S",IF(H56>=3.5,"A",IF(H56>=2.5,"B",IF(H56>=1.5,"C","D"))))) -> D
A57: ='01_인적정보'!A17 -> 12 | B57: ='01_인적정보'!B17 -> BSS-012 | C57: ='01_인적정보'!C17 -> 하은주 | D57: ='01_인적정보'!E17 -> 경영전략기획 | E57: ='01_인적정보'!H17 -> G5-M | F57: ='07b_하반기입력'!G17 -> 0 | G57: ='07b_하반기입력'!H17 -> 0 | H57: =IFERROR(IF(AND(F57<>"",G57<>""),'02_의사결정·종합결과'!$B$67*IF(F57="S",5,IF(F57="A",4,IF(F57="B",3,IF(F57="C",2,IF(F57="D",1,0)))))+'02_의사결정·종합결과'!$B$68*IF(G57="S",5,IF(G57="A",4,IF(G57="B",3,IF(G57="C",2,IF(G57="D",1,0))))),IF(F57<>"",IF(F57="S",5,IF(F57="A",4,IF(F57="B",3,IF(F57="C",2,IF(F57="D",1,0))))),IF(G57<>"",IF(G57="S",5,IF(G57="A",4,IF(G57="B",3,IF(G57="C",2,IF(G57="D",1,0))))),""))),"") -> 0 | I57: =IF(H57="","",IF(H57>=4.5,"S",IF(H57>=3.5,"A",IF(H57>=2.5,"B",IF(H57>=1.5,"C","D"))))) -> D
... A79: ='01_인적정보'!A39 -> 34 | B79: ='01_인적정보'!B39 -> BSS-034 | C79: ='01_인적정보'!C39 -> 엄보근 | D79: ='01_인적정보'!E39 -> BIM컨설팅 | E79: ='01_인적정보'!H39 -> G1 | F79: ='07b_하반기입력'!G39 -> 0 | G79: ='07b_하반기입력'!H39 -> 0 | H79: =IFERROR(IF(AND(F79<>"",G79<>""),'02_의사결정·종합결과'!$B$67*IF(F79="S",5,IF(F79="A",4,IF(F79="B",3,IF(F79="C",2,IF(F79="D",1,0)))))+'02_의사결정·종합결과'!$B$68*IF(G79="S",5,IF(G79="A",4,IF(G79="B",3,IF(G79="C",2,IF(G79="D",1,0))))),IF(F79<>"",IF(F79="S",5,IF(F79="A",4,IF(F79="B",3,IF(F79="C",2,IF(F79="D",1,0))))),IF(G79<>"",IF(G79="S",5,IF(G79="A",4,IF(G79="B",3,IF(G79="C",2,IF(G79="D",1,0))))),""))),"") -> 0 | I79: =IF(H79="","",IF(H79>=4.5,"S",IF(H79>=3.5,"A",IF(H79>=2.5,"B",IF(H79>=1.5,"C","D"))))) -> D
A90: ='01_인적정보'!A38 -> 33 | B90: ='01_인적정보'!B38 -> BSS-033 | C90: ='01_인적정보'!C38 -> 유태석 | D90: ='01_인적정보'!E38 -> BIM컨설팅 | E90: ='01_인적정보'!H38 -> G1 | F90: =IFERROR(VLOOKUP('01_인적정보'!M38,'13_직무역할DB'!$A$6:$D$70,4,FALSE),"") -> 실무 보조 | G90: ='07b_하반기입력'!G38 -> 0 | H90: ='07b_하반기입력'!H38 -> 0 | I90: ='07b_하반기입력'!I38 -> 0 | J90: ='07b_하반기입력'!J38 -> 0 | K90: ='07b_하반기입력'!K38 -> 0 | L90: =IFERROR((IF(G90="S",5,IF(G90="A",4,IF(G90="B",3,IF(G90="C",2,IF(G90="D",1,0)))))+IF(H90="S",5,IF(H90="A",4,IF(H90="B",3,IF(H90="C",2,IF(H90="D",1,0)))))+IF(I90="S",5,IF(I90="A",4,IF(I90="B",3,IF(I90="C",2,IF(I90="D",1,0)))))+IF(J90="S",5,IF(J90="A",4,IF(J90="B",3,IF(J90="C",2,IF(J90="D",1,0)))))+IF(K90="S",5,IF(K90="A",4,IF(K90="B",3,IF(K90="C",2,IF(K90="D",1,0))))))/5,"") -> 0 | M90: ='07b_하반기입력'!L38 -> 0 | N90: ='07b_하반기입력'!M38 -> 0 | O90: =IF(N90<>"",N90,IF(M90<>"",M90,IF(L90="","",IF(L90>=4.5,"S",IF(L90>=3.5,"A",IF(L90>=2.5,"B",IF(L90>=1.5,"C","D"))))))) -> 0 | P90: =IF(O90="","",IF(O90="S",5,IF(O90="A",4,IF(O90="B",3,IF(O90="C",2,IF(O90="D",1,0)))))) -> 0
A91: ='01_인적정보'!A39 -> 34 | B91: ='01_인적정보'!B39 -> BSS-034 | C91: ='01_인적정보'!C39 -> 엄보근 | D91: ='01_인적정보'!E39 -> BIM컨설팅 | E91: ='01_인적정보'!H39 -> G1 | F91: =IFERROR(VLOOKUP('01_인적정보'!M39,'13_직무역할DB'!$A$6:$D$70,4,FALSE),"") -> 실무 보조 | G91: ='07b_하반기입력'!G39 -> 0 | H91: ='07b_하반기입력'!H39 -> 0 | I91: ='07b_하반기입력'!I39 -> 0 | J91: ='07b_하반기입력'!J39 -> 0 | K91: ='07b_하반기입력'!K39 -> 0 | L91: =IFERROR((IF(G91="S",5,IF(G91="A",4,IF(G91="B",3,IF(G91="C",2,IF(G91="D",1,0)))))+IF(H91="S",5,IF(H91="A",4,IF(H91="B",3,IF(H91="C",2,IF(H91="D",1,0)))))+IF(I91="S",5,IF(I91="A",4,IF(I91="B",3,IF(I91="C",2,IF(I91="D",1,0)))))+IF(J91="S",5,IF(J91="A",4,IF(J91="B",3,IF(J91="C",2,IF(J91="D",1,0)))))+IF(K91="S",5,IF(K91="A",4,IF(K91="B",3,IF(K91="C",2,IF(K91="D",1,0))))))/5,"") -> 0 | M91: ='07b_하반기입력'!L39 -> 0 | N91: ='07b_하반기입력'!M39 -> 0 | O91: =IF(N91<>"",N91,IF(M91<>"",M91,IF(L91="","",IF(L91>=4.5,"S",IF(L91>=3.5,"A",IF(L91>=2.5,"B",IF(L91>=1.5,"C","D"))))))) -> 0 | P91: =IF(O91="","",IF(O91="S",5,IF(O91="A",4,IF(O91="B",3,IF(O91="C",2,IF(O91="D",1,0)))))) -> 0

Sheet 05_공통역량평가
A1: 공통역량평가 (자동 산출)
A2: 07a/07b의 1·2차 평가자 공통역량 종합 등급 → 평가자 가중치 적용 → 확정 등급
A4: ■ 상반기 공통역량평가
A5: No. | B5: 사번 | C5: 성명 | D5: 직무 | E5: 역할등급 | F5: 공통(1차) | G5: 공통(2차) | H5: 가중평균(점수) | I5: 확정등급
A6: ='01_인적정보'!A6 -> 1 | B6: ='01_인적정보'!B6 -> BSS-001 | C6: ='01_인적정보'!C6 -> 이화형 | D6: ='01_인적정보'!E6 -> 프로젝트영업 | E6: ='01_인적정보'!H6 -> G6 | F6: ='07a_상반기입력'!I6 -> 0 | G6: ='07a_상반기입력'!J6 -> 0 | H6: =IFERROR(IF(AND(F6<>"",G6<>""),'02_의사결정·종합결과'!$B$67*IF(F6="S",5,IF(F6="A",4,IF(F6="B",3,IF(F6="C",2,IF(F6="D",1,0)))))+'02_의사결정·종합결과'!$B$68*IF(G6="S",5,IF(G6="A",4,IF(G6="B",3,IF(G6="C",2,IF(G6="D",1,0))))),IF(F6<>"",IF(F6="S",5,IF(F6="A",4,IF(F6="B",3,IF(F6="C",2,IF(F6="D",1,0))))),IF(G6<>"",IF(G6="S",5,IF(G6="A",4,IF(G6="B",3,IF(G6="C",2,IF(G6="D",1,0))))),""))),"") -> 0 | I6: =IF(H6="","",IF(H6>=4.5,"S",IF(H6>=3.5,"A",IF(H6>=2.5,"B",IF(H6>=1.5,"C","D"))))) -> D
A7: ='01_인적정보'!A7 -> 2 | B7: ='01_인적정보'!B7 -> BSS-002 | C7: ='01_인적정보'!C7 -> 강전용 | D7: ='01_인적정보'!E7 -> 연구개발(R&D) | E7: ='01_인적정보'!H7 -> G6 | F7: ='07a_상반기입력'!I7 -> 0 | G7: ='07a_상반기입력'!J7 -> 0 | H7: =IFERROR(IF(AND(F7<>"",G7<>""),'02_의사결정·종합결과'!$B$67*IF(F7="S",5,IF(F7="A",4,IF(F7="B",3,IF(F7="C",2,IF(F7="D",1,0)))))+'02_의사결정·종합결과'!$B$68*IF(G7="S",5,IF(G7="A",4,IF(G7="B",3,IF(G7="C",2,IF(G7="D",1,0))))),IF(F7<>"",IF(F7="S",5,IF(F7="A",4,IF(F7="B",3,IF(F7="C",2,IF(F7="D",1,0))))),IF(G7<>"",IF(G7="S",5,IF(G7="A",4,IF(G7="B",3,IF(G7="C",2,IF(G7="D",1,0))))),""))),"") -> 0 | I7: =IF(H7="","",IF(H7>=4.5,"S",IF(H7>=3.5,"A",IF(H7>=2.5,"B",IF(H7>=1.5,"C","D"))))) -> D
A8: ='01_인적정보'!A8 -> 3 | B8: ='01_인적정보'!B8 -> BSS-003 | C8: ='01_인적정보'!C8 -> 김현민 | D8: ='01_인적정보'!E8 -> BIM컨설팅 | E8: ='01_인적정보'!H8 -> G6 | F8: ='07a_상반기입력'!I8 -> 0 | G8: ='07a_상반기입력'!J8 -> 0 | H8: =IFERROR(IF(AND(F8<>"",G8<>""),'02_의사결정·종합결과'!$B$67*IF(F8="S",5,IF(F8="A",4,IF(F8="B",3,IF(F8="C",2,IF(F8="D",1,0)))))+'02_의사결정·종합결과'!$B$68*IF(G8="S",5,IF(G8="A",4,IF(G8="B",3,IF(G8="C",2,IF(G8="D",1,0))))),IF(F8<>"",IF(F8="S",5,IF(F8="A",4,IF(F8="B",3,IF(F8="C",2,IF(F8="D",1,0))))),IF(G8<>"",IF(G8="S",5,IF(G8="A",4,IF(G8="B",3,IF(G8="C",2,IF(G8="D",1,0))))),""))),"") -> 0 | I8: =IF(H8="","",IF(H8>=4.5,"S",IF(H8>=3.5,"A",IF(H8>=2.5,"B",IF(H8>=1.5,"C","D"))))) -> D
A9: ='01_인적정보'!A9 -> 4 | B9: ='01_인적정보'!B9 -> BSS-004 | C9: ='01_인적정보'!C9 -> 이일곤 | D9: ='01_인적정보'!E9 -> 경영전략기획 | E9: ='01_인적정보'!H9 -> G6 | F9: ='07a_상반기입력'!I9 -> 0 | G9: ='07a_상반기입력'!J9 -> 0 | H9: =IFERROR(IF(AND(F9<>"",G9<>""),'02_의사결정·종합결과'!$B$67*IF(F9="S",5,IF(F9="A",4,IF(F9="B",3,IF(F9="C",2,IF(F9="D",1,0)))))+'02_의사결정·종합결과'!$B$68*IF(G9="S",5,IF(G9="A",4,IF(G9="B",3,IF(G9="C",2,IF(G9="D",1,0))))),IF(F9<>"",IF(F9="S",5,IF(F9="A",4,IF(F9="B",3,IF(F9="C",2,IF(F9="D",1,0))))),IF(G9<>"",IF(G9="S",5,IF(G9="A",4,IF(G9="B",3,IF(G9="C",2,IF(G9="D",1,0))))),""))),"") -> 0 | I9: =IF(H9="","",IF(H9>=4.5,"S",IF(H9>=3.5,"A",IF(H9>=2.5,"B",IF(H9>=1.5,"C","D"))))) -> D
A10: ='01_인적정보'!A10 -> 5 | B10: ='01_인적정보'!B10 -> BSS-005 | C10: ='01_인적정보'!C10 -> 송헌영 | D10: ='01_인적정보'!E10 -> 경영전략기획 | E10: ='01_인적정보'!H10 -> G6 | F10: ='07a_상반기입력'!I10 -> 0 | G10: ='07a_상반기입력'!J10 -> 0 | H10: =IFERROR(IF(AND(F10<>"",G10<>""),'02_의사결정·종합결과'!$B$67*IF(F10="S",5,IF(F10="A",4,IF(F10="B",3,IF(F10="C",2,IF(F10="D",1,0)))))+'02_의사결정·종합결과'!$B$68*IF(G10="S",5,IF(G10="A",4,IF(G10="B",3,IF(G10="C",2,IF(G10="D",1,0))))),IF(F10<>"",IF(F10="S",5,IF(F10="A",4,IF(F10="B",3,IF(F10="C",2,IF(F10="D",1,0))))),IF(G10<>"",IF(G10="S",5,IF(G10="A",4,IF(G10="B",3,IF(G10="C",2,IF(G10="D",1,0))))),""))),"") -> 0 | I10: =IF(H10="","",IF(H10>=4.5,"S",IF(H10>=3.5,"A",IF(H10>=2.5,"B",IF(H10>=1.5,"C","D"))))) -> D
A11: ='01_인적정보'!A11 -> 6 | B11: ='01_인적정보'!B11 -> BSS-006 | C11: ='01_인적정보'!C11 -> 이재용 | D11: ='01_인적정보'!E11 -> 경영전략기획 | E11: ='01_인적정보'!H11 -> G6 | F11: ='07a_상반기입력'!I11 -> 0 | G11: ='07a_상반기입력'!J11 -> 0 | H11: =IFERROR(IF(AND(F11<>"",G11<>""),'02_의사결정·종합결과'!$B$67*IF(F11="S",5,IF(F11="A",4,IF(F11="B",3,IF(F11="C",2,IF(F11="D",1,0)))))+'02_의사결정·종합결과'!$B$68*IF(G11="S",5,IF(G11="A",4,IF(G11="B",3,IF(G11="C",2,IF(G11="D",1,0))))),IF(F11<>"",IF(F11="S",5,IF(F11="A",4,IF(F11="B",3,IF(F11="C",2,IF(F11="D",1,0))))),IF(G11<>"",IF(G11="S",5,IF(G11="A",4,IF(G11="B",3,IF(G11="C",2,IF(G11="D",1,0))))),""))),"") -> 0 | I11: =IF(H11="","",IF(H11>=4.5,"S",IF(H11>=3.5,"A",IF(H11>=2.5,"B",IF(H11>=1.5,"C","D"))))) -> D
A12: ='01_인적정보'!A12 -> 7 | B12: ='01_인적정보'!B12 -> BSS-007 | C12: ='01_인적정보'!C12 -> 이진행 | D12: ='01_인적정보'!E12 -> 교육 | E12: ='01_인적정보'!H12 -> G5-M | F12: ='07a_상반기입력'!I12 -> 0 | G12: ='07a_상반기입력'!J12 -> 0 | H12: =IFERROR(IF(AND(F12<>"",G12<>""),'02_의사결정·종합결과'!$B$67*IF(F12="S",5,IF(F12="A",4,IF(F12="B",3,IF(F12="C",2,IF(F12="D",1,0)))))+'02_의사결정·종합결과'!$B$68*IF(G12="S",5,IF(G12="A",4,IF(G12="B",3,IF(G12="C",2,IF(G12="D",1,0))))),IF(F12<>"",IF(F12="S",5,IF(F12="A",4,IF(F12="B",3,IF(F12="C",2,IF(F12="D",1,0))))),IF(G12<>"",IF(G12="S",5,IF(G12="A",4,IF(G12="B",3,IF(G12="C",2,IF(G12="D",1,0))))),""))),"") -> 0 | I12: =IF(H12="","",IF(H12>=4.5,"S",IF(H12>=3.5,"A",IF(H12>=2.5,"B",IF(H12>=1.5,"C","D"))))) -> D
A13: ='01_인적정보'!A13 -> 8 | B13: ='01_인적정보'!B13 -> BSS-008 | C13: ='01_인적정보'!C13 -> 김민수 | D13: ='01_인적정보'!E13 -> 기술지원 | E13: ='01_인적정보'!H13 -> G5-M | F13: ='07a_상반기입력'!I13 -> 0 | G13: ='07a_상반기입력'!J13 -> 0 | H13: =IFERROR(IF(AND(F13<>"",G13<>""),'02_의사결정·종합결과'!$B$67*IF(F13="S",5,IF(F13="A",4,IF(F13="B",3,IF(F13="C",2,IF(F13="D",1,0)))))+'02_의사결정·종합결과'!$B$68*IF(G13="S",5,IF(G13="A",4,IF(G13="B",3,IF(G13="C",2,IF(G13="D",1,0))))),IF(F13<>"",IF(F13="S",5,IF(F13="A",4,IF(F13="B",3,IF(F13="C",2,IF(F13="D",1,0))))),IF(G13<>"",IF(G13="S",5,IF(G13="A",4,IF(G13="B",3,IF(G13="C",2,IF(G13="D",1,0))))),""))),"") -> 0 | I13: =IF(H13="","",IF(H13>=4.5,"S",IF(H13>=3.5,"A",IF(H13>=2.5,"B",IF(H13>=1.5,"C","D"))))) -> D
A14: ='01_인적정보'!A14 -> 9 | B14: ='01_인적정보'!B14 -> BSS-009 | C14: ='01_인적정보'!C14 -> 박남식 | D14: ='01_인적정보'!E14 -> BIM컨설팅 | E14: ='01_인적정보'!H14 -> G5-M | F14: ='07a_상반기입력'!I14 -> 0 | G14: ='07a_상반기입력'!J14 -> 0 | H14: =IFERROR(IF(AND(F14<>"",G14<>""),'02_의사결정·종합결과'!$B$67*IF(F14="S",5,IF(F14="A",4,IF(F14="B",3,IF(F14="C",2,IF(F14="D",1,0)))))+'02_의사결정·종합결과'!$B$68*IF(G14="S",5,IF(G14="A",4,IF(G14="B",3,IF(G14="C",2,IF(G14="D",1,0))))),IF(F14<>"",IF(F14="S",5,IF(F14="A",4,IF(F14="B",3,IF(F14="C",2,IF(F14="D",1,0))))),IF(G14<>"",IF(G14="S",5,IF(G14="A",4,IF(G14="B",3,IF(G14="C",2,IF(G14="D",1,0))))),""))),"") -> 0 | I14: =IF(H14="","",IF(H14>=4.5,"S",IF(H14>=3.5,"A",IF(H14>=2.5,"B",IF(H14>=1.5,"C","D"))))) -> D
A15: ='01_인적정보'!A15 -> 10 | B15: ='01_인적정보'!B15 -> BSS-010 | C15: ='01_인적정보'!C15 -> 신재민 | D15: ='01_인적정보'!E15 -> BIM컨설팅 | E15: ='01_인적정보'!H15 -> G5-S | F15: ='07a_상반기입력'!I15 -> 0 | G15: ='07a_상반기입력'!J15 -> 0 | H15: =IFERROR(IF(AND(F15<>"",G15<>""),'02_의사결정·종합결과'!$B$67*IF(F15="S",5,IF(F15="A",4,IF(F15="B",3,IF(F15="C",2,IF(F15="D",1,0)))))+'02_의사결정·종합결과'!$B$68*IF(G15="S",5,IF(G15="A",4,IF(G15="B",3,IF(G15="C",2,IF(G15="D",1,0))))),IF(F15<>"",IF(F15="S",5,IF(F15="A",4,IF(F15="B",3,IF(F15="C",2,IF(F15="D",1,0))))),IF(G15<>"",IF(G15="S",5,IF(G15="A",4,IF(G15="B",3,IF(G15="C",2,IF(G15="D",1,0))))),""))),"") -> 0 | I15: =IF(H15="","",IF(H15>=4.5,"S",IF(H15>=3.5,"A",IF(H15>=2.5,"B",IF(H15>=1.5,"C","D"))))) -> D
A16: ='01_인적정보'!A16 -> 11 | B16: ='01_인적정보'!B16 -> BSS-011 | C16: ='01_인적정보'!C16 -> 마장엽 | D16: ='01_인적정보'!E16 -> BIM컨설팅 | E16: ='01_인적정보'!H16 -> G5-S | F16: ='07a_상반기입력'!I16 -> 0 | G16: ='07a_상반기입력'!J16 -> 0 | H16: =IFERROR(IF(AND(F16<>"",G16<>""),'02_의사결정·종합결과'!$B$67*IF(F16="S",5,IF(F16="A",4,IF(F16="B",3,IF(F16="C",2,IF(F16="D",1,0)))))+'02_의사결정·종합결과'!$B$68*IF(G16="S",5,IF(G16="A",4,IF(G16="B",3,IF(G16="C",2,IF(G16="D",1,0))))),IF(F16<>"",IF(F16="S",5,IF(F16="A",4,IF(F16="B",3,IF(F16="C",2,IF(F16="D",1,0))))),IF(G16<>"",IF(G16="S",5,IF(G16="A",4,IF(G16="B",3,IF(G16="C",2,IF(G16="D",1,0))))),""))),"") -> 0 | I16: =IF(H16="","",IF(H16>=4.5,"S",IF(H16>=3.5,"A",IF(H16>=2.5,"B",IF(H16>=1.5,"C","D"))))) -> D
A17: ='01_인적정보'!A17 -> 12 | B17: ='01_인적정보'!B17 -> BSS-012 | C17: ='01_인적정보'!C17 -> 하은주 | D17: ='01_인적정보'!E17 -> 경영전략기획 | E17: ='01_인적정보'!H17 -> G5-M | F17: ='07a_상반기입력'!I17 -> 0 | G17: ='07a_상반기입력'!J17 -> 0 | H17: =IFERROR(IF(AND(F17<>"",G17<>""),'02_의사결정·종합결과'!$B$67*IF(F17="S",5,IF(F17="A",4,IF(F17="B",3,IF(F17="C",2,IF(F17="D",1,0)))))+'02_의사결정·종합결과'!$B$68*IF(G17="S",5,IF(G17="A",4,IF(G17="B",3,IF(G17="C",2,IF(G17="D",1,0))))),IF(F17<>"",IF(F17="S",5,IF(F17="A",4,IF(F17="B",3,IF(F17="C",2,IF(F17="D",1,0))))),IF(G17<>"",IF(G17="S",5,IF(G17="A",4,IF(G17="B",3,IF(G17="C",2,IF(G17="D",1,0))))),""))),"") -> 0 | I17: =IF(H17="","",IF(H17>=4.5,"S",IF(H17>=3.5,"A",IF(H17>=2.5,"B",IF(H17>=1.5,"C","D"))))) -> D
... A39: ='01_인적정보'!A39 -> 34 | B39: ='01_인적정보'!B39 -> BSS-034 | C39: ='01_인적정보'!C39 -> 엄보근 | D39: ='01_인적정보'!E39 -> BIM컨설팅 | E39: ='01_인적정보'!H39 -> G1 | F39: ='07a_상반기입력'!I39 -> 0 | G39: ='07a_상반기입력'!J39 -> 0 | H39: =IFERROR(IF(AND(F39<>"",G39<>""),'02_의사결정·종합결과'!$B$67*IF(F39="S",5,IF(F39="A",4,IF(F39="B",3,IF(F39="C",2,IF(F39="D",1,0)))))+'02_의사결정·종합결과'!$B$68*IF(G39="S",5,IF(G39="A",4,IF(G39="B",3,IF(G39="C",2,IF(G39="D",1,0))))),IF(F39<>"",IF(F39="S",5,IF(F39="A",4,IF(F39="B",3,IF(F39="C",2,IF(F39="D",1,0))))),IF(G39<>"",IF(G39="S",5,IF(G39="A",4,IF(G39="B",3,IF(G39="C",2,IF(G39="D",1,0))))),""))),"") -> 0 | I39: =IF(H39="","",IF(H39>=4.5,"S",IF(H39>=3.5,"A",IF(H39>=2.5,"B",IF(H39>=1.5,"C","D"))))) -> D
A44: ■ 하반기 공통역량평가
A45: No. | B45: 사번 | C45: 성명 | D45: 직무 | E45: 역할등급 | F45: 공통(1차) | G45: 공통(2차) | H45: 가중평균(점수) | I45: 확정등급
A46: ='01_인적정보'!A6 -> 1 | B46: ='01_인적정보'!B6 -> BSS-001 | C46: ='01_인적정보'!C6 -> 이화형 | D46: ='01_인적정보'!E6 -> 프로젝트영업 | E46: ='01_인적정보'!H6 -> G6 | F46: ='07b_하반기입력'!I6 -> 0 | G46: ='07b_하반기입력'!J6 -> 0 | H46: =IFERROR(IF(AND(F46<>"",G46<>""),'02_의사결정·종합결과'!$B$67*IF(F46="S",5,IF(F46="A",4,IF(F46="B",3,IF(F46="C",2,IF(F46="D",1,0)))))+'02_의사결정·종합결과'!$B$68*IF(G46="S",5,IF(G46="A",4,IF(G46="B",3,IF(G46="C",2,IF(G46="D",1,0))))),IF(F46<>"",IF(F46="S",5,IF(F46="A",4,IF(F46="B",3,IF(F46="C",2,IF(F46="D",1,0))))),IF(G46<>"",IF(G46="S",5,IF(G46="A",4,IF(G46="B",3,IF(G46="C",2,IF(G46="D",1,0))))),""))),"") -> 0 | I46: =IF(H46="","",IF(H46>=4.5,"S",IF(H46>=3.5,"A",IF(H46>=2.5,"B",IF(H46>=1.5,"C","D"))))) -> D
A47: ='01_인적정보'!A7 -> 2 | B47: ='01_인적정보'!B7 -> BSS-002 | C47: ='01_인적정보'!C7 -> 강전용 | D47: ='01_인적정보'!E7 -> 연구개발(R&D) | E47: ='01_인적정보'!H7 -> G6 | F47: ='07b_하반기입력'!I7 -> 0 | G47: ='07b_하반기입력'!J7 -> 0 | H47: =IFERROR(IF(AND(F47<>"",G47<>""),'02_의사결정·종합결과'!$B$67*IF(F47="S",5,IF(F47="A",4,IF(F47="B",3,IF(F47="C",2,IF(F47="D",1,0)))))+'02_의사결정·종합결과'!$B$68*IF(G47="S",5,IF(G47="A",4,IF(G47="B",3,IF(G47="C",2,IF(G47="D",1,0))))),IF(F47<>"",IF(F47="S",5,IF(F47="A",4,IF(F47="B",3,IF(F47="C",2,IF(F47="D",1,0))))),IF(G47<>"",IF(G47="S",5,IF(G47="A",4,IF(G47="B",3,IF(G47="C",2,IF(G47="D",1,0))))),""))),"") -> 0 | I47: =IF(H47="","",IF(H47>=4.5,"S",IF(H47>=3.5,"A",IF(H47>=2.5,"B",IF(H47>=1.5,"C","D"))))) -> D
A48: ='01_인적정보'!A8 -> 3 | B48: ='01_인적정보'!B8 -> BSS-003 | C48: ='01_인적정보'!C8 -> 김현민 | D48: ='01_인적정보'!E8 -> BIM컨설팅 | E48: ='01_인적정보'!H8 -> G6 | F48: ='07b_하반기입력'!I8 -> 0 | G48: ='07b_하반기입력'!J8 -> 0 | H48: =IFERROR(IF(AND(F48<>"",G48<>""),'02_의사결정·종합결과'!$B$67*IF(F48="S",5,IF(F48="A",4,IF(F48="B",3,IF(F48="C",2,IF(F48="D",1,0)))))+'02_의사결정·종합결과'!$B$68*IF(G48="S",5,IF(G48="A",4,IF(G48="B",3,IF(G48="C",2,IF(G48="D",1,0))))),IF(F48<>"",IF(F48="S",5,IF(F48="A",4,IF(F48="B",3,IF(F48="C",2,IF(F48="D",1,0))))),IF(G48<>"",IF(G48="S",5,IF(G48="A",4,IF(G48="B",3,IF(G48="C",2,IF(G48="D",1,0))))),""))),"") -> 0 | I48: =IF(H48="","",IF(H48>=4.5,"S",IF(H48>=3.5,"A",IF(H48>=2.5,"B",IF(H48>=1.5,"C","D"))))) -> D
A49: ='01_인적정보'!A9 -> 4 | B49: ='01_인적정보'!B9 -> BSS-004 | C49: ='01_인적정보'!C9 -> 이일곤 | D49: ='01_인적정보'!E9 -> 경영전략기획 | E49: ='01_인적정보'!H9 -> G6 | F49: ='07b_하반기입력'!I9 -> 0 | G49: ='07b_하반기입력'!J9 -> 0 | H49: =IFERROR(IF(AND(F49<>"",G49<>""),'02_의사결정·종합결과'!$B$67*IF(F49="S",5,IF(F49="A",4,IF(F49="B",3,IF(F49="C",2,IF(F49="D",1,0)))))+'02_의사결정·종합결과'!$B$68*IF(G49="S",5,IF(G49="A",4,IF(G49="B",3,IF(G49="C",2,IF(G49="D",1,0))))),IF(F49<>"",IF(F49="S",5,IF(F49="A",4,IF(F49="B",3,IF(F49="C",2,IF(F49="D",1,0))))),IF(G49<>"",IF(G49="S",5,IF(G49="A",4,IF(G49="B",3,IF(G49="C",2,IF(G49="D",1,0))))),""))),"") -> 0 | I49: =IF(H49="","",IF(H49>=4.5,"S",IF(H49>=3.5,"A",IF(H49>=2.5,"B",IF(H49>=1.5,"C","D"))))) -> D
A50: ='01_인적정보'!A10 -> 5 | B50: ='01_인적정보'!B10 -> BSS-005 | C50: ='01_인적정보'!C10 -> 송헌영 | D50: ='01_인적정보'!E10 -> 경영전략기획 | E50: ='01_인적정보'!H10 -> G6 | F50: ='07b_하반기입력'!I10 -> 0 | G50: ='07b_하반기입력'!J10 -> 0 | H50: =IFERROR(IF(AND(F50<>"",G50<>""),'02_의사결정·종합결과'!$B$67*IF(F50="S",5,IF(F50="A",4,IF(F50="B",3,IF(F50="C",2,IF(F50="D",1,0)))))+'02_의사결정·종합결과'!$B$68*IF(G50="S",5,IF(G50="A",4,IF(G50="B",3,IF(G50="C",2,IF(G50="D",1,0))))),IF(F50<>"",IF(F50="S",5,IF(F50="A",4,IF(F50="B",3,IF(F50="C",2,IF(F50="D",1,0))))),IF(G50<>"",IF(G50="S",5,IF(G50="A",4,IF(G50="B",3,IF(G50="C",2,IF(G50="D",1,0))))),""))),"") -> 0 | I50: =IF(H50="","",IF(H50>=4.5,"S",IF(H50>=3.5,"A",IF(H50>=2.5,"B",IF(H50>=1.5,"C","D"))))) -> D
A51: ='01_인적정보'!A11 -> 6 | B51: ='01_인적정보'!B11 -> BSS-006 | C51: ='01_인적정보'!C11 -> 이재용 | D51: ='01_인적정보'!E11 -> 경영전략기획 | E51: ='01_인적정보'!H11 -> G6 | F51: ='07b_하반기입력'!I11 -> 0 | G51: ='07b_하반기입력'!J11 -> 0 | H51: =IFERROR(IF(AND(F51<>"",G51<>""),'02_의사결정·종합결과'!$B$67*IF(F51="S",5,IF(F51="A",4,IF(F51="B",3,IF(F51="C",2,IF(F51="D",1,0)))))+'02_의사결정·종합결과'!$B$68*IF(G51="S",5,IF(G51="A",4,IF(G51="B",3,IF(G51="C",2,IF(G51="D",1,0))))),IF(F51<>"",IF(F51="S",5,IF(F51="A",4,IF(F51="B",3,IF(F51="C",2,IF(F51="D",1,0))))),IF(G51<>"",IF(G51="S",5,IF(G51="A",4,IF(G51="B",3,IF(G51="C",2,IF(G51="D",1,0))))),""))),"") -> 0 | I51: =IF(H51="","",IF(H51>=4.5,"S",IF(H51>=3.5,"A",IF(H51>=2.5,"B",IF(H51>=1.5,"C","D"))))) -> D
A52: ='01_인적정보'!A12 -> 7 | B52: ='01_인적정보'!B12 -> BSS-007 | C52: ='01_인적정보'!C12 -> 이진행 | D52: ='01_인적정보'!E12 -> 교육 | E52: ='01_인적정보'!H12 -> G5-M | F52: ='07b_하반기입력'!I12 -> 0 | G52: ='07b_하반기입력'!J12 -> 0 | H52: =IFERROR(IF(AND(F52<>"",G52<>""),'02_의사결정·종합결과'!$B$67*IF(F52="S",5,IF(F52="A",4,IF(F52="B",3,IF(F52="C",2,IF(F52="D",1,0)))))+'02_의사결정·종합결과'!$B$68*IF(G52="S",5,IF(G52="A",4,IF(G52="B",3,IF(G52="C",2,IF(G52="D",1,0))))),IF(F52<>"",IF(F52="S",5,IF(F52="A",4,IF(F52="B",3,IF(F52="C",2,IF(F52="D",1,0))))),IF(G52<>"",IF(G52="S",5,IF(G52="A",4,IF(G52="B",3,IF(G52="C",2,IF(G52="D",1,0))))),""))),"") -> 0 | I52: =IF(H52="","",IF(H52>=4.5,"S",IF(H52>=3.5,"A",IF(H52>=2.5,"B",IF(H52>=1.5,"C","D"))))) -> D
A53: ='01_인적정보'!A13 -> 8 | B53: ='01_인적정보'!B13 -> BSS-008 | C53: ='01_인적정보'!C13 -> 김민수 | D53: ='01_인적정보'!E13 -> 기술지원 | E53: ='01_인적정보'!H13 -> G5-M | F53: ='07b_하반기입력'!I13 -> 0 | G53: ='07b_하반기입력'!J13 -> 0 | H53: =IFERROR(IF(AND(F53<>"",G53<>""),'02_의사결정·종합결과'!$B$67*IF(F53="S",5,IF(F53="A",4,IF(F53="B",3,IF(F53="C",2,IF(F53="D",1,0)))))+'02_의사결정·종합결과'!$B$68*IF(G53="S",5,IF(G53="A",4,IF(G53="B",3,IF(G53="C",2,IF(G53="D",1,0))))),IF(F53<>"",IF(F53="S",5,IF(F53="A",4,IF(F53="B",3,IF(F53="C",2,IF(F53="D",1,0))))),IF(G53<>"",IF(G53="S",5,IF(G53="A",4,IF(G53="B",3,IF(G53="C",2,IF(G53="D",1,0))))),""))),"") -> 0 | I53: =IF(H53="","",IF(H53>=4.5,"S",IF(H53>=3.5,"A",IF(H53>=2.5,"B",IF(H53>=1.5,"C","D"))))) -> D
A54: ='01_인적정보'!A14 -> 9 | B54: ='01_인적정보'!B14 -> BSS-009 | C54: ='01_인적정보'!C14 -> 박남식 | D54: ='01_인적정보'!E14 -> BIM컨설팅 | E54: ='01_인적정보'!H14 -> G5-M | F54: ='07b_하반기입력'!I14 -> 0 | G54: ='07b_하반기입력'!J14 -> 0 | H54: =IFERROR(IF(AND(F54<>"",G54<>""),'02_의사결정·종합결과'!$B$67*IF(F54="S",5,IF(F54="A",4,IF(F54="B",3,IF(F54="C",2,IF(F54="D",1,0)))))+'02_의사결정·종합결과'!$B$68*IF(G54="S",5,IF(G54="A",4,IF(G54="B",3,IF(G54="C",2,IF(G54="D",1,0))))),IF(F54<>"",IF(F54="S",5,IF(F54="A",4,IF(F54="B",3,IF(F54="C",2,IF(F54="D",1,0))))),IF(G54<>"",IF(G54="S",5,IF(G54="A",4,IF(G54="B",3,IF(G54="C",2,IF(G54="D",1,0))))),""))),"") -> 0 | I54: =IF(H54="","",IF(H54>=4.5,"S",IF(H54>=3.5,"A",IF(H54>=2.5,"B",IF(H54>=1.5,"C","D"))))) -> D
A55: ='01_인적정보'!A15 -> 10 | B55: ='01_인적정보'!B15 -> BSS-010 | C55: ='01_인적정보'!C15 -> 신재민 | D55: ='01_인적정보'!E15 -> BIM컨설팅 | E55: ='01_인적정보'!H15 -> G5-S | F55: ='07b_하반기입력'!I15 -> 0 | G55: ='07b_하반기입력'!J15 -> 0 | H55: =IFERROR(IF(AND(F55<>"",G55<>""),'02_의사결정·종합결과'!$B$67*IF(F55="S",5,IF(F55="A",4,IF(F55="B",3,IF(F55="C",2,IF(F55="D",1,0)))))+'02_의사결정·종합결과'!$B$68*IF(G55="S",5,IF(G55="A",4,IF(G55="B",3,IF(G55="C",2,IF(G55="D",1,0))))),IF(F55<>"",IF(F55="S",5,IF(F55="A",4,IF(F55="B",3,IF(F55="C",2,IF(F55="D",1,0))))),IF(G55<>"",IF(G55="S",5,IF(G55="A",4,IF(G55="B",3,IF(G55="C",2,IF(G55="D",1,0))))),""))),"") -> 0 | I55: =IF(H55="","",IF(H55>=4.5,"S",IF(H55>=3.5,"A",IF(H55>=2.5,"B",IF(H55>=1.5,"C","D"))))) -> D
A56: ='01_인적정보'!A16 -> 11 | B56: ='01_인적정보'!B16 -> BSS-011 | C56: ='01_인적정보'!C16 -> 마장엽 | D56: ='01_인적정보'!E16 -> BIM컨설팅 | E56: ='01_인적정보'!H16 -> G5-S | F56: ='07b_하반기입력'!I16 -> 0 | G56: ='07b_하반기입력'!J16 -> 0 | H56: =IFERROR(IF(AND(F56<>"",G56<>""),'02_의사결정·종합결과'!$B$67*IF(F56="S",5,IF(F56="A",4,IF(F56="B",3,IF(F56="C",2,IF(F56="D",1,0)))))+'02_의사결정·종합결과'!$B$68*IF(G56="S",5,IF(G56="A",4,IF(G56="B",3,IF(G56="C",2,IF(G56="D",1,0))))),IF(F56<>"",IF(F56="S",5,IF(F56="A",4,IF(F56="B",3,IF(F56="C",2,IF(F56="D",1,0))))),IF(G56<>"",IF(G56="S",5,IF(G56="A",4,IF(G56="B",3,IF(G56="C",2,IF(G56="D",1,0))))),""))),"") -> 0 | I56: =IF(H56="","",IF(H56>=4.5,"S",IF(H56>=3.5,"A",IF(H56>=2.5,"B",IF(H56>=1.5,"C","D"))))) -> D
A57: ='01_인적정보'!A17 -> 12 | B57: ='01_인적정보'!B17 -> BSS-012 | C57: ='01_인적정보'!C17 -> 하은주 | D57: ='01_인적정보'!E17 -> 경영전략기획 | E57: ='01_인적정보'!H17 -> G5-M | F57: ='07b_하반기입력'!I17 -> 0 | G57: ='07b_하반기입력'!J17 -> 0 | H57: =IFERROR(IF(AND(F57<>"",G57<>""),'02_의사결정·종합결과'!$B$67*IF(F57="S",5,IF(F57="A",4,IF(F57="B",3,IF(F57="C",2,IF(F57="D",1,0)))))+'02_의사결정·종합결과'!$B$68*IF(G57="S",5,IF(G57="A",4,IF(G57="B",3,IF(G57="C",2,IF(G57="D",1,0))))),IF(F57<>"",IF(F57="S",5,IF(F57="A",4,IF(F57="B",3,IF(F57="C",2,IF(F57="D",1,0))))),IF(G57<>"",IF(G57="S",5,IF(G57="A",4,IF(G57="B",3,IF(G57="C",2,IF(G57="D",1,0))))),""))),"") -> 0 | I57: =IF(H57="","",IF(H57>=4.5,"S",IF(H57>=3.5,"A",IF(H57>=2.5,"B",IF(H57>=1.5,"C","D"))))) -> D
... A79: ='01_인적정보'!A39 -> 34 | B79: ='01_인적정보'!B39 -> BSS-034 | C79: ='01_인적정보'!C39 -> 엄보근 | D79: ='01_인적정보'!E39 -> BIM컨설팅 | E79: ='01_인적정보'!H39 -> G1 | F79: ='07b_하반기입력'!I39 -> 0 | G79: ='07b_하반기입력'!J39 -> 0 | H79: =IFERROR(IF(AND(F79<>"",G79<>""),'02_의사결정·종합결과'!$B$67*IF(F79="S",5,IF(F79="A",4,IF(F79="B",3,IF(F79="C",2,IF(F79="D",1,0)))))+'02_의사결정·종합결과'!$B$68*IF(G79="S",5,IF(G79="A",4,IF(G79="B",3,IF(G79="C",2,IF(G79="D",1,0))))),IF(F79<>"",IF(F79="S",5,IF(F79="A",4,IF(F79="B",3,IF(F79="C",2,IF(F79="D",1,0))))),IF(G79<>"",IF(G79="S",5,IF(G79="A",4,IF(G79="B",3,IF(G79="C",2,IF(G79="D",1,0))))),""))),"") -> 0 | I79: =IF(H79="","",IF(H79>=4.5,"S",IF(H79>=3.5,"A",IF(H79>=2.5,"B",IF(H79>=1.5,"C","D"))))) -> D

Sheet 06_직무역량평가
A1: 직무역량평가 (자동 산출)
A2: 07a/07b의 1·2차 평가자 직무역량 종합 등급 → 평가자 가중치 적용 → 확정 등급
A4: ■ 상반기 직무역량평가
A5: No. | B5: 사번 | C5: 성명 | D5: 직무 | E5: 역할등급 | F5: 메인 책무 수 | G5: 직무(1차) | H5: 직무(2차) | I5: 가중평균(점수) | J5: 확정등급
A6: ='01_인적정보'!A6 -> 1 | B6: ='01_인적정보'!B6 -> BSS-001 | C6: ='01_인적정보'!C6 -> 이화형 | D6: ='01_인적정보'!E6 -> 프로젝트영업 | E6: ='01_인적정보'!H6 -> G6 | F6: ='01_인적정보'!L6 -> 0 | G6: ='07a_상반기입력'!K6 -> 0 | H6: ='07a_상반기입력'!L6 -> 0 | I6: =IFERROR(IF(AND(G6<>"",H6<>""),'02_의사결정·종합결과'!$B$67*IF(G6="S",5,IF(G6="A",4,IF(G6="B",3,IF(G6="C",2,IF(G6="D",1,0)))))+'02_의사결정·종합결과'!$B$68*IF(H6="S",5,IF(H6="A",4,IF(H6="B",3,IF(H6="C",2,IF(H6="D",1,0))))),IF(G6<>"",IF(G6="S",5,IF(G6="A",4,IF(G6="B",3,IF(G6="C",2,IF(G6="D",1,0))))),IF(H6<>"",IF(H6="S",5,IF(H6="A",4,IF(H6="B",3,IF(H6="C",2,IF(H6="D",1,0))))),""))),"") -> 0 | J6: =IF(I6="","",IF(I6>=4.5,"S",IF(I6>=3.5,"A",IF(I6>=2.5,"B",IF(I6>=1.5,"C","D"))))) -> D
A7: ='01_인적정보'!A7 -> 2 | B7: ='01_인적정보'!B7 -> BSS-002 | C7: ='01_인적정보'!C7 -> 강전용 | D7: ='01_인적정보'!E7 -> 연구개발(R&D) | E7: ='01_인적정보'!H7 -> G6 | F7: ='01_인적정보'!L7 -> 0 | G7: ='07a_상반기입력'!K7 -> 0 | H7: ='07a_상반기입력'!L7 -> 0 | I7: =IFERROR(IF(AND(G7<>"",H7<>""),'02_의사결정·종합결과'!$B$67*IF(G7="S",5,IF(G7="A",4,IF(G7="B",3,IF(G7="C",2,IF(G7="D",1,0)))))+'02_의사결정·종합결과'!$B$68*IF(H7="S",5,IF(H7="A",4,IF(H7="B",3,IF(H7="C",2,IF(H7="D",1,0))))),IF(G7<>"",IF(G7="S",5,IF(G7="A",4,IF(G7="B",3,IF(G7="C",2,IF(G7="D",1,0))))),IF(H7<>"",IF(H7="S",5,IF(H7="A",4,IF(H7="B",3,IF(H7="C",2,IF(H7="D",1,0))))),""))),"") -> 0 | J7: =IF(I7="","",IF(I7>=4.5,"S",IF(I7>=3.5,"A",IF(I7>=2.5,"B",IF(I7>=1.5,"C","D"))))) -> D
A8: ='01_인적정보'!A8 -> 3 | B8: ='01_인적정보'!B8 -> BSS-003 | C8: ='01_인적정보'!C8 -> 김현민 | D8: ='01_인적정보'!E8 -> BIM컨설팅 | E8: ='01_인적정보'!H8 -> G6 | F8: ='01_인적정보'!L8 -> 0 | G8: ='07a_상반기입력'!K8 -> 0 | H8: ='07a_상반기입력'!L8 -> 0 | I8: =IFERROR(IF(AND(G8<>"",H8<>""),'02_의사결정·종합결과'!$B$67*IF(G8="S",5,IF(G8="A",4,IF(G8="B",3,IF(G8="C",2,IF(G8="D",1,0)))))+'02_의사결정·종합결과'!$B$68*IF(H8="S",5,IF(H8="A",4,IF(H8="B",3,IF(H8="C",2,IF(H8="D",1,0))))),IF(G8<>"",IF(G8="S",5,IF(G8="A",4,IF(G8="B",3,IF(G8="C",2,IF(G8="D",1,0))))),IF(H8<>"",IF(H8="S",5,IF(H8="A",4,IF(H8="B",3,IF(H8="C",2,IF(H8="D",1,0))))),""))),"") -> 0 | J8: =IF(I8="","",IF(I8>=4.5,"S",IF(I8>=3.5,"A",IF(I8>=2.5,"B",IF(I8>=1.5,"C","D"))))) -> D
A9: ='01_인적정보'!A9 -> 4 | B9: ='01_인적정보'!B9 -> BSS-004 | C9: ='01_인적정보'!C9 -> 이일곤 | D9: ='01_인적정보'!E9 -> 경영전략기획 | E9: ='01_인적정보'!H9 -> G6 | F9: ='01_인적정보'!L9 -> 0 | G9: ='07a_상반기입력'!K9 -> 0 | H9: ='07a_상반기입력'!L9 -> 0 | I9: =IFERROR(IF(AND(G9<>"",H9<>""),'02_의사결정·종합결과'!$B$67*IF(G9="S",5,IF(G9="A",4,IF(G9="B",3,IF(G9="C",2,IF(G9="D",1,0)))))+'02_의사결정·종합결과'!$B$68*IF(H9="S",5,IF(H9="A",4,IF(H9="B",3,IF(H9="C",2,IF(H9="D",1,0))))),IF(G9<>"",IF(G9="S",5,IF(G9="A",4,IF(G9="B",3,IF(G9="C",2,IF(G9="D",1,0))))),IF(H9<>"",IF(H9="S",5,IF(H9="A",4,IF(H9="B",3,IF(H9="C",2,IF(H9="D",1,0))))),""))),"") -> 0 | J9: =IF(I9="","",IF(I9>=4.5,"S",IF(I9>=3.5,"A",IF(I9>=2.5,"B",IF(I9>=1.5,"C","D"))))) -> D
A10: ='01_인적정보'!A10 -> 5 | B10: ='01_인적정보'!B10 -> BSS-005 | C10: ='01_인적정보'!C10 -> 송헌영 | D10: ='01_인적정보'!E10 -> 경영전략기획 | E10: ='01_인적정보'!H10 -> G6 | F10: ='01_인적정보'!L10 -> 0 | G10: ='07a_상반기입력'!K10 -> 0 | H10: ='07a_상반기입력'!L10 -> 0 | I10: =IFERROR(IF(AND(G10<>"",H10<>""),'02_의사결정·종합결과'!$B$67*IF(G10="S",5,IF(G10="A",4,IF(G10="B",3,IF(G10="C",2,IF(G10="D",1,0)))))+'02_의사결정·종합결과'!$B$68*IF(H10="S",5,IF(H10="A",4,IF(H10="B",3,IF(H10="C",2,IF(H10="D",1,0))))),IF(G10<>"",IF(G10="S",5,IF(G10="A",4,IF(G10="B",3,IF(G10="C",2,IF(G10="D",1,0))))),IF(H10<>"",IF(H10="S",5,IF(H10="A",4,IF(H10="B",3,IF(H10="C",2,IF(H10="D",1,0))))),""))),"") -> 0 | J10: =IF(I10="","",IF(I10>=4.5,"S",IF(I10>=3.5,"A",IF(I10>=2.5,"B",IF(I10>=1.5,"C","D"))))) -> D
A11: ='01_인적정보'!A11 -> 6 | B11: ='01_인적정보'!B11 -> BSS-006 | C11: ='01_인적정보'!C11 -> 이재용 | D11: ='01_인적정보'!E11 -> 경영전략기획 | E11: ='01_인적정보'!H11 -> G6 | F11: ='01_인적정보'!L11 -> 0 | G11: ='07a_상반기입력'!K11 -> 0 | H11: ='07a_상반기입력'!L11 -> 0 | I11: =IFERROR(IF(AND(G11<>"",H11<>""),'02_의사결정·종합결과'!$B$67*IF(G11="S",5,IF(G11="A",4,IF(G11="B",3,IF(G11="C",2,IF(G11="D",1,0)))))+'02_의사결정·종합결과'!$B$68*IF(H11="S",5,IF(H11="A",4,IF(H11="B",3,IF(H11="C",2,IF(H11="D",1,0))))),IF(G11<>"",IF(G11="S",5,IF(G11="A",4,IF(G11="B",3,IF(G11="C",2,IF(G11="D",1,0))))),IF(H11<>"",IF(H11="S",5,IF(H11="A",4,IF(H11="B",3,IF(H11="C",2,IF(H11="D",1,0))))),""))),"") -> 0 | J11: =IF(I11="","",IF(I11>=4.5,"S",IF(I11>=3.5,"A",IF(I11>=2.5,"B",IF(I11>=1.5,"C","D"))))) -> D
A12: ='01_인적정보'!A12 -> 7 | B12: ='01_인적정보'!B12 -> BSS-007 | C12: ='01_인적정보'!C12 -> 이진행 | D12: ='01_인적정보'!E12 -> 교육 | E12: ='01_인적정보'!H12 -> G5-M | F12: ='01_인적정보'!L12 -> 0 | G12: ='07a_상반기입력'!K12 -> 0 | H12: ='07a_상반기입력'!L12 -> 0 | I12: =IFERROR(IF(AND(G12<>"",H12<>""),'02_의사결정·종합결과'!$B$67*IF(G12="S",5,IF(G12="A",4,IF(G12="B",3,IF(G12="C",2,IF(G12="D",1,0)))))+'02_의사결정·종합결과'!$B$68*IF(H12="S",5,IF(H12="A",4,IF(H12="B",3,IF(H12="C",2,IF(H12="D",1,0))))),IF(G12<>"",IF(G12="S",5,IF(G12="A",4,IF(G12="B",3,IF(G12="C",2,IF(G12="D",1,0))))),IF(H12<>"",IF(H12="S",5,IF(H12="A",4,IF(H12="B",3,IF(H12="C",2,IF(H12="D",1,0))))),""))),"") -> 0 | J12: =IF(I12="","",IF(I12>=4.5,"S",IF(I12>=3.5,"A",IF(I12>=2.5,"B",IF(I12>=1.5,"C","D"))))) -> D
A13: ='01_인적정보'!A13 -> 8 | B13: ='01_인적정보'!B13 -> BSS-008 | C13: ='01_인적정보'!C13 -> 김민수 | D13: ='01_인적정보'!E13 -> 기술지원 | E13: ='01_인적정보'!H13 -> G5-M | F13: ='01_인적정보'!L13 -> 0 | G13: ='07a_상반기입력'!K13 -> 0 | H13: ='07a_상반기입력'!L13 -> 0 | I13: =IFERROR(IF(AND(G13<>"",H13<>""),'02_의사결정·종합결과'!$B$67*IF(G13="S",5,IF(G13="A",4,IF(G13="B",3,IF(G13="C",2,IF(G13="D",1,0)))))+'02_의사결정·종합결과'!$B$68*IF(H13="S",5,IF(H13="A",4,IF(H13="B",3,IF(H13="C",2,IF(H13="D",1,0))))),IF(G13<>"",IF(G13="S",5,IF(G13="A",4,IF(G13="B",3,IF(G13="C",2,IF(G13="D",1,0))))),IF(H13<>"",IF(H13="S",5,IF(H13="A",4,IF(H13="B",3,IF(H13="C",2,IF(H13="D",1,0))))),""))),"") -> 0 | J13: =IF(I13="","",IF(I13>=4.5,"S",IF(I13>=3.5,"A",IF(I13>=2.5,"B",IF(I13>=1.5,"C","D"))))) -> D
A14: ='01_인적정보'!A14 -> 9 | B14: ='01_인적정보'!B14 -> BSS-009 | C14: ='01_인적정보'!C14 -> 박남식 | D14: ='01_인적정보'!E14 -> BIM컨설팅 | E14: ='01_인적정보'!H14 -> G5-M | F14: ='01_인적정보'!L14 -> 0 | G14: ='07a_상반기입력'!K14 -> 0 | H14: ='07a_상반기입력'!L14 -> 0 | I14: =IFERROR(IF(AND(G14<>"",H14<>""),'02_의사결정·종합결과'!$B$67*IF(G14="S",5,IF(G14="A",4,IF(G14="B",3,IF(G14="C",2,IF(G14="D",1,0)))))+'02_의사결정·종합결과'!$B$68*IF(H14="S",5,IF(H14="A",4,IF(H14="B",3,IF(H14="C",2,IF(H14="D",1,0))))),IF(G14<>"",IF(G14="S",5,IF(G14="A",4,IF(G14="B",3,IF(G14="C",2,IF(G14="D",1,0))))),IF(H14<>"",IF(H14="S",5,IF(H14="A",4,IF(H14="B",3,IF(H14="C",2,IF(H14="D",1,0))))),""))),"") -> 0 | J14: =IF(I14="","",IF(I14>=4.5,"S",IF(I14>=3.5,"A",IF(I14>=2.5,"B",IF(I14>=1.5,"C","D"))))) -> D
