Workbook
Name bizforms: "bizforms.co.kr"
Name 감면: [1]인사관리현황!$R:$R
Name 감면시작일: [1]인사관리현황!$S:$S
Name 감면자1: [1]소득세감면명세서!$B$17
Name 감면자1병역기간: [1]소득세감면명세서!$V$17
Name 감면자1생년월일: [1]소득세감면명세서!$Z$17
Name 감면자1입대일: [1]소득세감면명세서!$AB$17
Name 감면자1입사연령: [1]소득세감면명세서!$T$17
Name 감면자1입사일: [1]소득세감면명세서!$F$17
Name 감면자1제대일: [1]소득세감면명세서!$AD$17
Name 감면자1차감연령: [1]소득세감면명세서!$X$17
Name 감면자2: [1]소득세감면명세서!$B$19
Name 감면자2병역기간: [1]소득세감면명세서!$V$19
Name 감면자2생년월일: [1]소득세감면명세서!$Z$19
Name 감면자2입대일: [1]소득세감면명세서!$AB$19
Name 감면자2입사연령: [1]소득세감면명세서!$T$19
Name 감면자2입사일: [1]소득세감면명세서!$F$19
Name 감면자2제대일: [1]소득세감면명세서!$AD$19
Name 감면자2차감연령: [1]소득세감면명세서!$X$19
Name 감면자3: [1]소득세감면명세서!$B$21
Name 감면자3병역기간: [1]소득세감면명세서!$V$21
Name 감면자3생년월일: [1]소득세감면명세서!$Z$21
Name 감면자3입대일: [1]소득세감면명세서!$AB$21
Name 감면자3입사연령: [1]소득세감면명세서!$T$21
Name 감면자3입사일: [1]소득세감면명세서!$F$21
Name 감면자3제대일: [1]소득세감면명세서!$AD$21
Name 감면자3차감연령: [1]소득세감면명세서!$X$21
Name 감면자4: [1]소득세감면명세서!$B$23
Name 감면자4병역기간: [1]소득세감면명세서!$V$23
Name 감면자4생년월일: [1]소득세감면명세서!$Z$23
Name 감면자4입대일: [1]소득세감면명세서!$AB$23
Name 감면자4입사연령: [1]소득세감면명세서!$T$23
Name 감면자4입사일: [1]소득세감면명세서!$F$23
Name 감면자4제대일: [1]소득세감면명세서!$AD$23
Name 감면자4차감연령: [1]소득세감면명세서!$X$23
Name 감면자5: [1]소득세감면명세서!$B$25
Name 감면자5병역기간: [1]소득세감면명세서!$V$25
Name 감면자5생년월일: [1]소득세감면명세서!$Z$25
Name 감면자5입대일: [1]소득세감면명세서!$AB$25
Name 감면자5입사연령: [1]소득세감면명세서!$T$25
Name 감면자5입사일: [1]소득세감면명세서!$F$25
Name 감면자5제대일: [1]소득세감면명세서!$AD$25
Name 감면자5차감연령: [1]소득세감면명세서!$X$25
Name 감면종료일: [1]인사관리현황!$T:$T
Name 계좌번호: [1]인사관리현황!$X:$X
Name 교육구분1: [1]인사관리현황!$BJ$4:$BJ$1048576
Name 교육구분2: [1]인사관리현황!$BP$4:$BP$1048576
Name 교육구분3: [1]인사관리현황!$BV$4:$BV$1048576
Name 교육구분4: [1]인사관리현황!$CB$4:$CB$1048576
Name 교육구분5: [1]인사관리현황!$CH$4:$CH$1048576
Name 교육기간끝1: [1]인사관리현황!$BM$4:$BM$1048576
Name 교육기간끝2: [1]인사관리현황!$BS$4:$BS$1048576
Name 교육기간끝3: [1]인사관리현황!$BY$4:$BY$1048576
Name 교육기간끝4: [1]인사관리현황!$CE$4:$CE$1048576
Name 교육기간끝5: [1]인사관리현황!$CK$4:$CK$1048576
Name 교육기간시작1: [1]인사관리현황!$BL$4:$BL$1048576
Name 교육기간시작2: [1]인사관리현황!$BR$4:$BR$1048576
Name 교육기간시작3: [1]인사관리현황!$BX$4:$BX$1048576
Name 교육기간시작4: [1]인사관리현황!$CD$4:$CD$1048576
Name 교육기간시작5: [1]인사관리현황!$CJ$4:$CJ$1048576

Sheet 베이시스_임금 관리 시트
A1: 당해연도 임금 테이블 | K1: 차기년도 임금 테이블
A2: NO | B2: 이름 | C2: 직군 | D2: 부서명 | E2: 기존 직급 | F2: 역할급 직급 | G2: 그래프 반영 직급 | H2: 기존 연봉 | I2: 비고 | K2: 기준인상률 | L2: 평가등급 | M2: 평가인상률 | N2: 승진여부 | O2: 승진인상률 | P2: 차년도 직급 | Q2: 그래프 반영 직급 | R2: 총 인상률 | S2: 인상 연봉(안) | T2: 연봉 확정안 | V2: 2026년 페이밴드 | AD2: 당해연도 임금 현황
A3: 1 | B3: 이화형 | C3: 영업 | D3: 스마트사업부 | E3: 전무 | F3: G6 | G3: 6 | H3: 72500000 | K3: 0.02 | L3: B | M3: {=IF(L3="","",_xlfn.IFS(L3="S",0.04,L3="A",0.03,L3="B",0.02,L3="C",0.01,L3="D",0,TRUE,""))} -> 0.02 | N3: N | O3: {=IF(N3="","",_xlfn.IFS(N3="Y",0.01,N3="N",0,TRUE,""))} -> 0 | P3: G6 | Q3: 6 | R3: =K3+M3+O3 -> 0.04 | S3: =IF(R3="","",ROUND(H3*(1+R3),-4)) -> 75400000 | V3: 항목 | W3: G1 | X3: G2 | Y3: G3 | Z3: G4 | AA3: G5 | AB3: G6
A4: 2 | B4: 강전용 | C4: 연구&개발 | D4: R&D 본부 | E4: 상무 | F4: G6 | G4: 6 | H4: 68870000 | K4: 0.02 | L4: B | M4: {=IF(L4="","",_xlfn.IFS(L4="S",0.04,L4="A",0.03,L4="B",0.02,L4="C",0.01,L4="D",0,TRUE,""))} -> 0.02 | N4: N | O4: {=IF(N4="","",_xlfn.IFS(N4="Y",0.01,N4="N",0,TRUE,""))} -> 0 | P4: G6 | Q4: 6 | R4: =K4+M4+O4 -> 0.04 | S4: =IF(R4="","",ROUND(H4*(1+R4),-4)) -> 71620000 | V4: 최대값 | W4: 44000000 | X4: 49000000 | Y4: 57000000 | Z4: 66000000 | AA4: 73000000 | AB4: 80000000
A5: 3 | B5: 김현민 | C5: 설계 | D5: 컨설틴본부 | E5: 상무 | F5: G6 | G5: 6 | H5: 67500000 | K5: 0.02 | L5: B | M5: {=IF(L5="","",_xlfn.IFS(L5="S",0.04,L5="A",0.03,L5="B",0.02,L5="C",0.01,L5="D",0,TRUE,""))} -> 0.02 | N5: N | O5: {=IF(N5="","",_xlfn.IFS(N5="Y",0.01,N5="N",0,TRUE,""))} -> 0 | P5: G6 | Q5: 6 | R5: =K5+M5+O5 -> 0.04 | S5: =IF(R5="","",ROUND(H5*(1+R5),-4)) -> 70200000 | V5: 최소값 | W5: 33000000 | X5: 36000000 | Y5: 42000000 | Z5: 49000000 | AA5: 53000000 | AB5: 58000000
A6: 4 | B6: 이일곤 | C6: 경영관리 | D6: 경영전략실 | E6: 이사 | F6: G6 | G6: 6 | H6: 64530000 | K6: 0.02 | L6: B | M6: {=IF(L6="","",_xlfn.IFS(L6="S",0.04,L6="A",0.03,L6="B",0.02,L6="C",0.01,L6="D",0,TRUE,""))} -> 0.02 | N6: N | O6: {=IF(N6="","",_xlfn.IFS(N6="Y",0.01,N6="N",0,TRUE,""))} -> 0 | P6: G6 | Q6: 6 | R6: =K6+M6+O6 -> 0.04 | S6: =IF(R6="","",ROUND(H6*(1+R6),-4)) -> 67110000 | V6: 하위폭 | W6: 5500000 | X6: 6500000 | Y6: 7500000 | Z6: 8500000 | AA6: 10000000 | AB6: 11000000
A7: 5 | B7: 송헌영 | C7: 경영관리 | D7: 경영전략실 | E7: 이사 | F7: G6 | G7: 6 | H7: 65180000 | K7: 0.02 | L7: B | M7: {=IF(L7="","",_xlfn.IFS(L7="S",0.04,L7="A",0.03,L7="B",0.02,L7="C",0.01,L7="D",0,TRUE,""))} -> 0.02 | N7: N | O7: {=IF(N7="","",_xlfn.IFS(N7="Y",0.01,N7="N",0,TRUE,""))} -> 0 | P7: G6 | Q7: 6 | R7: =K7+M7+O7 -> 0.04 | S7: =IF(R7="","",ROUND(H7*(1+R7),-4)) -> 67790000 | V7: 상위폭 | W7: 5500000 | X7: 6500000 | Y7: 7500000 | Z7: 8500000 | AA7: 10000000 | AB7: 11000000
A8: 6 | B8: 이재용 | C8: 경영관리 | D8: 경영전략실 | E8: 이사 | F8: G6 | G8: 6 | H8: 62000000 | K8: 0.02 | L8: B | M8: {=IF(L8="","",_xlfn.IFS(L8="S",0.04,L8="A",0.03,L8="B",0.02,L8="C",0.01,L8="D",0,TRUE,""))} -> 0.02 | N8: N | O8: {=IF(N8="","",_xlfn.IFS(N8="Y",0.01,N8="N",0,TRUE,""))} -> 0 | P8: G6 | Q8: 6 | R8: =K8+M8+O8 -> 0.04 | S8: =IF(R8="","",ROUND(H8*(1+R8),-4)) -> 64480000 | V8: 중위값 | W8: 38500000 | X8: 42500000 | Y8: 49500000 | Z8: 57500000 | AA8: 63000000 | AB8: 69000000
A9: 7 | B9: 이진행 | C9: 교육 및 기술지원 | D9: 솔루션본부 | E9: 부장 | F9: G5 | G9: 5 | H9: 59700000 | K9: 0.02 | L9: B | M9: {=IF(L9="","",_xlfn.IFS(L9="S",0.04,L9="A",0.03,L9="B",0.02,L9="C",0.01,L9="D",0,TRUE,""))} -> 0.02 | N9: N | O9: {=IF(N9="","",_xlfn.IFS(N9="Y",0.01,N9="N",0,TRUE,""))} -> 0 | P9: G5 | Q9: 5 | R9: =K9+M9+O9 -> 0.04 | S9: =IF(R9="","",ROUND(H9*(1+R9),-4)) -> 62090000
A10: 8 | B10: 김민수 | C10: 교육 및 기술지원 | D10: 솔루션본부 | E10: 부장 | F10: G5 | G10: 5 | H10: 59050000 | K10: 0.02 | L10: B | M10: {=IF(L10="","",_xlfn.IFS(L10="S",0.04,L10="A",0.03,L10="B",0.02,L10="C",0.01,L10="D",0,TRUE,""))} -> 0.02 | N10: N | O10: {=IF(N10="","",_xlfn.IFS(N10="Y",0.01,N10="N",0,TRUE,""))} -> 0 | P10: G5 | Q10: 5 | R10: =K10+M10+O10 -> 0.04 | S10: =IF(R10="","",ROUND(H10*(1+R10),-4)) -> 61410000
A11: 9 | B11: 박남식 | C11: 설계 | D11: 컨설팅본부 | E11: 부장 | F11: G5 | G11: 5 | H11: 59050000 | K11: 0.02 | L11: B | M11: {=IF(L11="","",_xlfn.IFS(L11="S",0.04,L11="A",0.03,L11="B",0.02,L11="C",0.01,L11="D",0,TRUE,""))} -> 0.02 | N11: N | O11: {=IF(N11="","",_xlfn.IFS(N11="Y",0.01,N11="N",0,TRUE,""))} -> 0 | P11: G5 | Q11: 5 | R11: =K11+M11+O11 -> 0.04 | S11: =IF(R11="","",ROUND(H11*(1+R11),-4)) -> 61410000
A12: 10 | B12: 신재민 | C12: 설계 | D12: 컨설팅본부 | E12: 부장 | F12: G5 | G12: 5 | H12: 59050000 | K12: 0.02 | L12: B | M12: {=IF(L12="","",_xlfn.IFS(L12="S",0.04,L12="A",0.03,L12="B",0.02,L12="C",0.01,L12="D",0,TRUE,""))} -> 0.02 | N12: N | O12: {=IF(N12="","",_xlfn.IFS(N12="Y",0.01,N12="N",0,TRUE,""))} -> 0 | P12: G5 | Q12: 5 | R12: =K12+M12+O12 -> 0.04 | S12: =IF(R12="","",ROUND(H12*(1+R12),-4)) -> 61410000 | V12: 당해연도 임금 현황
A13: 11 | B13: 마장엽 | C13: 설계 | D13: 컨설팅본부 | E13: 부장 | F13: G5 | G13: 5 | H13: 57760000 | K13: 0.02 | L13: B | M13: {=IF(L13="","",_xlfn.IFS(L13="S",0.04,L13="A",0.03,L13="B",0.02,L13="C",0.01,L13="D",0,TRUE,""))} -> 0.02 | N13: N | O13: {=IF(N13="","",_xlfn.IFS(N13="Y",0.01,N13="N",0,TRUE,""))} -> 0 | P13: G5 | Q13: 5 | R13: =K13+M13+O13 -> 0.04 | S13: =IF(R13="","",ROUND(H13*(1+R13),-4)) -> 60070000 | V13: 항목 | W13: G1 | X13: G2 | Y13: G3 | Z13: G4 | AA13: G5 | AB13: G6
A14: 12 | B14: 하은주 | C14: 경영관리 | D14: 마케팅팀 | E14: 부장 | F14: G5 | G14: 5 | H14: 57760000 | K14: 0.02 | L14: B | M14: {=IF(L14="","",_xlfn.IFS(L14="S",0.04,L14="A",0.03,L14="B",0.02,L14="C",0.01,L14="D",0,TRUE,""))} -> 0.02 | N14: N | O14: {=IF(N14="","",_xlfn.IFS(N14="Y",0.01,N14="N",0,TRUE,""))} -> 0 | P14: G5 | Q14: 5 | R14: =K14+M14+O14 -> 0.04 | S14: =IF(R14="","",ROUND(H14*(1+R14),-4)) -> 60070000 | V14: 해당 인원 | W14: =COUNTIF($F:$F,W$13) -> 8 | X14: =COUNTIF($F:$F,X$13) -> 7 | Y14: =COUNTIF($F:$F,Y$13) -> 1 | Z14: =COUNTIF($F:$F,Z$13) -> 2 | AA14: =COUNTIF($F:$F,AA$13) -> 10 | AB14: =COUNTIF($F:$F,AB$13) -> 6
A15: 13 | B15: 홍사훈 | C15: 설계 | D15: 컨설팅본부 | E15: 부장 | F15: G5 | G15: 5 | H15: 58400000 | K15: 0.02 | L15: B | M15: {=IF(L15="","",_xlfn.IFS(L15="S",0.04,L15="A",0.03,L15="B",0.02,L15="C",0.01,L15="D",0,TRUE,""))} -> 0.02 | N15: N | O15: {=IF(N15="","",_xlfn.IFS(N15="Y",0.01,N15="N",0,TRUE,""))} -> 0 | P15: G5 | Q15: 5 | R15: =K15+M15+O15 -> 0.04 | S15: =IF(R15="","",ROUND(H15*(1+R15),-4)) -> 60740000 | V15: 최대값 | W15: {=MAX(IF($F:$F=W$13,$H:$H))} -> 37090000 | X15: {=MAX(IF($F:$F=X$13,$H:$H))} -> 47500000 | Y15: {=MAX(IF($F:$F=Y$13,$H:$H))} -> 43060000 | Z15: {=MAX(IF($F:$F=Z$13,$H:$H))} -> 49240000 | AA15: {=MAX(IF($F:$F=AA$13,$H:$H))} -> 59700000 | AB15: {=MAX(IF($F:$F=AB$13,$H:$H))} -> 72500000
A16: 14 | B16: 유자영 | C16: 설계 | D16: 컨설팅본부 | E16: 부장 | F16: G5 | G16: 5 | H16: 56500000 | K16: 0.02 | L16: B | M16: {=IF(L16="","",_xlfn.IFS(L16="S",0.04,L16="A",0.03,L16="B",0.02,L16="C",0.01,L16="D",0,TRUE,""))} -> 0.02 | N16: N | O16: {=IF(N16="","",_xlfn.IFS(N16="Y",0.01,N16="N",0,TRUE,""))} -> 0 | P16: G5 | Q16: 5 | R16: =K16+M16+O16 -> 0.04 | S16: =IF(R16="","",ROUND(H16*(1+R16),-4)) -> 58760000 | V16: 최소값 | W16: {=MIN(IF($F:$F=W$13,$H:$H))} -> 32000000 | X16: {=MIN(IF($F:$F=X$13,$H:$H))} -> 35000000 | Y16: {=MIN(IF($F:$F=Y$13,$H:$H))} -> 43060000 | Z16: {=MIN(IF($F:$F=Z$13,$H:$H))} -> 48650000 | AA16: {=MIN(IF($F:$F=AA$13,$H:$H))} -> 53160000 | AB16: {=MIN(IF($F:$F=AB$13,$H:$H))} -> 62000000
A17: 15 | B17: 민지선 | C17: 설계 | D17: 컨설팅본부 | E17: 차장 | F17: G5 | G17: 5 | H17: 53160000 | K17: 0.02 | L17: B | M17: {=IF(L17="","",_xlfn.IFS(L17="S",0.04,L17="A",0.03,L17="B",0.02,L17="C",0.01,L17="D",0,TRUE,""))} -> 0.02 | N17: N | O17: {=IF(N17="","",_xlfn.IFS(N17="Y",0.01,N17="N",0,TRUE,""))} -> 0 | P17: G5 | Q17: 5 | R17: =K17+M17+O17 -> 0.04 | S17: =IF(R17="","",ROUND(H17*(1+R17),-4)) -> 55290000 | V17: 평균값 | W17: {=IFERROR(AVERAGE(IF($F:$F=W$13,$H:$H)),"-")} -> 34570625 | X17: {=IFERROR(AVERAGE(IF($F:$F=X$13,$H:$H)),"-")} -> 42142857 | Y17: {=IFERROR(AVERAGE(IF($F:$F=Y$13,$H:$H)),"-")} -> 43060000 | Z17: {=IFERROR(AVERAGE(IF($F:$F=Z$13,$H:$H)),"-")} -> 48945000 | AA17: {=IFERROR(AVERAGE(IF($F:$F=AA$13,$H:$H)),"-")} -> 57418000 | AB17: {=IFERROR(AVERAGE(IF($F:$F=AB$13,$H:$H)),"-")} -> 66763333
A18: 16 | B18: 장훈 | C18: 설계 | D18: 컨설팅본부 | E18: 차장 | F18: G5 | G18: 5 | H18: 53750000 | K18: 0.02 | L18: B | M18: {=IF(L18="","",_xlfn.IFS(L18="S",0.04,L18="A",0.03,L18="B",0.02,L18="C",0.01,L18="D",0,TRUE,""))} -> 0.02 | N18: N | O18: {=IF(N18="","",_xlfn.IFS(N18="Y",0.01,N18="N",0,TRUE,""))} -> 0 | P18: G5 | Q18: 5 | R18: =K18+M18+O18 -> 0.04 | S18: =IF(R18="","",ROUND(H18*(1+R18),-4)) -> 55900000 | V18: 중위값 | W18: {=IFERROR(MEDIAN(IF($F:$F=W$13,$H:$H)),"-")} -> 35467500 | X18: {=IFERROR(MEDIAN(IF($F:$F=X$13,$H:$H)),"-")} -> 42500000 | Y18: {=IFERROR(MEDIAN(IF($F:$F=Y$13,$H:$H)),"-")} -> 43060000 | Z18: {=IFERROR(MEDIAN(IF($F:$F=Z$13,$H:$H)),"-")} -> 48945000 | AA18: {=IFERROR(MEDIAN(IF($F:$F=AA$13,$H:$H)),"-")} -> 58080000 | AB18: {=IFERROR(MEDIAN(IF($F:$F=AB$13,$H:$H)),"-")} -> 66340000
A19: 17 | B19: 김우람 | C19: 교육 및 기술지원 | D19: 솔루션본부 | E19: 과장 | F19: G4 | G19: 4 | H19: 49240000 | K19: 0.02 | L19: B | M19: {=IF(L19="","",_xlfn.IFS(L19="S",0.04,L19="A",0.03,L19="B",0.02,L19="C",0.01,L19="D",0,TRUE,""))} -> 0.02 | N19: N | O19: {=IF(N19="","",_xlfn.IFS(N19="Y",0.01,N19="N",0,TRUE,""))} -> 0 | P19: G4 | Q19: 4 | R19: =K19+M19+O19 -> 0.04 | S19: =IF(R19="","",ROUND(H19*(1+R19),-4)) -> 51210000 | V19: 임금폭(RANGESPREAD) | W19: =IFERROR((W15-W16)/W16,"-") -> 0.1590625 | X19: =IFERROR((X15-X16)/X16,"-") -> 0.35714286 | Y19: =IFERROR((Y15-Y16)/Y16,"-") -> 0 | Z19: =IFERROR((Z15-Z16)/Z16,"-") -> 0.012127441 | AA19: =IFERROR((AA15-AA16)/AA16,"-") -> 0.12302483 | AB19: =IFERROR((AB15-AB16)/AB16,"-") -> 0.16935484
A20: 18 | B20: 조성준 | C20: 설계 | D20: 컨설팅본부 | E20: 과장 | F20: G4 | G20: 4 | H20: 48650000 | K20: 0.02 | L20: B | M20: {=IF(L20="","",_xlfn.IFS(L20="S",0.04,L20="A",0.03,L20="B",0.02,L20="C",0.01,L20="D",0,TRUE,""))} -> 0.02 | N20: N | O20: {=IF(N20="","",_xlfn.IFS(N20="Y",0.01,N20="N",0,TRUE,""))} -> 0 | P20: G4 | Q20: 4 | R20: =K20+M20+O20 -> 0.04 | S20: =IF(R20="","",ROUND(H20*(1+R20),-4)) -> 50600000 | V20: 상승폭(MIDPOINT) | W20: =IFERROR(W18/V18-1,"-") -> - | X20: =IFERROR(X18/W18-1,"-") -> 0.19828012 | Y20: =IFERROR(Y18/X18-1,"-") -> 0.013176471 | Z20: =IFERROR(Z18/Y18-1,"-") -> 0.13666976 | AA20: =IFERROR(AA18/Z18-1,"-") -> 0.18663806 | AB20: =IFERROR(AB18/AA18-1,"-") -> 0.14221763
A21: 19 | B21: 구서현 | C21: 설계 | D21: 컨설팅본부 | E21: 과장 | F21: G2 | G21: 2 | H21: 47500000 | K21: 0.02 | L21: B | M21: {=IF(L21="","",_xlfn.IFS(L21="S",0.04,L21="A",0.03,L21="B",0.02,L21="C",0.01,L21="D",0,TRUE,""))} -> 0.02 | N21: N | O21: {=IF(N21="","",_xlfn.IFS(N21="Y",0.01,N21="N",0,TRUE,""))} -> 0 | P21: G2 | Q21: 2 | R21: =K21+M21+O21 -> 0.04 | S21: =IF(R21="","",ROUND(H21*(1+R21),-4)) -> 49400000 | V21: 중복률(OVERLAP) | W21: =IFERROR(MAX((V15-W16)/(W15-W16),0),"-") -> - | X21: =IFERROR(MAX((W15-X16)/(X15-X16),0),"-") -> 0.1672 | Y21: =IFERROR(MAX((X15-Y16)/(Y15-Y16),0),"-") -> - | Z21: =IFERROR(MAX((Y15-Z16)/(Z15-Z16),0),"-") -> 0 | AA21: =IFERROR(MAX((Z15-AA16)/(AA15-AA16),0),"-") -> 0 | AB21: =IFERROR(MAX((AA15-AB16)/(AB15-AB16),0),"-") -> 0
A22: 20 | B22: 박진용 | C22: 교육 및 기술지원 | D22: 솔루션본부 | E22: 대리 | F22: G3 | G22: 3 | H22: 43060000 | K22: 0.02 | L22: B | M22: {=IF(L22="","",_xlfn.IFS(L22="S",0.04,L22="A",0.03,L22="B",0.02,L22="C",0.01,L22="D",0,TRUE,""))} -> 0.02 | N22: N | O22: {=IF(N22="","",_xlfn.IFS(N22="Y",0.01,N22="N",0,TRUE,""))} -> 0 | P22: G3 | Q22: 3 | R22: =K22+M22+O22 -> 0.04 | S22: =IF(R22="","",ROUND(H22*(1+R22),-4)) -> 44780000
A23: 21 | B23: 김가연 | C23: 설계 | D23: 컨설팅본부 | E23: 대리 | F23: G2 | G23: 2 | H23: 42500000 | K23: 0.02 | L23: B | M23: {=IF(L23="","",_xlfn.IFS(L23="S",0.04,L23="A",0.03,L23="B",0.02,L23="C",0.01,L23="D",0,TRUE,""))} -> 0.02 | N23: N | O23: {=IF(N23="","",_xlfn.IFS(N23="Y",0.01,N23="N",0,TRUE,""))} -> 0 | P23: G2 | Q23: 2 | R23: =K23+M23+O23 -> 0.04 | S23: =IF(R23="","",ROUND(H23*(1+R23),-4)) -> 44200000
A24: 22 | B24: 한근수 | C24: 설계 | D24: 컨설팅본부 | E24: 대리 | F24: G2 | G24: 2 | H24: 42500000 | K24: 0.02 | L24: B | M24: {=IF(L24="","",_xlfn.IFS(L24="S",0.04,L24="A",0.03,L24="B",0.02,L24="C",0.01,L24="D",0,TRUE,""))} -> 0.02 | N24: N | O24: {=IF(N24="","",_xlfn.IFS(N24="Y",0.01,N24="N",0,TRUE,""))} -> 0 | P24: G2 | Q24: 2 | R24: =K24+M24+O24 -> 0.04 | S24: =IF(R24="","",ROUND(H24*(1+R24),-4)) -> 44200000
A25: 23 | B25: 김성민 | C25: 설계 | D25: 컨설팅본부 | E25: 대리 | F25: G2 | G25: 2 | H25: 42500000 | K25: 0.02 | L25: B | M25: {=IF(L25="","",_xlfn.IFS(L25="S",0.04,L25="A",0.03,L25="B",0.02,L25="C",0.01,L25="D",0,TRUE,""))} -> 0.02 | N25: N | O25: {=IF(N25="","",_xlfn.IFS(N25="Y",0.01,N25="N",0,TRUE,""))} -> 0 | P25: G2 | Q25: 2 | R25: =K25+M25+O25 -> 0.04 | S25: =IF(R25="","",ROUND(H25*(1+R25),-4)) -> 44200000 | V25: 차기연도 임금 현황
A26: 24 | B26: 고광우 | C26: 설계 | D26: 컨설팅본부 | E26: 대리 | F26: G2 | G26: 2 | H26: 42500000 | K26: 0.02 | L26: B | M26: {=IF(L26="","",_xlfn.IFS(L26="S",0.04,L26="A",0.03,L26="B",0.02,L26="C",0.01,L26="D",0,TRUE,""))} -> 0.02 | N26: N | O26: {=IF(N26="","",_xlfn.IFS(N26="Y",0.01,N26="N",0,TRUE,""))} -> 0 | P26: G2 | Q26: 2 | R26: =K26+M26+O26 -> 0.04 | S26: =IF(R26="","",ROUND(H26*(1+R26),-4)) -> 44200000 | V26: 항목 | W26: G1 | X26: G2 | Y26: G3 | Z26: G4 | AA26: G5 | AB26: G6
A27: 25 | B27: 김성수 | C27: 연구&개발 | D27: 컨설팅본부 | E27: 대리 | F27: G2 | G27: 2 | H27: 42500000 | K27: 0.02 | L27: B | M27: {=IF(L27="","",_xlfn.IFS(L27="S",0.04,L27="A",0.03,L27="B",0.02,L27="C",0.01,L27="D",0,TRUE,""))} -> 0.02 | N27: N | O27: {=IF(N27="","",_xlfn.IFS(N27="Y",0.01,N27="N",0,TRUE,""))} -> 0 | P27: G2 | Q27: 2 | R27: =K27+M27+O27 -> 0.04 | S27: =IF(R27="","",ROUND(H27*(1+R27),-4)) -> 44200000 | V27: 해당 인원 | W27: =COUNTIF($F:$F,W$26) -> 8 | X27: =COUNTIF($F:$F,X$26) -> 7 | Y27: =COUNTIF($F:$F,Y$26) -> 1 | Z27: =COUNTIF($F:$F,Z$26) -> 2 | AA27: =COUNTIF($F:$F,AA$26) -> 10 | AB27: =COUNTIF($F:$F,AB$26) -> 6
A28: 26 | B28: 박진희 | C28: 경영관리 | D28: 마케팅팀 | E28: 주임 | F28: G1 | G28: 1 | H28: 34935000 | K28: 0.02 | L28: B | M28: {=IF(L28="","",_xlfn.IFS(L28="S",0.04,L28="A",0.03,L28="B",0.02,L28="C",0.01,L28="D",0,TRUE,""))} -> 0.02 | N28: N | O28: {=IF(N28="","",_xlfn.IFS(N28="Y",0.01,N28="N",0,TRUE,""))} -> 0 | P28: G1 | Q28: 1 | R28: =K28+M28+O28 -> 0.04 | S28: =IF(R28="","",ROUND(H28*(1+R28),-4)) -> 36330000 | V28: 최대값 | W28: {=IFERROR(MAX(IF(IF($P3:$P1048576="",$F3:$F1048576,$P3:$P1048576)=W$26,$S3:$S1048576)),"-")} -> 38570000 | X28: {=IFERROR(MAX(IF(IF($P3:$P1048576="",$F3:$F1048576,$P3:$P1048576)=X$26,$S3:$S1048576)),"-")} -> 49400000 | Y28: {=IFERROR(MAX(IF(IF($P3:$P1048576="",$F3:$F1048576,$P3:$P1048576)=Y$26,$S3:$S1048576)),"-")} -> 44780000 | Z28: {=IFERROR(MAX(IF(IF($P3:$P1048576="",$F3:$F1048576,$P3:$P1048576)=Z$26,$S3:$S1048576)),"-")} -> 51210000 | AA28: {=IFERROR(MAX(IF(IF($P3:$P1048576="",$F3:$F1048576,$P3:$P1048576)=AA$26,$S3:$S1048576)),"-")} -> 62090000 | AB28: {=IFERROR(MAX(IF(IF($P3:$P1048576="",$F3:$F1048576,$P3:$P1048576)=AB$26,$S3:$S1048576)),"-")} -> 75400000
A29: 27 | B29: 장은한 | C29: 교육 및 기술지원 | D29: 솔루션본부 | E29: 주임 | F29: G2 | G29: 2 | H29: 35000000 | K29: 0.02 | L29: B | M29: {=IF(L29="","",_xlfn.IFS(L29="S",0.04,L29="A",0.03,L29="B",0.02,L29="C",0.01,L29="D",0,TRUE,""))} -> 0.02 | N29: N | O29: {=IF(N29="","",_xlfn.IFS(N29="Y",0.01,N29="N",0,TRUE,""))} -> 0 | P29: G2 | Q29: 2 | R29: =K29+M29+O29 -> 0.04 | S29: =IF(R29="","",ROUND(H29*(1+R29),-4)) -> 36400000 | V29: 최소값 | W29: {=IFERROR(MIN(IF(IF($P3:$P1048576="",$F3:$F1048576,$P3:$P1048576)=W$26,$S3:$S1048576)),"-")} -> 33280000 | X29: {=IFERROR(MIN(IF(IF($P3:$P1048576="",$F3:$F1048576,$P3:$P1048576)=X$26,$S3:$S1048576)),"-")} -> 36400000 | Y29: {=IFERROR(MIN(IF(IF($P3:$P1048576="",$F3:$F1048576,$P3:$P1048576)=Y$26,$S3:$S1048576)),"-")} -> 44780000 | Z29: {=IFERROR(MIN(IF(IF($P3:$P1048576="",$F3:$F1048576,$P3:$P1048576)=Z$26,$S3:$S1048576)),"-")} -> 50600000 | AA29: {=IFERROR(MIN(IF(IF($P3:$P1048576="",$F3:$F1048576,$P3:$P1048576)=AA$26,$S3:$S1048576)),"-")} -> 55290000 | AB29: {=IFERROR(MIN(IF(IF($P3:$P1048576="",$F3:$F1048576,$P3:$P1048576)=AB$26,$S3:$S1048576)),"-")} -> 64480000
A30: 28 | B30: 김현수 | C30: 설계 | D30: 컨설팅본부 | E30: 주임 | F30: G1 | G30: 1 | H30: 36000000 | K30: 0.02 | L30: B | M30: {=IF(L30="","",_xlfn.IFS(L30="S",0.04,L30="A",0.03,L30="B",0.02,L30="C",0.01,L30="D",0,TRUE,""))} -> 0.02 | N30: N | O30: {=IF(N30="","",_xlfn.IFS(N30="Y",0.01,N30="N",0,TRUE,""))} -> 0 | P30: G1 | Q30: 1 | R30: =K30+M30+O30 -> 0.04 | S30: =IF(R30="","",ROUND(H30*(1+R30),-4)) -> 37440000 | V30: 평균값 | W30: {=IFERROR(AVERAGE(IF(IF($P3:$P1048576="",$F3:$F1048576,$P3:$P1048576)=W$26,$S3:$S1048576)),"-")} -> 35952500 | X30: {=IFERROR(AVERAGE(IF(IF($P3:$P1048576="",$F3:$F1048576,$P3:$P1048576)=X$26,$S3:$S1048576)),"-")} -> 43828571 | Y30: {=IFERROR(AVERAGE(IF(IF($P3:$P1048576="",$F3:$F1048576,$P3:$P1048576)=Y$26,$S3:$S1048576)),"-")} -> 44780000 | Z30: {=IFERROR(AVERAGE(IF(IF($P3:$P1048576="",$F3:$F1048576,$P3:$P1048576)=Z$26,$S3:$S1048576)),"-")} -> 50905000 | AA30: {=IFERROR(AVERAGE(IF(IF($P3:$P1048576="",$F3:$F1048576,$P3:$P1048576)=AA$26,$S3:$S1048576)),"-")} -> 59715000 | AB30: {=IFERROR(AVERAGE(IF(IF($P3:$P1048576="",$F3:$F1048576,$P3:$P1048576)=AB$26,$S3:$S1048576)),"-")} -> 69433333
A31: 29 | B31: 콜셍홍 | C31: 설계 | D31: 컨설팅본부 | E31: 주임 | F31: G1 | G31: 1 | H31: 36000000 | K31: 0.02 | L31: B | M31: {=IF(L31="","",_xlfn.IFS(L31="S",0.04,L31="A",0.03,L31="B",0.02,L31="C",0.01,L31="D",0,TRUE,""))} -> 0.02 | N31: N | O31: {=IF(N31="","",_xlfn.IFS(N31="Y",0.01,N31="N",0,TRUE,""))} -> 0 | P31: G1 | Q31: 1 | R31: =K31+M31+O31 -> 0.04 | S31: =IF(R31="","",ROUND(H31*(1+R31),-4)) -> 37440000 | V31: 중위값 | W31: {=IFERROR(MEDIAN(IF(IF($P3:$P1048576="",$F3:$F1048576,$P3:$P1048576)=W$26,$S3:$S1048576)),"-")} -> 36885000 | X31: {=IFERROR(MEDIAN(IF(IF($P3:$P1048576="",$F3:$F1048576,$P3:$P1048576)=X$26,$S3:$S1048576)),"-")} -> 44200000 | Y31: {=IFERROR(MEDIAN(IF(IF($P3:$P1048576="",$F3:$F1048576,$P3:$P1048576)=Y$26,$S3:$S1048576)),"-")} -> 44780000 | Z31: {=IFERROR(MEDIAN(IF(IF($P3:$P1048576="",$F3:$F1048576,$P3:$P1048576)=Z$26,$S3:$S1048576)),"-")} -> 50905000 | AA31: {=IFERROR(MEDIAN(IF(IF($P3:$P1048576="",$F3:$F1048576,$P3:$P1048576)=AA$26,$S3:$S1048576)),"-")} -> 60405000 | AB31: {=IFERROR(MEDIAN(IF(IF($P3:$P1048576="",$F3:$F1048576,$P3:$P1048576)=AB$26,$S3:$S1048576)),"-")} -> 68995000 | AD31: 차기연도 임금 현황
A32: 30 | B32: 안성진 | C32: 설계 | D32: 컨설팅본부 | E32: 주임 | F32: G1 | G32: 1 | H32: 36540000 | K32: 0.02 | L32: B | M32: {=IF(L32="","",_xlfn.IFS(L32="S",0.04,L32="A",0.03,L32="B",0.02,L32="C",0.01,L32="D",0,TRUE,""))} -> 0.02 | N32: N | O32: {=IF(N32="","",_xlfn.IFS(N32="Y",0.01,N32="N",0,TRUE,""))} -> 0 | P32: G1 | Q32: 1 | R32: =K32+M32+O32 -> 0.04 | S32: =IF(R32="","",ROUND(H32*(1+R32),-4)) -> 38000000 | V32: 임금폭(RANGESPREAD) | W32: =IFERROR((W28-W29)/W29,"-") -> 0.15895433 | X32: =IFERROR((X28-X29)/X29,"-") -> 0.35714286 | Y32: =IFERROR((Y28-Y29)/Y29,"-") -> 0 | Z32: =IFERROR((Z28-Z29)/Z29,"-") -> 0.012055336 | AA32: =IFERROR((AA28-AA29)/AA29,"-") -> 0.12298788 | AB32: =IFERROR((AB28-AB29)/AB29,"-") -> 0.16935484
A33: 31 | B33: 이정일 | C33: 설계 | D33: 컨설팅본부 | E33: 주임 | F33: G1 | G33: 1 | H33: 37090000 | K33: 0.02 | L33: B | M33: {=IF(L33="","",_xlfn.IFS(L33="S",0.04,L33="A",0.03,L33="B",0.02,L33="C",0.01,L33="D",0,TRUE,""))} -> 0.02 | N33: N | O33: {=IF(N33="","",_xlfn.IFS(N33="Y",0.01,N33="N",0,TRUE,""))} -> 0 | P33: G1 | Q33: 1 | R33: =K33+M33+O33 -> 0.04 | S33: =IF(R33="","",ROUND(H33*(1+R33),-4)) -> 38570000 | V33: 상승폭(MIDPOINT) | W33: =IFERROR(W31/V31-1,"-") -> - | X33: =IFERROR(X31/W31-1,"-") -> 0.1983191 | Y33: =IFERROR(Y31/X31-1,"-") -> 0.013122172 | Z33: =IFERROR(Z31/Y31-1,"-") -> 0.13677981 | AA33: =IFERROR(AA31/Z31-1,"-") -> 0.18662214 | AB33: =IFERROR(AB31/AA31-1,"-") -> 0.14220677
A34: 32 | B34: 안재성 | C34: 설계 | D34: 컨설팅본부 | E34: 사원 | F34: G1 | G34: 1 | H34: 32000000 | K34: 0.02 | L34: B | M34: {=IF(L34="","",_xlfn.IFS(L34="S",0.04,L34="A",0.03,L34="B",0.02,L34="C",0.01,L34="D",0,TRUE,""))} -> 0.02 | N34: N | O34: {=IF(N34="","",_xlfn.IFS(N34="Y",0.01,N34="N",0,TRUE,""))} -> 0 | P34: G1 | Q34: 1 | R34: =K34+M34+O34 -> 0.04 | S34: =IF(R34="","",ROUND(H34*(1+R34),-4)) -> 33280000 | V34: 중복률(OVERLAP) | W34: =IFERROR(MAX((V28-W29)/(W28-W29),0),"-") -> - | X34: =IFERROR(MAX((W28-X29)/(X28-X29),0),"-") -> 0.16692308 | Y34: =IFERROR(MAX((X28-Y29)/(Y28-Y29),0),"-") -> - | Z34: =IFERROR(MAX((Y28-Z29)/(Z28-Z29),0),"-") -> 0 | AA34: =IFERROR(MAX((Z28-AA29)/(AA28-AA29),0),"-") -> 0 | AB34: =IFERROR(MAX((AA28-AB29)/(AB28-AB29),0),"-") -> 0
A35: 33 | B35: 유태석 | C35: 설계 | D35: 컨설팅본부 | E35: 사원 | F35: G1 | G35: 1 | H35: 32000000 | K35: 0.02 | L35: B | M35: {=IF(L35="","",_xlfn.IFS(L35="S",0.04,L35="A",0.03,L35="B",0.02,L35="C",0.01,L35="D",0,TRUE,""))} -> 0.02 | N35: N | O35: {=IF(N35="","",_xlfn.IFS(N35="Y",0.01,N35="N",0,TRUE,""))} -> 0 | P35: G1 | Q35: 1 | R35: =K35+M35+O35 -> 0.04 | S35: =IF(R35="","",ROUND(H35*(1+R35),-4)) -> 33280000
A36: 34 | B36: 엄보근 | C36: 설계 | D36: 컨설팅본부 | E36: 사원 | F36: G1 | G36: 1 | H36: 32000000 | K36: 0.02 | L36: B | M36: {=IF(L36="","",_xlfn.IFS(L36="S",0.04,L36="A",0.03,L36="B",0.02,L36="C",0.01,L36="D",0,TRUE,""))} -> 0.02 | N36: N | O36: {=IF(N36="","",_xlfn.IFS(N36="Y",0.01,N36="N",0,TRUE,""))} -> 0 | P36: G1 | Q36: 1 | R36: =K36+M36+O36 -> 0.04 | S36: =IF(R36="","",ROUND(H36*(1+R36),-4)) -> 33280000
A37: 35 | M37: {=IF(L37="","",_xlfn.IFS(L37="S",0.04,L37="A",0.03,L37="B",0.02,L37="C",0.01,L37="D",0,TRUE,""))} | O37: {=IF(N37="","",_xlfn.IFS(N37="Y",0.01,N37="N",0,TRUE,""))} | S37: =IF(R37="","",ROUND(H37*(1+R37),-4))
A38: 36 | M38: {=IF(L38="","",_xlfn.IFS(L38="S",0.04,L38="A",0.03,L38="B",0.02,L38="C",0.01,L38="D",0,TRUE,""))} | O38: {=IF(N38="","",_xlfn.IFS(N38="Y",0.01,N38="N",0,TRUE,""))} | S38: =IF(R38="","",ROUND(H38*(1+R38),-4)) | V38: 임금 변경 요약
A39: 37 | M39: {=IF(L39="","",_xlfn.IFS(L39="S",0.04,L39="A",0.03,L39="B",0.02,L39="C",0.01,L39="D",0,TRUE,""))} | O39: {=IF(N39="","",_xlfn.IFS(N39="Y",0.01,N39="N",0,TRUE,""))} | S39: =IF(R39="","",ROUND(H39*(1+R39),-4)) | V39: 항목 | W39: 당해연도 | Y39: 차기년도 | AA39: 변동액 | AB39: 변동률
A40: 38 | M40: {=IF(L40="","",_xlfn.IFS(L40="S",0.04,L40="A",0.03,L40="B",0.02,L40="C",0.01,L40="D",0,TRUE,""))} | O40: {=IF(N40="","",_xlfn.IFS(N40="Y",0.01,N40="N",0,TRUE,""))} | S40: =IF(R40="","",ROUND(H40*(1+R40),-4)) | V40: 인원수 (명) | W40: =COUNTA($B$3:$B$49) -> 34 | Y40: =COUNTA($B$3:$B$49) -> 34 | AA40: - | AB40: -
...

Sheet 베이시스_2026년 페이밴드 설계_시트
A2: NO | B2: 부서명 | C2: 직급 | D2: 순서 | E2: 연봉
A3: 1 | B3: 최대 | C3: G6 | D3: 6 | E3: 80000000 | G3: 항목 | H3: G1 | I3: G2 | J3: G3 | K3: G4 | L3: G5 | M3: G6
A4: 2 | B4: 최소 | C4: G6 | D4: 6 | E4: 58000000 | G4: 해당 인원 | H4: =COUNTIF($C:$C,'베이시스_2026년 페이밴드 설계_시트'!H$3) -> 2 | I4: =COUNTIF($C:$C,'베이시스_2026년 페이밴드 설계_시트'!I$3) -> 2 | J4: =COUNTIF($C:$C,'베이시스_2026년 페이밴드 설계_시트'!J$3) -> 2 | K4: =COUNTIF($C:$C,'베이시스_2026년 페이밴드 설계_시트'!K$3) -> 2 | L4: =COUNTIF($C:$C,'베이시스_2026년 페이밴드 설계_시트'!L$3) -> 2 | M4: =COUNTIF($C:$C,'베이시스_2026년 페이밴드 설계_시트'!M$3) -> 2
A5: 3 | B5: 최대 | C5: G5 | D5: 5 | E5: 73000000 | G5: 최대값 | H5: {=MAX(IF($C:$C='베이시스_2026년 페이밴드 설계_시트'!H$3,$E:$E))} -> 44000000 | I5: {=MAX(IF($C:$C='베이시스_2026년 페이밴드 설계_시트'!I$3,$E:$E))} -> 49000000 | J5: {=MAX(IF($C:$C='베이시스_2026년 페이밴드 설계_시트'!J$3,$E:$E))} -> 57000000 | K5: {=MAX(IF($C:$C='베이시스_2026년 페이밴드 설계_시트'!K$3,$E:$E))} -> 66000000 | L5: {=MAX(IF($C:$C='베이시스_2026년 페이밴드 설계_시트'!L$3,$E:$E))} -> 73000000 | M5: {=MAX(IF($C:$C='베이시스_2026년 페이밴드 설계_시트'!M$3,$E:$E))} -> 80000000
A6: 4 | B6: 최소 | C6: G5 | D6: 5 | E6: 53000000 | G6: 최소값 | H6: {=MIN(IF($C:$C='베이시스_2026년 페이밴드 설계_시트'!H$3,$E:$E))} -> 33000000 | I6: {=MIN(IF($C:$C='베이시스_2026년 페이밴드 설계_시트'!I$3,$E:$E))} -> 36000000 | J6: {=MIN(IF($C:$C='베이시스_2026년 페이밴드 설계_시트'!J$3,$E:$E))} -> 42000000 | K6: {=MIN(IF($C:$C='베이시스_2026년 페이밴드 설계_시트'!K$3,$E:$E))} -> 49000000 | L6: {=MIN(IF($C:$C='베이시스_2026년 페이밴드 설계_시트'!L$3,$E:$E))} -> 53000000 | M6: {=MIN(IF($C:$C='베이시스_2026년 페이밴드 설계_시트'!M$3,$E:$E))} -> 58000000
A7: 5 | B7: 최대 | C7: G4 | D7: 4 | E7: 66000000 | G7: 평균값 | H7: {=AVERAGE(IF($C:$C='베이시스_2026년 페이밴드 설계_시트'!H$3,$E:$E))} -> 38500000 | I7: {=AVERAGE(IF($C:$C='베이시스_2026년 페이밴드 설계_시트'!I$3,$E:$E))} -> 42500000 | J7: {=AVERAGE(IF($C:$C='베이시스_2026년 페이밴드 설계_시트'!J$3,$E:$E))} -> 49500000 | K7: {=AVERAGE(IF($C:$C='베이시스_2026년 페이밴드 설계_시트'!K$3,$E:$E))} -> 57500000 | L7: {=AVERAGE(IF($C:$C='베이시스_2026년 페이밴드 설계_시트'!L$3,$E:$E))} -> 63000000 | M7: {=AVERAGE(IF($C:$C='베이시스_2026년 페이밴드 설계_시트'!M$3,$E:$E))} -> 69000000
A8: 6 | B8: 최소 | C8: G4 | D8: 4 | E8: 49000000 | G8: 중위값 | H8: {=MEDIAN(IF($C:$C='베이시스_2026년 페이밴드 설계_시트'!H$3,$E:$E))} -> 38500000 | I8: {=MEDIAN(IF($C:$C='베이시스_2026년 페이밴드 설계_시트'!I$3,$E:$E))} -> 42500000 | J8: {=MEDIAN(IF($C:$C='베이시스_2026년 페이밴드 설계_시트'!J$3,$E:$E))} -> 49500000 | K8: {=MEDIAN(IF($C:$C='베이시스_2026년 페이밴드 설계_시트'!K$3,$E:$E))} -> 57500000 | L8: {=MEDIAN(IF($C:$C='베이시스_2026년 페이밴드 설계_시트'!L$3,$E:$E))} -> 63000000 | M8: {=MEDIAN(IF($C:$C='베이시스_2026년 페이밴드 설계_시트'!M$3,$E:$E))} -> 69000000
A9: 7 | B9: 최대 | C9: G3 | D9: 3 | E9: 57000000 | G9: 임금폭(RANGESPREAD) | H9: =(H5-H6)/H6 -> 0.33333333 | I9: =(I5-I6)/I6 -> 0.36111111 | J9: =(J5-J6)/J6 -> 0.35714286 | K9: =(K5-K6)/K6 -> 0.34693878 | L9: =(L5-L6)/L6 -> 0.37735849 | M9: =(M5-M6)/M6 -> 0.37931034
A10: 8 | B10: 최소 | C10: G3 | D10: 3 | E10: 42000000 | G10: 상승폭(MIDPOINT) | H10: =H8/G8-1 -> #VALUE! | I10: =I8/H8-1 -> 0.1038961 | J10: =J8/I8-1 -> 0.16470588 | K10: =K8/J8-1 -> 0.16161616 | L10: =L8/K8-1 -> 0.095652174 | M10: =M8/L8-1 -> 0.095238095
A11: 9 | B11: 최대 | C11: G2 | D11: 2 | E11: 49000000 | G11: 중복률(OVERLAP) | H11: =MAX((G5-H6)/(H5-H6),0) -> #VALUE! | I11: =MAX((H5-I6)/(I5-I6),0) -> 0.61538462 | J11: =MAX((I5-J6)/(J5-J6),0) -> 0.46666667 | K11: =MAX((J5-K6)/(K5-K6),0) -> 0.47058824 | L11: =MAX((K5-L6)/(L5-L6),0) -> 0.65 | M11: =MAX((L5-M6)/(M5-M6),0) -> 0.68181818
A12: 10 | B12: 최소 | C12: G2 | D12: 2 | E12: 36000000
A13: 11 | B13: 최대 | C13: G1 | D13: 1 | E13: 44000000
A14: 12 | B14: 최소 | C14: G1 | D14: 1 | E14: 33000000
A15: 13 | B15: 0
A16: 14 | B16: 0
A17: 15 | B17: 0 | G17: <그래프>
A18: 16 | B18: 0 | G18: 항목 | H18: G1 | I18: G2 | J18: G3 | K18: G4 | L18: G5 | M18: G6
A19: 17 | B19: 0 | G19: 최대값 | H19: =H5 -> 44000000 | I19: =I5 -> 49000000 | J19: =J5 -> 57000000 | K19: =K5 -> 66000000 | L19: =L5 -> 73000000 | M19: =M5 -> 80000000
A20: 18 | B20: 0 | G20: 최소값 | H20: =H6 -> 33000000 | I20: =I6 -> 36000000 | J20: =J6 -> 42000000 | K20: =K6 -> 49000000 | L20: =L6 -> 53000000 | M20: =M6 -> 58000000
A21: 19 | B21: 0 | G21: 하위폭 | H21: =H8-H6 -> 5500000 | I21: =I8-I6 -> 6500000 | J21: =J8-J6 -> 7500000 | K21: =K8-K6 -> 8500000 | L21: =L8-L6 -> 10000000 | M21: =M8-M6 -> 11000000
A22: 20 | B22: 0 | G22: 상위폭 | H22: =H5-H8 -> 5500000 | I22: =I5-I8 -> 6500000 | J22: =J5-J8 -> 7500000 | K22: =K5-K8 -> 8500000 | L22: =L5-L8 -> 10000000 | M22: =M5-M8 -> 11000000
A23: 21 | B23: 0 | G23: 중위값 | H23: =H8 -> 38500000 | I23: =I8 -> 42500000 | J23: =J8 -> 49500000 | K23: =K8 -> 57500000 | L23: =L8 -> 63000000 | M23: =M8 -> 69000000
A24: 22 | B24: 0
A25: 23 | B25: 0
A26: 24 | B26: 0
A27: 25 | B27: 0
A28: 26 | B28: 0
A29: 27 | B29: 0 | G29: <표> | H29: 금액 단위 변경
A30: 28 | B30: 0 | G30: 항목 | H30: G1 | I30: G2 | J30: G3 | K30: G4 | L30: G5 | M30: G6
A31: 29 | B31: 0 | G31: 해당 인원 | H31: =H4 -> 2 | I31: =I4 -> 2 | J31: =J4 -> 2 | K31: =K4 -> 2 | L31: =L4 -> 2 | M31: =M4 -> 2
A32: 30 | B32: 0 | G32: 최대값 | H32: =INT(H5/1000) -> 44000 | I32: =INT(I5/1000) -> 49000 | J32: =INT(J5/1000) -> 57000 | K32: =INT(K5/1000) -> 66000 | L32: =INT(L5/1000) -> 73000 | M32: =INT(M5/1000) -> 80000
A33: 31 | B33: 0 | G33: 최소값 | H33: =INT(H6/1000) -> 33000 | I33: =INT(I6/1000) -> 36000 | J33: =INT(J6/1000) -> 42000 | K33: =INT(K6/1000) -> 49000 | L33: =INT(L6/1000) -> 53000 | M33: =INT(M6/1000) -> 58000
A34: 32 | B34: 0 | G34: 평균값 | H34: =INT(H7/1000) -> 38500 | I34: =INT(I7/1000) -> 42500 | J34: =INT(J7/1000) -> 49500 | K34: =INT(K7/1000) -> 57500 | L34: =INT(L7/1000) -> 63000 | M34: =INT(M7/1000) -> 69000
A35: 33 | B35: 0 | G35: 중위값 | H35: =INT(H8/1000) -> 38500 | I35: =INT(I8/1000) -> 42500 | J35: =INT(J8/1000) -> 49500 | K35: =INT(K8/1000) -> 57500 | L35: =INT(L8/1000) -> 63000 | M35: =INT(M8/1000) -> 69000
A36: 34 | B36: 0 | G36: 임금폭 | H36: =H9 -> 0.33333333 | I36: =I9 -> 0.36111111 | J36: =J9 -> 0.35714286 | K36: =K9 -> 0.34693878 | L36: =L9 -> 0.37735849 | M36: =M9 -> 0.37931034
A37: 35 | B37: 0 | G37: 상승폭 | H37: - | I37: =I10 -> 0.1038961 | J37: =J10 -> 0.16470588 | K37: =K10 -> 0.16161616 | L37: =L10 -> 0.095652174 | M37: =M10 -> 0.095238095
A38: 36 | B38: 0 | G38: 중복률 | H38: - | I38: =I11 -> 0.61538462 | J38: =J11 -> 0.46666667 | K38: =K11 -> 0.47058824 | L38: =L11 -> 0.65 | M38: =M11 -> 0.68181818
A39: 37 | B39: 0
A40: 38 | B40: 0
A41: 39 | B41: 0
...
